Workbook
Name ScenarioSelection: '[1]Table of Contents'!$J$1:$J$3

Sheet Project Title
B2: Finance and Economics of M&A
B4: Acquisition of Pharmacia Corporation by Pfizer Inc.
B5: Standalone Valuation of Pfizer Pre-Merger
B16: by
B18: Marc Schwarz
B24: EBS Universität für Wirtschaft und Recht
B25: Spring Term 2018

Sheet Summary
D3: Pfizer Inc (Pfizer US) Summary of Results
D6: Expected Enterprise Value based on Method:
D8: In Millions of USD | I8: Min | J8: 25th | K8: Median | L8: 75th | M8: Max | O8: Min Point | P8: 25th Point | Q8: Median Point | R8: 75th Point | S8: Max Point
D9: Discounted Cash Flow Method (Base/Base Case) | K9: ='1.2 DCF Analysis'!F52 -> 275607.26
D10: Multiples based on Assets | I10: =MIN('1.1 Multiple Valuation'!K38:K41) -> 144818.26 | J10: =_xlfn.QUARTILE.EXC('1.1 Multiple Valuation'!K38:K41,1) -> 146870.73 | K10: ='1.1 Multiple Valuation'!K42 -> 194020.94 | L10: =_xlfn.QUARTILE.EXC('1.1 Multiple Valuation'!K38:K41,3) -> 235799.87 | M10: =MAX('1.1 Multiple Valuation'!K38:K41) -> 236061.91 | O10: =I10 -> 144818.26 | P10: =J10-I10 -> 2052.4746 | Q10: =K10-J10 -> 47150.208 | R10: =L10-K10 -> 41778.925 | S10: =M10-L10 -> 262.04723
D11: Price Multiples based on Cash Flow | I11: =MIN('1.1 Multiple Valuation'!I52:I55) -> 141078.44 | J11: =_xlfn.QUARTILE.EXC('1.1 Multiple Valuation'!I52:I55,1) -> 154073.4 | K11: ='1.1 Multiple Valuation'!I56 -> 207412.85 | L11: =_xlfn.QUARTILE.EXC('1.1 Multiple Valuation'!I52:I55,3) -> 235783.87 | M11: =MAX('1.1 Multiple Valuation'!I52:I55) -> 240456.01 | O11: =I11 -> 141078.44 | P11: =J11-I11 -> 12994.962 | Q11: =K11-J11 -> 53339.451 | R11: =L11-K11 -> 28371.013 | S11: =M11-L11 -> 4672.1497
D12: Value Multiples based on Cash Flow | I12: =MIN('1.1 Multiple Valuation'!I24:I27) -> 147344.77 | J12: =_xlfn.QUARTILE.EXC('1.1 Multiple Valuation'!I24:I27,1) -> 160242.81 | K12: ='1.1 Multiple Valuation'!I28 -> 208015.59 | L12: =_xlfn.QUARTILE.EXC('1.1 Multiple Valuation'!I24:I27,3) -> 239965.01 | M12: =MAX('1.1 Multiple Valuation'!I24:I27) -> 247588.6 | O12: =I12 -> 147344.77 | P12: =J12-I12 -> 12898.045 | Q12: =K12-J12 -> 47772.782 | R12: =L12-K12 -> 31949.419 | S12: =M12-L12 -> 7623.5905

Sheet 1. Valuations>>>

Sheet 1.1 Multiple Valuation
C2: Pfizer Inc (Pfizer US) Trading Multiples
B6: Comparable Pharma Companies | C6: Price per Share | D6: Market | E6: Enterprise | F6: EBITDA | G6: Bookvalue of Equity | H6: Shares Outstanding | I6: Diluted EPS | J6: P/E Ratio | K6: Price/Book Ratio | L6: Enterprise Value/EBITDA
B7: in Millions of USD except per share | D7: Capitalization | E7: Value | L7: FY 2001
B8: Pfizer Inc. | C8: ='3.4 Trading Multiples Bloomberg'!C10 -> 39.85 | D8: ='3.4 Trading Multiples Bloomberg'!F10 -> 250525.88 | E8: ='3.4 Trading Multiples Bloomberg'!E10 -> 250782.88 | F8: ='3.4 Trading Multiples Bloomberg'!U10 -> 11776 | G8: ='3.4 Trading Multiples Bloomberg'!Y10 -> 18293 | H8: ='3.4 Trading Multiples Bloomberg'!L11 -> 6162.164 | I8: ='3.4 Trading Multiples Bloomberg'!S10 -> 1.22 | J8: ='3.4 Trading Multiples Bloomberg'!Z10 -> 31.378 | K8: ='3.4 Trading Multiples Bloomberg'!AA10 -> 13.674 | L8: ='3.4 Trading Multiples Bloomberg'!V10 -> 21.2961
B9: Eli Lilly and Co | C9: ='3.4 Trading Multiples Bloomberg'!C35 -> 78.54 | D9: ='3.4 Trading Multiples Bloomberg'!F35 -> 88295.278 | E9: ='3.4 Trading Multiples Bloomberg'!E35 -> 87982.678 | F9: ='3.4 Trading Multiples Bloomberg'!U35 -> 4184.7 | G9: ='3.4 Trading Multiples Bloomberg'!Y35 -> 7104 | H9: ='3.4 Trading Multiples Bloomberg'!L36 -> 1123.374 | I9: ='3.4 Trading Multiples Bloomberg'!S35 -> 2.55 | J9: ='3.4 Trading Multiples Bloomberg'!Z35 -> 28.4565 | K9: ='3.4 Trading Multiples Bloomberg'!AA35 -> 12.4195 | L9: ='3.4 Trading Multiples Bloomberg'!V35 -> 21.0248
B10: Johnson & Johnson | C10: ='3.4 Trading Multiples Bloomberg'!C59 -> 59.1 | D10: ='3.4 Trading Multiples Bloomberg'!F59 -> 180141.11 | E10: ='3.4 Trading Multiples Bloomberg'!E59 -> 174951.11 | F10: ='3.4 Trading Multiples Bloomberg'!U59 -> 9490 | G10: ='3.4 Trading Multiples Bloomberg'!Y59 -> 24233 | H10: ='3.4 Trading Multiples Bloomberg'!L60 -> 2970.582 | I10: ='3.4 Trading Multiples Bloomberg'!S59 -> 1.84 | J10: ='3.4 Trading Multiples Bloomberg'!Z59 -> 30.9424 | K10: ='3.4 Trading Multiples Bloomberg'!AA59 -> 7.4316 | L10: ='3.4 Trading Multiples Bloomberg'!V59 -> 18.4353
B11: Merck & Co. | C11: ='3.4 Trading Multiples Bloomberg'!C83 -> 55.6517 | D11: ='3.4 Trading Multiples Bloomberg'!F83 -> 133752.95 | E11: ='3.4 Trading Multiples Bloomberg'!E83 -> 144169.15 | F11: ='3.4 Trading Multiples Bloomberg'!U83 -> 11522.2 | G11: ='3.4 Trading Multiples Bloomberg'!Y83 -> 20887.6 | H11: ='3.4 Trading Multiples Bloomberg'!L84 -> 2245.556 | I11: ='3.4 Trading Multiples Bloomberg'!S83 -> 3.14 | J11: ='3.4 Trading Multiples Bloomberg'!Z83 -> 17.7235 | K11: ='3.4 Trading Multiples Bloomberg'!AA83 -> 7.8804 | L11: ='3.4 Trading Multiples Bloomberg'!V83 -> 12.5123
B12: Bristol-Myers Squibb | C12: ='3.4 Trading Multiples Bloomberg'!C107 -> 51 | D12: ='3.4 Trading Multiples Bloomberg'!F107 -> 98677.685 | E12: ='3.4 Trading Multiples Bloomberg'!E107 -> 99434.685 | F12: ='3.4 Trading Multiples Bloomberg'!U107 -> 5886 | G12: ='3.4 Trading Multiples Bloomberg'!Y107 -> 9075 | H12: ='3.4 Trading Multiples Bloomberg'!L108 -> 1937.045 | I12: ='3.4 Trading Multiples Bloomberg'!S107 -> 2.46 | J12: ='3.4 Trading Multiples Bloomberg'!Z107 -> 24.6377 | K12: ='3.4 Trading Multiples Bloomberg'!AA107 -> 12.3622 | L12: ='3.4 Trading Multiples Bloomberg'!V107 -> 16.8934
B13: Average (excl. Pfizer) | C13: =AVERAGE(C9:C12) -> 61.072925 | D13: =AVERAGE(D9:D12) -> 125216.76 | E13: =AVERAGE(E9:E12) -> 126634.41 | F13: =AVERAGE(F9:F12) -> 7770.725 | G13: =AVERAGE(G9:G12) -> 15324.9 | H13: =AVERAGE(H9:H11) -> 2113.1707 | I13: =AVERAGE(I9:I11) -> 2.51 | J13: =AVERAGE(J9:J11) -> 25.707467 | K13: =AVERAGE(K9:K11) -> 9.2438333 | L13: =AVERAGE(L9:L11) -> 17.324133
B14: 1st Quartile (excl. Pfizer) | C14: =_xlfn.QUARTILE.EXC(C9:C12,1) -> 52.162925 | D14: =_xlfn.QUARTILE.EXC(D9:D12,1) -> 90890.88 | E14: =_xlfn.QUARTILE.EXC(E9:E12,1) -> 90845.68 | F14: =_xlfn.QUARTILE.EXC(F9:F12,1) -> 4610.025 | G14: =_xlfn.QUARTILE.EXC(G9:G12,1) -> 7596.75 | H14: =_xlfn.QUARTILE.EXC(H9:H12,1) -> 1326.7918 | I14: =_xlfn.QUARTILE.EXC(I9:I12,1) -> 1.995 | J14: =_xlfn.QUARTILE.EXC(J9:J12,1) -> 19.45205 | ... L14: =_xlfn.QUARTILE.EXC(L9:L12,1) -> 13.607575
B15: Median (excl. Pfizer) | C15: =MEDIAN(C9:C12) -> 57.37585 | D15: =MEDIAN(D9:D12) -> 116215.32 | E15: =MEDIAN(E9:E12) -> 121801.92 | F15: =MEDIAN(F9:F12) -> 7688 | G15: =MEDIAN(G9:G12) -> 14981.3 | H15: =MEDIAN(H9:H12) -> 2091.3005 | I15: =MEDIAN(I9:I12) -> 2.505 | J15: =MEDIAN(J9:J12) -> 26.5471 | ... L15: =MEDIAN(L9:L12) -> 17.66435
B16: 3rd Quartile (excl. Pfizer) | C16: =_xlfn.QUARTILE.EXC(C9:C12,3) -> 73.68 | D16: =_xlfn.QUARTILE.EXC(D9:D12,3) -> 168544.07 | E16: =_xlfn.QUARTILE.EXC(E9:E12,3) -> 167255.62 | F16: =_xlfn.QUARTILE.EXC(F9:F12,3) -> 11014.15 | G16: =_xlfn.QUARTILE.EXC(G9:G12,3) -> 23396.65 | H16: =_xlfn.QUARTILE.EXC(H9:H12,3) -> 2789.3255 | I16: =_xlfn.QUARTILE.EXC(I9:I12,3) -> 2.9925 | J16: =_xlfn.QUARTILE.EXC(J9:J12,3) -> 30.320925 | ... L16: =_xlfn.QUARTILE.EXC(L9:L12,3) -> 20.377425
B17: Bloomberg (as of 16.04.2018)
B20: 1. Value Multiples based on Cash Flows
B21: Comparable Pharma Companies | C21: Enterprise Value | D21: EBITDA (1) | E21: EBITDA (2) | F21: EV/EBITDA (1) | G21: EV/EBITDA (2) | H21: EV Pfizer (Calculated) | I21: EV Pfizer
B22: in Millions of USD except per share
B23: Pfizer Inc. | C23: =E8 -> 250782.88 | D23: =F8 -> 11776 | E23: =C23/F23 -> 11776 | F23: =L8 -> 21.2961 | G23: =C23/D23 -> 21.2961
B24: Eli Lilly and Co | C24: =E9 -> 87982.678 | D24: =F9 -> 4184.7 | E24: =C24/F24 -> 4184.7094 | F24: =L9 -> 21.0248 | G24: =C24/D24 -> 21.024847 | H24: =$D$23*F24 -> 247588.04 | I24: =$E$23*G24 -> 247588.6
B25: Johnson & Johnson | C25: =E10 -> 174951.11 | D25: =F10 -> 9490 | E25: =C25/F25 -> 9490.0064 | F25: =L10 -> 18.4353 | G25: =C25/D25 -> 18.435312 | H25: =$D$23*F25 -> 217094.09 | I25: =$E$23*G25 -> 217094.24
B26: Merck & Co. | C26: =E11 -> 144169.15 | D26: =F11 -> 11522.2 | E26: =C26/F26 -> 11522.194 | F26: =L11 -> 12.5123 | G26: =C26/D26 -> 12.512293 | H26: =$D$23*F26 -> 147344.84 | I26: =$E$23*G26 -> 147344.77
B27: Bristol-Myers Squibb | C27: =E12 -> 99434.685 | D27: =F12 -> 5886 | E27: =C27/F27 -> 5886.0078 | F27: =L12 -> 16.8934 | G27: =C27/D27 -> 16.893423 | H27: =$D$23*F27 -> 198936.68 | I27: =$E$23*G27 -> 198936.95
B28: Median Peer Group | C28: =MEDIAN(C24:C27) -> 121801.92 | D28: =MEDIAN(D24:D27) -> 7688 | E28: =MEDIAN(E24:E27) -> 7688.0071 | F28: =MEDIAN(F24:F27) -> 17.66435 | G28: =MEDIAN(G24:G27) -> 17.664367 | H28: =MEDIAN(H24:H27) -> 208015.39 | I28: =MEDIAN(I24:I27) -> 208015.59
B29: 1st Quartile (excl. Pfizer) | C29: =_xlfn.QUARTILE.EXC(C24:C27,1) -> 90845.68 | D29: =_xlfn.QUARTILE.EXC(D24:D27,1) -> 4610.025 | E29: =_xlfn.QUARTILE.EXC(E24:E27,1) -> 4610.034 | F29: =_xlfn.QUARTILE.EXC(F24:F27,1) -> 13.607575 | G29: =_xlfn.QUARTILE.EXC(G24:G27,1) -> 13.607576 | H29: =_xlfn.QUARTILE.EXC(H24:H27,1) -> 160242.8 | I29: =_xlfn.QUARTILE.EXC(I24:I27,1) -> 160242.81
B30: 3rd Quartile (excl. Pfizer) | C30: =_xlfn.QUARTILE.EXC(C24:C27,3) -> 167255.62 | D30: =_xlfn.QUARTILE.EXC(D24:D27,3) -> 11014.15 | E30: =_xlfn.QUARTILE.EXC(E24:E27,3) -> 11014.147 | F30: =_xlfn.QUARTILE.EXC(F24:F27,3) -> 20.377425 | G30: =_xlfn.QUARTILE.EXC(G24:G27,3) -> 20.377463 | H30: =_xlfn.QUARTILE.EXC(H24:H27,3) -> 239964.56 | I30: =_xlfn.QUARTILE.EXC(I24:I27,3) -> 239965.01
B31: Bloomberg (as of 16.04.2018)
B34: 2. Multiples Based on Assets
B35: Comparable Pharma Companies | C35: Price per Share | D35: Shares Outstanding | E35: MV of Equity | F35: Bookvalue of Equity | G35: Price/Book Ratio (1) | H35: Price/Book Ratio (2) | I35: BV Equity based on P/B (1) | J35: BV Equity based on P/B (1) | K35: EV Nike based on P/B (2)
B36: in Millions of USD except per share
B37: Pfizer Inc. | C37: =C8 -> 39.85 | D37: =H8 -> 6162.164 | E37: =C37*D37 -> 245562.24 | F37: =G8 -> 18293 | G37: =E37/F37 -> 13.423836 | H37: =K8 -> 13.674
B38: Eli Lilly and Co | C38: =C9 -> 78.54 | D38: =H9 -> 1123.374 | E38: =C38*D38 -> 88229.794 | F38: =G9 -> 7104 | G38: =E38/F38 -> 12.419735 | H38: =K9 -> 12.4195 | I38: =$F$37*G38 -> 227194.2 | J38: =$F$37*H38 -> 227189.91 | K38: =J38+$C$63 -> 236061.91
B39: Johnson & Johnson | C39: =C10 -> 59.1 | D39: =H10 -> 2970.582 | E39: =C39*D39 -> 175561.4 | F39: =G10 -> 24233 | G39: =E39/F39 -> 7.244724 | H39: =K10 -> 7.4316 | I39: =$F$37*G39 -> 132527.74 | J39: =$F$37*H39 -> 135946.26 | K39: =J39+$C$63 -> 144818.26
B40: Merck & Co. | C40: =C11 -> 55.6517 | D40: =H11 -> 2245.556 | E40: =C40*D40 -> 124969.01 | F40: =G11 -> 20887.6 | G40: =E40/F40 -> 5.9829281 | H40: =K11 -> 7.8804 | I40: =$F$37*G40 -> 109445.7 | J40: =$F$37*H40 -> 144156.16 | K40: =J40+$C$63 -> 153028.16
B41: Bristol-Myers Squibb | C41: =C12 -> 51 | D41: =H12 -> 1937.045 | E41: =C41*D41 -> 98789.295 | F41: =G12 -> 9075 | G41: =E41/F41 -> 10.885873 | H41: =K12 -> 12.3622 | I41: =$F$37*G41 -> 199135.27 | J41: =$F$37*H41 -> 226141.72 | K41: =J41+$C$63 -> 235013.72
B42: Median Peer Group | C42: =MEDIAN(C38:C41) -> 57.37585 | D42: =MEDIAN(D38:D41) -> 2091.3005 | E42: =MEDIAN(E38:E41) -> 111879.15 | F42: =MEDIAN(F38:F41) -> 14981.3 | G42: =MEDIAN(G38:G41) -> 9.0652984 | H42: =MEDIAN(H38:H41) -> 10.1213 | I42: =MEDIAN(I38:I41) -> 165831.5 | J42: =MEDIAN(J38:J41) -> 185148.94 | K42: =MEDIAN(K38:K41) -> 194020.94
B43: 1st Quartile (excl. Pfizer) | C43: =_xlfn.QUARTILE.EXC(C38:C41,1) -> 52.162925 | D43: =_xlfn.QUARTILE.EXC(D38:D41,1) -> 1326.7918 | E43: =_xlfn.QUARTILE.EXC(E38:E41,1) -> 90869.669 | F43: =_xlfn.QUARTILE.EXC(F38:F41,1) -> 7596.75 | G43: =_xlfn.QUARTILE.EXC(G38:G41,1) -> 6.2983771 | H43: =_xlfn.QUARTILE.EXC(H38:H41,1) -> 7.5438 | I43: =_xlfn.QUARTILE.EXC(I38:I41,1) -> 115216.21 | J43: =_xlfn.QUARTILE.EXC(J38:J41,1) -> 137998.73 | K43: =_xlfn.QUARTILE.EXC(K38:K41,1) -> 146870.73
B44: 3rd Quartile (excl. Pfizer) | C44: =_xlfn.QUARTILE.EXC(C38:C41,3) -> 73.68 | D44: =_xlfn.QUARTILE.EXC(D38:D41,3) -> 2789.3255 | E44: =_xlfn.QUARTILE.EXC(E38:E41,3) -> 162913.3 | F44: =_xlfn.QUARTILE.EXC(F38:F41,3) -> 23396.65 | G44: =_xlfn.QUARTILE.EXC(G38:G41,3) -> 12.036269 | H44: =_xlfn.QUARTILE.EXC(H38:H41,3) -> 12.405175 | I44: =_xlfn.QUARTILE.EXC(I38:I41,3) -> 220179.47 | J44: =_xlfn.QUARTILE.EXC(J38:J41,3) -> 226927.87 | K44: =_xlfn.QUARTILE.EXC(K38:K41,3) -> 235799.87
B45: Bloomberg (as of 16.04.2018)
B48: 3. Price Multiples based on Cash Flows
B49: Comparable Pharma Companies | C49: Price per Share | D49: Diluted EPS | E49: P/E (1) | F49: P/E (2) | G49: Market Share Price (2) | H49: Market Value of Equity | I49: EV Pfizer
B50: in Millions of USD except per share
...

Sheet 1.2 DCF Analysis
E2: Pfizer Inc (Pfizer US) DCF Valuation
E5: In Millions of USD | I5: FY 1997 A | J5: FY 1998 A | K5: FY 1999 A | L5: FY 2000 A | M5: FY 2001 A | N5: Est. Growth Rates | O5: FY 2002 E | P5: FY 2003 E | Q5: FY 2004 E | R5: FY 2005 E | S5: FY 2006 E
E7: Revenues | I7: ='3.1 Income Statements'!C9 -> 12504 | J7: ='3.1 Income Statements'!D9 -> 13544 | K7: ='3.1 Income Statements'!E9 -> 27376 | L7: ='3.1 Income Statements'!F9 -> 29355 | M7: ='3.1 Income Statements'!G9 -> 29024 | N7: =MEDIAN(J10:M10) -> 0.077731491 | O7: =M7*($N$7+1) -> 31280.079 | P7: =($N$7+1)*O7 -> 33711.526 | Q7: =($N$7+1)*P7 -> 36331.973 | R7: =($N$7+1)*Q7 -> 39156.112 | S7: =($N$7+1)*R7 -> 42199.774
E8: (+) Other Operating Income | I8: ='3.1 Income Statements'!C10 -> — | J8: ='3.1 Income Statements'!D10 -> — | K8: ='3.1 Income Statements'!E10 -> — | L8: ='3.1 Income Statements'!F10 -> — | M8: ='3.1 Income Statements'!G10 -> — | O8: ='3.1 Income Statements'!I10 -> — | P8: ='3.1 Income Statements'!J10 -> — | Q8: ='3.1 Income Statements'!K10 -> — | R8: ='3.1 Income Statements'!L10 -> — | S8: ='3.1 Income Statements'!M10 -> —
E9: (-) Operating Expenses | I9: ='3.1 Income Statements'!C15 -> 6206 | J9: ='3.1 Income Statements'!D15 -> 8856 | K9: ='3.1 Income Statements'!E15 -> 14846 | L9: ='3.1 Income Statements'!F15 -> 15658 | M9: ='3.1 Income Statements'!G15 -> 14493 | O9: =M9*($N$7+1) -> 15619.562 | P9: =O9*($N$7+1) -> 16833.694 | Q9: =P9*($N$7+1) -> 18142.203 | R9: =Q9*($N$7+1) -> 19552.423 | S9: =R9*($N$7+1) -> 21072.262
E10: Revenue Growth (y-o-y) | J10: =(J7/I7)-1 -> 0.083173385 | K10: =(K7/J7)-1 -> 1.021264 | L10: =(L7/K7)-1 -> 0.072289597 | M10: =(M7/L7)-1 -> -0.011275762 | O10: =N7 -> 0.077731491 | P10: =N7 -> 0.077731491 | Q10: =N7 -> 0.077731491 | R10: =N7 -> 0.077731491 | S10: =N7 -> 0.077731491
E12: Depreciation & Amortization | I12: ='3.3 CF Statements'!Z102 -> 428 | J12: ='3.3 CF Statements'!Y102 -> 489 | K12: ='3.3 CF Statements'!X102 -> 905 | L12: ='3.3 CF Statements'!W102 -> 968 | M12: ='3.3 CF Statements'!V102 -> 1068 | N12: =N7 -> 0.077731491 | O12: =M12*($N$12+1) -> 1151.0172 | P12: =O12*($N$12+1) -> 1240.4875 | Q12: =P12*($N$12+1) -> 1336.9125 | R12: =Q12*($N$12+1) -> 1440.8327 | S12: =R12*($N$12+1) -> 1552.8307
E14: Operating Income | I14: ='3.1 Income Statements'!C19 -> 3073 | J14: ='3.1 Income Statements'!D19 -> 2594 | K14: ='3.1 Income Statements'!E19 -> 7066 | L14: ='3.1 Income Statements'!F19 -> 8690 | M14: ='3.1 Income Statements'!G19 -> 10708 | N14: =N7 -> 0.077731491 | O14: =M14*($N$14+1) -> 11540.349 | P14: =O14*($N$14+1) -> 12437.397 | Q14: =P14*($N$14+1) -> 13404.175 | R14: =Q14*($N$14+1) -> 14446.101 | S14: =R14*($N$14+1) -> 15569.018
E15: Operating Income Margin | I15: =I14/I7 -> 0.24576136 | J15: =J14/J7 -> 0.19152392 | K15: =K14/K7 -> 0.25810929 | L15: =L14/L7 -> 0.29603134 | M15: =M14/M7 -> 0.36893605 | O15: =O14/O7 -> 0.36893605 | P15: =P14/P7 -> 0.36893605 | Q15: =Q14/Q7 -> 0.36893605 | R15: =R14/R7 -> 0.36893605 | S15: =S14/S7 -> 0.36893605
E16: Operating Income Growth | J16: =(J14/I14)-1 -> -0.15587374 | K16: =(K14/J14)-1 -> 1.7239784 | L16: =(L14/K14)-1 -> 0.229833 | M16: =(M14/L14)-1 -> 0.23222094 | O16: =(O14/M14)-1 -> 0.077731491 | P16: =(P14/O14)-1 -> 0.077731491 | Q16: =(Q14/P14)-1 -> 0.077731491 | R16: =(R14/Q14)-1 -> 0.077731491 | S16: =(S14/R14)-1 -> 0.077731491
E18: Taxes | I18: ='3.1 Income Statements'!C38 -> 775 | J18: ='3.1 Income Statements'!D38 -> 642 | K18: ='3.1 Income Statements'!E38 -> 1968 | L18: ='3.1 Income Statements'!F38 -> 2049 | M18: ='3.1 Income Statements'!G38 -> 2433 | N18: =AVERAGE(I19:M19) -> 0.24824183 | O18: =$N$18*O14 -> 2864.7974 | P18: =$N$18*P14 -> 3087.4823 | Q18: =$N$18*Q14 -> 3327.4769 | R18: =$N$18*R14 -> 3586.1267 | S18: =$N$18*S14 -> 3864.8816
E19: Average Tax Rate | I19: =I18/I14 -> 0.25219655 | J19: =J18/J14 -> 0.24749422 | K19: =K18/K14 -> 0.27851684 | L19: =L18/L14 -> 0.23578826 | M19: =M18/M14 -> 0.2272133 | O19: =$N$18 -> 0.24824183 | P19: =$N$18 -> 0.24824183 | Q19: =$N$18 -> 0.24824183 | R19: =$N$18 -> 0.24824183 | S19: =$N$18 -> 0.24824183
E21: Net Income | I21: =I14-I18 -> 2298 | J21: =J14-J18 -> 1952 | K21: =K14-K18 -> 5098 | L21: =L14-L18 -> 6641 | M21: =M14-M18 -> 8275 | O21: =O14-O18 -> 8675.5514 | P21: =P14-P18 -> 9349.915 | Q21: =Q14-Q18 -> 10076.698 | R21: =R14-R18 -> 10859.975 | S21: =S14-S18 -> 11704.137
E22: Net Income Margin | I22: =I21/I7 -> 0.18378119 | J22: =J21/J7 -> 0.14412286 | K22: =K21/K7 -> 0.18622151 | L22: =L21/L7 -> 0.22623063 | M22: =M21/M7 -> 0.28510888 | O22: =O21/O7 -> 0.27735069 | P22: =P21/P7 -> 0.27735069 | Q22: =Q21/Q7 -> 0.27735069 | R22: =R21/R7 -> 0.27735069 | S22: =S21/S7 -> 0.27735069
E23: Net Income Growth | J23: =(J21/I21)-1 -> -0.15056571 | K23: =(K21/J21)-1 -> 1.6116803 | L23: =(L21/K21)-1 -> 0.30266771 | M23: =(M21/L21)-1 -> 0.24604728 | O23: =(O21/M21)-1 -> 0.048405009 | P23: =(P21/O21)-1 -> 0.077731491 | Q23: =(Q21/P21)-1 -> 0.077731491 | R23: =(R21/Q21)-1 -> 0.077731491 | S23: =(S21/R21)-1 -> 0.077731491
E25: (+) Depreciation & Amortization | I25: =I12 -> 428 | J25: =J12 -> 489 | K25: =K12 -> 905 | L25: =L12 -> 968 | M25: =M12 -> 1068 | N25: =AVERAGE(J26:M26) -> 0.29153954 | O25: =M25*($N$25+1) -> 1379.3642 | P25: =O25*($N$25+1) -> 1781.5034 | Q25: =P25*($N$25+1) -> 2300.8821 | R25: =Q25*($N$25+1) -> 2971.6802 | S25: =R25*($N$25+1) -> 3838.0425
E26: %-Change D&A | J26: =(J25/I25)-1 -> 0.14252336 | K26: =(K25/J25)-1 -> 0.85071575 | L26: =(L25/K25)-1 -> 0.06961326 | M26: =(M25/L25)-1 -> 0.10330579 | O26: =(O25/M25)-1 -> 0.29153954 | P26: =(P25/O25)-1 -> 0.29153954 | Q26: =(Q25/P25)-1 -> 0.29153954 | R26: =(R25/Q25)-1 -> 0.29153954 | S26: =(S25/R25)-1 -> 0.29153954
E27: Net Working Capital | I27: ='3.2 Balance Sheets'!D10+'3.2 Balance Sheets'!D15+'3.2 Balance Sheets'!D12+'3.2 Balance Sheets'!D11-'3.2 Balance Sheets'!D72-'3.2 Balance Sheets'!D86-'3.2 Balance Sheets'!D89-'3.2 Balance Sheets'!D76 -> 410 | J27: ='3.2 Balance Sheets'!E10+'3.2 Balance Sheets'!E15+'3.2 Balance Sheets'!E12+'3.2 Balance Sheets'!E11-'3.2 Balance Sheets'!E72-'3.2 Balance Sheets'!E86-'3.2 Balance Sheets'!E89-'3.2 Balance Sheets'!E76 -> 2671 | K27: ='3.2 Balance Sheets'!F10+'3.2 Balance Sheets'!F15+'3.2 Balance Sheets'!F12+'3.2 Balance Sheets'!F11-'3.2 Balance Sheets'!F72-'3.2 Balance Sheets'!F86-'3.2 Balance Sheets'!F89-'3.2 Balance Sheets'!F76 -> 1628 | L27: ='3.2 Balance Sheets'!G10+'3.2 Balance Sheets'!G15+'3.2 Balance Sheets'!G12+'3.2 Balance Sheets'!G11-'3.2 Balance Sheets'!G72-'3.2 Balance Sheets'!G86-'3.2 Balance Sheets'!G89-'3.2 Balance Sheets'!G76 -> 3593 | M27: ='3.2 Balance Sheets'!H10+'3.2 Balance Sheets'!H15+'3.2 Balance Sheets'!H12+'3.2 Balance Sheets'!H11-'3.2 Balance Sheets'!H72-'3.2 Balance Sheets'!H86-'3.2 Balance Sheets'!H89-'3.2 Balance Sheets'!H76 -> 1362 | N27: =MEDIAN(I27:M27) -> 1628 | O27: =N27 -> 1628 | P27: =O27 -> 1628 | Q27: =P27 -> 1628 | R27: =Q27 -> 1628 | S27: =R27 -> 1628
E28: (-) Change in Net Working Capital | I28: =I27-F35 -> -251 | J28: =J27-I27 -> 2261 | K28: =K27-J27 -> -1043 | L28: =L27-K27 -> 1965 | M28: =M27-L27 -> -2231 | O28: =O27-M27 -> 266 | P28: =P27-O27 -> 0 | Q28: =Q27-P27 -> 0 | R28: =R27-Q27 -> 0 | S28: =S27-R27 -> 0
E29: %-Change in Net Working Capital | I29: =(I27/F35)-1 -> -0.37972769 | J29: =(J27/I27)-1 -> 5.5146341 | K29: =(K27/J27)-1 -> -0.39049045 | L29: =(L27/K27)-1 -> 1.2070025 | M29: =(M27/L27)-1 -> -0.62092959
E30: (-) CAPEX | I30: ='3.2 Balance Sheets'!O156-'3.2 Balance Sheets'!N156+'3.3 CF Statements'!Z102 -> 371 | J30: ='3.2 Balance Sheets'!E33-'3.2 Balance Sheets'!D33+'3.3 CF Statements'!Y102 -> 1466 | K30: ='3.2 Balance Sheets'!F27-'3.2 Balance Sheets'!E27+'3.3 CF Statements'!X102 -> 5175 | L30: ='3.2 Balance Sheets'!G27-'3.2 Balance Sheets'!F27+'3.3 CF Statements'!W102 -> 1708 | M30: ='3.2 Balance Sheets'!H27-'3.2 Balance Sheets'!G27+'3.3 CF Statements'!V102 -> 1426 | N30: =MEDIAN(I30:M30) -> 1466 | O30: =$N$30 -> 1466 | P30: =$N$30 -> 1466 | Q30: =$N$30 -> 1466 | R30: =$N$30 -> 1466 | S30: =$N$30 -> 1466
E33: Free Cash Flow | I33: =I21+I25-I28-I30 -> 2606 | J33: =J21+J25-J28-J30 -> -1286 | K33: =K21+K25-K28-K30 -> 1871 | L33: =L21+L25-L28-L30 -> 3936 | M33: =M21+M25-M28-M30 -> 10148 | O33: =O21+O25-O28-O30 -> 8322.9157 | P33: =P21+P25-P28-P30 -> 9665.4184 | Q33: =Q21+Q25-Q28-Q30 -> 10911.58 | R33: =R21+R25-R28-R30 -> 12365.655 | S33: =S21+S25-S28-S30 -> 14076.179
E35: NWC 1996 | F35: ='3.2 Balance Sheets'!N136+'3.2 Balance Sheets'!N144+'3.2 Balance Sheets'!N142-'3.2 Balance Sheets'!N178-'3.2 Balance Sheets'!N188-'3.2 Balance Sheets'!N190-'3.2 Balance Sheets'!N180 -> 661
E38: Projected Cash Flows | L38: WACC | M38: Discounted Cash Flows
E39: In Millions of USD | G39: FY 2002 E | H39: FY 2003 E | I39: FY 2004 E | J39: FY 2005 E | K39: FY 2006 E | L39: ='2.1 WACC'!V40 -> 0.078 | M39: In Millions of USD | O39: FY 2002 E | P39: FY 2003 E | Q39: FY 2004 E | R39: FY 2005 E | S39: FY 2006 E
E41: Free Cash Flow | G41: =O33 -> 8322.9157 | H41: =P33 -> 9665.4184 | I41: =Q33 -> 10911.58 | J41: =R33 -> 12365.655 | K41: =S33 -> 14076.179 | M41: Present Value of Free Cash Flow | O41: =O43*G41 -> 7720.701 | P41: =P43*H41 -> 8317.3148 | Q41: =Q43*I41 -> 8710.2648 | R41: =R43*J41 -> 9156.7651 | S41: =S43*K41 -> 9669.2097
M42: Discounting Period | O42: 1 | P42: 2 | Q42: 3 | R42: 4 | S42: 5
E43: Present Value of Pfizer Inc. | M43: Discounting Factor | O43: =1/((1+$L$39)^O42) -> 0.92764378 | P43: =1/((1+$L$39)^P42) -> 0.86052299 | Q43: =1/((1+$L$39)^Q42) -> 0.7982588 | R43: =1/((1+$L$39)^R42) -> 0.74049982 | S43: =1/((1+$L$39)^S42) -> 0.68692005
E44: Free cash flow terminal year | F44: =K41 -> 14076.179
E45: Inflation rate (as of 12/2001) | F45: ='3.6 US Inflation Growth Rate'!G41 -> 0.027
E46: GDP growth rate (as of 12/2001) | F46: ='3.5 US GDP Growth Rate'!D32 -> 0.0375
E47: Perpetuity growth rate | F47: =0.25*F45+0.75*F46 -> 0.034875
E48: Terminal Value | F48: =F44*(1+F47)/(L39-F47) -> 337787.5
E49: Discount Factor | F49: =1/((1+L39)^S42) -> 0.68692005
E50: PV of Terminal Value | F50: =F48*F49 -> 232033.01
E52: Enterprise Value (EV) | F52: =F50+O41+P41+Q41+R41+S41 -> 275607.26
E54: Share Price (in $) | F54: =F52/'3.1 Income Statements'!G61 -> 43.324938 | G54: =IF(F54>'3.4 Trading Multiples Bloomberg'!C10,CONCATENATE("undervalued by ",(G56*100),"%"),CONCATENATE("overvalued by ",((-1*G56)*100),"%")) -> undervalued by 8,7%
E55: Source: own calculations
G56: =ROUND(((F54-'3.4 Trading Multiples Bloomberg'!C10)/'3.4 Trading Multiples Bloomberg'!C10),3) -> 0.087

Sheet 2. Input Parameters>>>

Sheet 2.1 WACC
C5: Ticker | D5: PFE US Equity
C6: Company
C7: Start Date | D7: 19871231
C8: End Date | D8: 20171231
C9: Periodicity
C10: Currency | D10: USD
C11: Filing Status Mnemonic | D11: MR
C12: Filing | D12: Most Recent
C13: Units
C15: Field | D15: Mnemonic | E15: Current | F15: FY 2017 | G15: FY 2016 | H15: FY 2015 | I15: FY 2014 | J15: FY 2013 | K15: FY 2012 | L15: FY 2011 | M15: FY 2010 | N15: FY 2009 | O15: FY 2008 | P15: FY 2007 | Q15: FY 2006 | R15: FY 2005 | S15: FY 2004 | T15: FY 2003 | U15: FY 2002 | V15: FY 2001 | W15: FY 2000
F16: Original | G16: Original | H16: Reclassified/Restated | I16: Reclassified/Restated | J16: Reclassified/Restated | K16: Reclassified/Restated | L16: Reclassified/Restated | M16: Reclassified/Restated | N16: Original | O16: Reclassified/Restated | P16: Original | Q16: Reclassified/Restated | R16: Reclassified/Restated | S16: Original | T16: Original | U16: Original | V16: Reclassified/Restated | W16: Reclassified/Restated
C17: Equity
C18: Cost of Equity | D18: WACC_COST_EQUITY | E18: 11.01 | F18: 8.1995 | G18: 7.8075 | H18: 8.9775 | I18: 9.1327 | J18: 8.0077 | K18: 8.5739 | L18: 8.7497 | M18: 9.7856 | N18: 9.4403 | O18: 10.3177 | P18: 11.4422 | Q18: 10.0012 | R18: 9.6622 | S18: 8.0599 | T18: 9.0299 | U18: 10.1052 | V18: 7.9698 | W18: 7.3506
C19: Weight of Equity | D19: WACC_WEIGHT_OF_EQUITY | E19: 83.27 | F19: 83.2692 | G19: 82.4002 | H19: 83.6624 | I19: 84.2222 | J19: 84.2932 | K19: 82.9531 | L19: 80.7861 | M19: 76.0978 | N19: 75.0798 | O19: 87.3154 | P19: 92.0724 | Q19: 95.7842 | R19: 90.4592 | S19: 91.4706 | T19: 94.7975 | U19: 94.1008 | V19: 96.5747 | W19: 98.1707
C20: + Debt
C21: Cost of Debt | D21: WACC_COST_DEBT | E21: 3.1 | F21: 2.6124 | G21: 2.1023 | H21: 1.7342 | I21: 1.6691 | J21: 2.1496 | K21: 1.3741 | L21: 1.3313 | M21: 2.9822 | N21: 3.2186 | O21: 1.2451 | P21: 3.3465 | Q21: 4.2016 | R21: 3.2506 | S21: 2.984 | T21: 1.4641 | U21: 1.7851 | V21: 2.8694 | W21: 3.4487
C22: Weight of Debt | D22: WACC_WEIGHT_OF_DEBT | E22: 16.72 | F22: 16.7227 | G22: 17.5898 | H22: 16.3267 | I22: 15.7653 | J22: 15.6926 | K22: 17.0291 | L22: 19.1918 | M22: 23.874 | N22: 24.889 | O22: 12.6312 | P22: 7.8719 | Q22: 4.1426 | R22: 9.4518 | S22: 8.4416 | T22: 5.1255 | U22: 5.8992 | V22: 3.4253 | W22: 1.8293
C23: + Preferred Equity
C24: Cost of Pref. Equity | D24: WACC_COST_PFD | E24: 0 | F24: 4.7619 | G24: 8.3333 | H24: 7.6923 | I24: 0 | J24: 6.0606 | K24: 5.1282 | L24: 6.6667 | M24: 5.7692 | N24: 8.1967 | O24: 4.1096 | P24: 4.3011 | Q24: 3.5461 | R24: 3.5503 | S24: 2.0725 | T24: 0 | U24: 0 | V24: 0 | W24: 0
C25: Weight of Pref. Equity | D25: WACC_WEIGHT_OF_PREFERRED_EQUITY | E25: 0.01 | F25: 0.0081 | G25: 0.01 | H25: 0.0109 | I25: 0.0125 | J25: 0.0142 | K25: 0.0177 | L25: 0.0222 | M25: 0.0282 | N25: 0.0312 | O25: 0.0534 | P25: 0.0557 | Q25: 0.0732 | R25: 0.0891 | S25: 0.0879 | T25: 0.077 | U25: 0 | V25: 0 | W25: 0
C26: WACC | D26: WACC | E26: 9.69 | F26: 7.2649 | G26: 6.804 | H26: 7.7947 | I26: 7.9549 | J26: 7.0881 | K26: 7.3473 | L26: 7.3255 | M26: 8.1602 | N26: 7.8914 | O26: 9.1684 | P26: 10.8009 | Q26: 9.7562 | R26: 9.0507 | S26: 7.6261 | T26: 8.6352 | U26: 9.6143 | V26: 7.7951 | W26: 7.2792
C28: Capital Structure
C29: + Historical Market Cap | D29: HISTORICAL_MARKET_CAP | E29: 216208 | F29: 216559.38 | G29: 197153.6 | H29: 199329 | I29: 195964.65 | J29: 196001.37 | K29: 182477.06 | L29: 163923 | M29: 140290.12 | N29: 146793.3 | O29: 119471.66 | P29: 153677.53 | Q29: 184511.6 | R29: 171658.52 | S29: 200948.97 | T29: 269532.57 | U29: 188372.34 | V29: 250138.45 | W29: 290444
C30: + Short Term Debt | D30: BS_ST_BORROW | E30: 9953 | F30: 9953 | G30: 10688 | H30: 10159 | I30: 5141 | J30: 6027 | K30: 6424 | L30: 4016 | M30: 5603 | N30: 5469 | O30: 9320 | P30: 5825 | Q30: 2434 | R30: 11589 | S30: 11266 | T30: 8818 | U30: 8669 | V30: 6263 | W30: 4289
C31: + Long Term Debt | D31: BS_LT_BORROW | E31: 33538 | F31: 33538 | G31: 31398 | H31: 28740 | I31: 31541 | J31: 30462 | K31: 31036 | L31: 34926 | M31: 38410 | N31: 43193 | O31: 7963 | P31: 7314 | Q31: 5546 | R31: 6347 | S31: 7279 | T31: 5755 | U31: 3140 | V31: 2609 | W31: 1123
C32: + Preferred Equity and Hybrid Capital | D32: BS_PFD_EQTY_&_HYBRID_CPTL | E32: 21 | F32: 21 | G32: 24 | H32: 26 | I32: 29 | J32: 33 | K32: 39 | L32: 45 | M32: 52 | N32: 61 | O32: 73 | P32: 93 | Q32: 141 | R32: 169 | S32: 193 | T32: 219 | U32: 0 | V32: 0 | W32: 0
C33: Total Capital | D33: WACC_TOTAL_CAPITAL | E33: 260071 | F33: 260071.38 | G33: 239263.6 | H33: 238254 | I33: 232675.65 | J33: 232523.37 | K33: 219976.06 | L33: 202910 | M33: 184355.12 | N33: 195516.3 | O33: 136827.66 | P33: 166909.53 | Q33: 192632.6 | R33: 189763.52 | S33: 219686.97 | T33: 284324.57 | U33: 200181.34 | V33: 259010.45 | W33: 295856
C35: EVA
C36: + Net Op. Profit | D36: WACC_NET_OPER_PROFIT | E36: 13852 | F36: 13851 | G36: 12262 | H36: 12562 | I36: 13179 | J36: 15569 | K36: 15583 | L36: 15167 | M36: 14093 | N36: 11794 | O36: 17174 | P36: 14695 | Q36: 14493 | R36: 14387 | S36: 17150 | T36: 16273 | U36: 12291 | V36: 10622 | W36: 8629
C37: - Cash Op. Taxes | D37: WACC_CASH_OPER_TAXES | E37: 17848 | F37: 17848 | G37: -2243.4942 | H37: -1085.3753 | I37: 6040.1961 | J37: -247.7618 | K37: -16612.403 | L37: 22141.936 | M37: -15867.692 | N37: 2270.0507 | O37: 6515.2769 | P37: 4309.6551 | Q37: 4108.7384 | R37: 8585.9528 | S37: 3631.1973 | T37: -4654.776 | U37: 2758.0119 | V37: 2591.4315 | W37: 3185.0571
C38: + NOPAT | D38: WACC_NOPAT | E38: -3996 | F38: -3997 | G38: 14505.494 | H38: 13647.375 | I38: 7138.8039 | J38: 15816.762 | K38: 32195.403 | L38: -6974.9362 | M38: 29960.692 | N38: 9523.9493 | O38: 10658.723 | P38: 10385.345 | Q38: 10384.262 | R38: 5801.0472 | S38: 13518.803 | T38: 20927.776 | U38: 9532.9881 | V38: 8030.5685 | W38: 5443.9429
C39: Total Invested Capital | D39: WACC_TOTAL_INV_CAPITAL | E39: 133441 | F39: 133441 | G39: 148538 | H39: 145675 | I39: 150193 | J39: 151813 | K39: 161031 | L39: 140542 | M39: 168015 | N39: 167021 | O39: 88132 | P39: 91700 | Q39: 104064 | R39: 106051 | S39: 110304 | T39: 102869 | U39: 38608 | V39: 31216 | W39: 24509
C40: WACC | D40: WACC | E40: 9.69 | F40: 7.2649 | G40: 6.804 | H40: 7.7947 | I40: 7.9549 | J40: 7.0881 | K40: 7.3473 | L40: 7.3255 | M40: 8.1602 | N40: 7.8914 | O40: 9.1684 | P40: 10.8009 | Q40: 9.7562 | R40: 9.0507 | S40: 7.6261 | T40: 8.6352 | U40: 9.6143 | V40: 0.078 | W40: 7.2792
C41: - Capital Charge | D41: WACC_CAPITAL_CHARGE | E41: 12924.3 | F41: 9694.394 | G41: 10106.517 | H41: 11354.985 | I41: 11947.641 | J41: 10760.722 | K41: 11831.352 | L41: 10295.405 | M41: 13710.337 | N41: 13180.261 | O41: 8080.3031 | P41: 9904.4709 | Q41: 10152.696 | R41: 9598.3652 | S41: 8411.9231 | T41: 8882.9406 | U41: 3711.9052 | V41: 2433.3104 | W41: 1784.068
C42: Economic Value Added | D42: WACC_ECON_VALUE_ADDED | E42: -16920.3 | F42: -13691.394 | G42: 4398.9776 | H42: 2292.39 | I42: -4808.837 | J42: 5056.0401 | K42: 20364.051 | L42: -17270.341 | M42: 16250.355 | N42: -3656.3113 | O42: 2578.42 | P42: 480.874 | Q42: 231.5657 | R42: -3797.318 | S42: 5106.8796 | T42: 12044.835 | U42: 5821.0829 | V42: 5597.2581 | W42: 3659.8749
C43: ROIC | D43: WACC_RETURN_ON_INV_CAPITAL | E43: -2.99 | F43: -2.9953 | G43: 9.7655 | H43: 9.3684 | I43: 4.7531 | J43: 10.4186 | K43: 19.9933 | L43: -4.9629 | M43: 17.8322 | N43: 5.7022 | O43: 12.094 | P43: 11.3253 | Q43: 9.9787 | R43: 5.4701 | S43: 12.2559 | T43: 20.3441 | U43: 24.6917 | V43: 25.7258 | W43: 22.212
C44: EVA Spread | D44: WACC_EVA_SPREAD | E44: -12.68 | F44: -10.2603 | G44: 2.9615 | H44: 1.5736 | I44: -3.2018 | J44: 3.3304 | K44: 12.646 | L44: -12.2884 | M44: 9.672 | N44: -2.1891 | O44: 2.9256 | P44: 0.5244 | Q44: 0.2225 | R44: -3.5807 | S44: 4.6298 | T44: 11.7089 | U44: 15.0774 | V44: 17.9307 | W44: 14.9328

Sheet 2.2 Stock & Index Data
B4: History Pharmacia LLC (748957Q US) in USD | K4: History Pfizer in USD | T4: History S&P 500 in USD
B5: Date | C5: Last Price | D5: Volume | E5: Dividends Paid | K5: Date | L5: Last Price | M5: Volume | N5: Dividends Paid | T5: Date | U5: Last Price | V5: Volume
B6: 37726 | C6: 45.06 | D6: 13630000 | K6: 39813 | L6: 17.71 | M6: 102260000 | N6: -2132 | T6: 39813 | U6: 903.25 | V6: 2420000000
B7: 37722 | C7: 43.89 | D7: 20060000 | K7: 39808 | L7: 17.1 | M7: 108890000 | T7: 39808 | U7: 872.8 | V7: 2400000000
B8: 37715 | C8: 45.8 | D8: 19160000 | K8: 39801 | L8: 17.3 | M8: 274720000 | T8: 39801 | U8: 887.88 | V8: 6729999872
B9: 37708 | C9: 44.49 | D9: 21250000 | K9: 39794 | L9: 16.92 | M9: 236990000 | T9: 39794 | U9: 879.73 | V9: 6230000128
B10: 37701 | C10: 44.45 | D10: 26540000 | K10: 39787 | L10: 16.55 | M10: 267130000 | T10: 39787 | U10: 876.07 | V10: 6769999872
B11: 37694 | C11: 40.13 | D11: 18970000 | K11: 39780 | L11: 16.43 | M11: 193940000 | T11: 39780 | U11: 896.24 | V11: 5110000128
B12: 37687 | C12: 41.52 | D12: 23570000 | K12: 39773 | L12: 15.67 | M12: 341940000 | T12: 39773 | U12: 800.03 | V12: 8339999744
B13: 37680 | C13: 41.32 | D13: 37670000 | K13: 39766 | L13: 16.28 | M13: 241740000 | T13: 39766 | U13: 873.29 | V13: 6630000128
B14: 37673 | C14: 39.6 | D14: 18300000 | K14: 39759 | L14: 16.86 | M14: 245500000 | T14: 39759 | U14: 930.99 | V14: 5920000000
B15: 37666 | C15: 39.05 | D15: 21620000 | K15: 39752 | L15: 17.71 | M15: 331880000 | T15: 39752 | U15: 968.75 | V15: 7059999744
B16: 37659 | C16: 40.36 | D16: 25920000 | K16: 39745 | L16: 16.57 | M16: 325489984 | T16: 39745 | U16: 876.77 | V16: 6840000000
B17: 37652 | C17: 41.77 | D17: 26910000 | K17: 39738 | L17: 16.91 | M17: 414729984 | T17: 39738 | U17: 940.55 | V17: 8510000128
B18: 37645 | C18: 41.43 | D18: 28340000 | K18: 39731 | L18: 15.14 | M18: 551670016 | T18: 39731 | U18: 899.22 | V18: 9939999744
B19: 37638 | C19: 41.11 | D19: 29430000 | K19: 39724 | L19: 19 | M19: 352750016 | T19: 39724 | U19: 1099.23 | V19: 8030000128
B20: 37631 | C20: 42.24 | D20: 23070000 | K20: 39717 | L20: 18.66 | M20: 242300000 | N20: -2132 | T20: 39717 | U20: 1213.01 | V20: 6000000000
B21: 37624 | C21: 43.52 | D21: 14240000 | E21: -175 | K21: 39710 | L21: 18.55 | M21: 402440000 | T21: 39710 | U21: 1255.07 | V21: 10350000128
B22: 37617 | C22: 40.5 | D22: 14770000 | K22: 39703 | L22: 18.62 | M22: 218510000 | T22: 39703 | U22: 1251.7 | V22: 6739999744
B23: 37610 | C23: 41.65 | D23: 29260000 | K23: 39696 | L23: 18.51 | M23: 147700000 | T23: 39696 | U23: 1242.31 | V23: 4240000000
B24: 37603 | C24: 41.4 | D24: 26870000 | K24: 39689 | L24: 19.11 | M24: 172740000 | T24: 39689 | U24: 1282.83 | V24: 3760000000
B25: 37596 | C25: 42.18 | D25: 28410000 | K25: 39682 | L25: 19.75 | M25: 158080000 | T25: 39682 | U25: 1292.2 | V25: 4030000128
B26: 37589 | C26: 42.3 | D26: 23560000 | K26: 39675 | L26: 19.97 | M26: 193400000 | T26: 39675 | U26: 1298.2 | V26: 4809999872
B27: 37582 | C27: 43.5 | D27: 36670000 | K27: 39668 | L27: 19.84 | M27: 223850000 | T27: 39668 | U27: 1296.32 | V27: 5379999744
B28: 37575 | C28: 45.24 | D28: 20940000 | K28: 39661 | L28: 18.6 | M28: 191360000 | T28: 39661 | U28: 1260.31 | V28: 5710000128
B29: 37568 | C29: 46 | D29: 27530000 | K29: 39654 | L29: 18.89 | M29: 248080000 | T29: 39654 | U29: 1257.76 | V29: 6440000000
B30: 37561 | C30: 43.55 | D30: 26620000 | K30: 39647 | L30: 18.32 | M30: 245450000 | T30: 39647 | U30: 1260.68 | V30: 7710000128
B31: 37554 | C31: 42.9 | D31: 26590000 | K31: 39640 | L31: 17.81 | M31: 258270000 | T31: 39640 | U31: 1239.49 | V31: 6990000128
B32: 37547 | C32: 45.3 | D32: 27180000 | K32: 39633 | L32: 17.75 | M32: 160140000 | T32: 39633 | U32: 1262.9 | V32: 4899999744
B33: 37540 | C33: 40.75 | D33: 25670000 | K33: 39626 | L33: 17.28 | M33: 274060000 | N33: -2139 | T33: 39626 | U33: 1278.38 | V33: 6280000000
B34: 37533 | C34: 38.33 | D34: 33700000 | E34: -178 | K34: 39619 | L34: 17.33 | M34: 324340000 | T34: 39619 | U34: 1317.93 | V34: 6070000128
B35: 37526 | C35: 38.24 | D35: 38100000 | K35: 39612 | L35: 17.99 | M35: 270689984 | T35: 39612 | U35: 1360.03 | V35: 6129999872
B36: 37519 | C36: 38.4 | D36: 24320000 | K36: 39605 | L36: 17.96 | M36: 346310016 | T36: 39605 | U36: 1360.68 | V36: 5769999872
B37: 37512 | C37: 39.9 | D37: 21400000 | K37: 39598 | L37: 19.36 | M37: 172370000 | T37: 39598 | U37: 1400.38 | V37: 4080000000
B38: 37505 | C38: 40.86 | D38: 21970000 | K38: 39591 | L38: 19.53 | M38: 288220000 | T38: 39591 | U38: 1375.93 | V38: 5249999872
B39: 37498 | C39: 43.7 | D39: 21630000 | K39: 39584 | L39: 20.03 | M39: 198980000 | T39: 39584 | U39: 1425.35 | V39: 5369999872
B40: 37491 | C40: 45.54 | D40: 19210000 | K40: 39577 | L40: 19.79 | M40: 212470000 | T40: 39577 | U40: 1388.28 | V40: 5489999872
B41: 37484 | C41: 44.1 | D41: 30710000 | K41: 39570 | L41: 20.61 | M41: 247290000 | T41: 39570 | U41: 1413.9 | V41: 5689999872
B42: 37477 | C42: 43.1617 | D42: 35790000 | K42: 39563 | L42: 20.43 | M42: 264270000 | T42: 39563 | U42: 1397.84 | V42: 5689999872
B43: 37470 | C43: 40.3795 | D43: 44560000 | K43: 39556 | L43: 20.47 | M43: 243090000 | T43: 39556 | U43: 1390.33 | V43: 5600000000
...

Sheet 2.3 Assumptions Pfizer
B8: M&A | O8: Pfizer Inc. US
B9: Assumptions | F9: Actual | K9: Projected | O9: Income Statement | T9: Actual | Y9: Projected
B10: in Millions of USD | D10: 1997 | E10: 1998 | F10: 1999 | G10: 2000 | H10: 2001 | I10: 2002 | J10: 2003 | K10: 2004 | L10: 2005 | M10: 2006 | O10: in Millions of USD | R10: 1997 | S10: 1998 | T10: 1999 | U10: 2000 | V10: 2001 | W10: 2002 | X10: 2003 | Y10: 2004 | Z10: 2005 | AA10: 2006
B12: Operating assumptions - Stable growth | P12: Income Statement
D13: 1997 | E13: 1998 | F13: 1999 | G13: 2000 | H13: 2001 | I13: 2002 | J13: 2003 | K13: 2004 | L13: 2005 | M13: 2006
B14: Income statement | P14: Sales | R14: ='3.1 Income Statements'!C9 -> 12504 | S14: ='3.1 Income Statements'!D9 -> 13544 | T14: ='3.1 Income Statements'!E9 -> 27376 | U14: ='3.1 Income Statements'!F9 -> 29355 | V14: ='3.1 Income Statements'!G9 -> 29024 | W14: =(1+I15)*V14 -> 31280.079 | X14: =(1+J15)*W14 -> 33711.526 | Y14: =(1+K15)*X14 -> 36331.973 | Z14: =(1+L15)*Y14 -> 39156.112 | AA14: =(1+M15)*Z14 -> 42199.774
B15: Sales growth | D15: NA | E15: =('3.1 Income Statements'!D9/'3.1 Income Statements'!C9)-1 -> 0.083173385 | F15: =('3.1 Income Statements'!E9/'3.1 Income Statements'!D9)-1 -> 1.021264 | G15: =('3.1 Income Statements'!F9/'3.1 Income Statements'!E9)-1 -> 0.072289597 | H15: =('3.1 Income Statements'!G9/'3.1 Income Statements'!F9)-1 -> -0.011275762 | I15: ='1.2 DCF Analysis'!O10 -> 0.077731491 | J15: ='1.2 DCF Analysis'!P10 -> 0.077731491 | K15: ='1.2 DCF Analysis'!Q10 -> 0.077731491 | L15: ='1.2 DCF Analysis'!R10 -> 0.077731491 | M15: ='1.2 DCF Analysis'!S10 -> 0.077731491 | P15: Cost of sales | R15: =-('3.1 Income Statements'!C11) -> -1776 | S15: =-('3.1 Income Statements'!D11) -> -2094 | T15: =-('3.1 Income Statements'!E11) -> -5464 | U15: =-('3.1 Income Statements'!F11) -> -5007 | V15: =-('3.1 Income Statements'!G11) -> -3823 | W15: =-(I16*W14) -> -4100.8183 | X15: =-(J16*X14) -> -4251.0234 | Y15: =-(K16*Y14) -> -4399.8019 | Z15: =-(L16*Z14) -> -4546.0245 | AA15: =-(M16*AA14) -> -4688.3949
B16: COGS as % of sales | D16: =-R15/R14 -> 0.14203455 | E16: =-S15/S14 -> 0.15460721 | F16: =-T15/T14 -> 0.19959088 | G16: =-U15/U14 -> 0.17056719 | H16: =-V15/V14 -> 0.13171858 | I16: =6*-0.005+0.1611 -> 0.1311 | J16: =7*-0.005+0.1611 -> 0.1261 | K16: =8*-0.005+0.1611 -> 0.1211 | L16: =9*-0.005+0.1611 -> 0.1161 | M16: =10*-0.005+0.1611 -> 0.1111 | P16: SG&A | R16: =-('3.1 Income Statements'!C15-'3.1 Income Statements'!C17) -> -4401 | S16: =-('3.1 Income Statements'!D15-'3.1 Income Statements'!D17) -> -6577 | T16: =-('3.1 Income Statements'!E15-'3.1 Income Statements'!E17) -> -12070 | U16: =-('3.1 Income Statements'!F15-'3.1 Income Statements'!F17) -> -11223 | V16: =-('3.1 Income Statements'!G15-'3.1 Income Statements'!G17) -> -9646 | W16: =-('1.2 DCF Analysis'!O9+'2.3 Assumptions Pfizer'!W17) -> -11039.507 | X16: =-('1.2 DCF Analysis'!P9+'2.3 Assumptions Pfizer'!X17) -> -11897.624 | Y16: =-('1.2 DCF Analysis'!Q9+'2.3 Assumptions Pfizer'!Y17) -> -12822.445 | Z16: =-('1.2 DCF Analysis'!R9+'2.3 Assumptions Pfizer'!Z17) -> -13819.152 | AA16: =-('1.2 DCF Analysis'!S9+'2.3 Assumptions Pfizer'!AA17) -> -14893.336
B17: SG&A, Others as % of sales | D17: =-R16/R14 -> 0.35196737 | E17: =-S16/S14 -> 0.48560248 | F17: =-T16/T14 -> 0.44089714 | G17: =-U16/U14 -> 0.38231988 | H17: =-V16/V14 -> 0.33234564 | I17: =-W16/W14 -> 0.35292453 | J17: =-X16/X14 -> 0.35292453 | K17: =-Y16/Y14 -> 0.35292453 | ... M17: =-AA16/AA14 -> 0.35292453 | P17: R&D expenses | R17: =-('3.1 Income Statements'!C17) -> -1805 | S17: =-('3.1 Income Statements'!D17) -> -2279 | T17: =-('3.1 Income Statements'!E17) -> -2776 | U17: =-('3.1 Income Statements'!F17) -> -4435 | V17: =-('3.1 Income Statements'!G17) -> -4847 | W17: =-(I18*W14) -> -4580.0554 | X17: =-(J18*X14) -> -4936.0699 | Y17: =-(K18*Y14) -> -5319.758 | Z17: =-(L18*Z14) -> -5733.2707 | AA17: =-(M18*AA14) -> -6178.9264
B18: R&D as % of sales | D18: =-(R17/R14) -> 0.14435381 | E18: =-(S17/S14) -> 0.16826639 | F18: =-(T17/T14) -> 0.10140269 | G18: =-(U17/U14) -> 0.15108159 | H18: =-(V17/V14) -> 0.16699972 | I18: =AVERAGE($D$18,$E$18,$F$18,$G$18,$H$18) -> 0.14642084 | J18: =AVERAGE($D$18,$E$18,$F$18,$G$18,$H$18) -> 0.14642084 | K18: =AVERAGE($D$18,$E$18,$F$18,$G$18,$H$18) -> 0.14642084 | L18: =AVERAGE($D$18,$E$18,$F$18,$G$18,$H$18) -> 0.14642084 | M18: =AVERAGE($D$18,$E$18,$F$18,$G$18,$H$18) -> 0.14642084 | P18: EBITDA | R18: =SUM(R14,R15,R16,R17) -> 4522 | S18: =SUM(S14,S15,S16,S17) -> 2594 | T18: =SUM(T14,T15,T16,T17) -> 7066 | U18: =SUM(U14,U15,U16,U17) -> 8690 | V18: =SUM(V14,V15,V16,V17) -> 10708 | W18: =SUM(W14,W15,W16,W17) -> 11559.698 | X18: =SUM(X14,X15,X16,X17) -> 12626.808 | Y18: =SUM(Y14,Y15,Y16,Y17) -> 13789.969 | ... AA18: =SUM(AA14,AA15,AA16,AA17) -> 16439.118
B19: Effective tax rate | D19: 0.1967 | E19: 0.1967 | F19: 0.3119 | G19: 0.2269 | H19: 0.1873 | I19: 0.4 | J19: 0.4 | K19: 0.4 | L19: 0.4 | M19: 0.4 | P19: % margin | R19: =R18/R14 -> 0.36164427 | S19: =S18/S14 -> 0.19152392 | T19: =T18/T14 -> 0.25810929 | U19: =U18/U14 -> 0.29603134 | V19: =V18/V14 -> 0.36893605 | W19: =W18/W14 -> 0.36955463 | X19: =X18/X14 -> 0.37455463 | Y19: =Y18/Y14 -> 0.37955463 | ... AA19: =AA18/AA14 -> 0.38955463
B21: Balance Sheet | P21: Depreciation & amortization* | R21: =-('3.3 CF Statements'!Z102) -> -428 | S21: =-('3.3 CF Statements'!Y102) -> -489 | T21: =-('3.3 CF Statements'!X102) -> -905 | U21: =-('3.3 CF Statements'!W102) -> -968 | V21: =-('3.3 CF Statements'!V102) -> -1068 | W21: 0 | X21: 0 | Y21: 0 | Z21: 0 | AA21: 0
B22: NC-WC as % of sales | D22: 0.3086239 | E22: 0.33093823 | F22: 0.23744292 | G22: 0.14322978 | H22: 0.13501988 | I22: =AVERAGE($E$22:$H$22) -> 0.2116577 | J22: =AVERAGE($E$22:$H$22) -> 0.2116577 | K22: =AVERAGE($E$22:$H$22) -> 0.2116577 | L22: =AVERAGE($E$22:$H$22) -> 0.2116577 | M22: =AVERAGE($E$22:$H$22) -> 0.2116577 | P22: EBIT | R22: =R18+R21 -> 4094 | S22: =S18+S21 -> 2105 | T22: =T18+T21 -> 6161 | U22: =U18+U21 -> 7722 | V22: =V18+V21 -> 9640 | W22: =W18+W21 -> 11559.698 | X22: =X18+X21 -> 12626.808 | Y22: =Y18+Y21 -> 13789.969 | ... AA22: =AA18+AA21 -> 16439.118
P23: % margin | R23: =R22/R14 -> 0.32741523 | S23: =S22/S14 -> 0.15541937 | T23: =T22/T14 -> 0.22505114 | U23: =U22/U14 -> 0.2630557 | V23: =V22/V14 -> 0.33213892 | W23: =W22/W14 -> 0.36955463 | X23: =X22/X14 -> 0.37455463 | Y23: =Y22/Y14 -> 0.37955463 | ... AA23: =AA22/AA14 -> 0.38955463
B24: Cash Flow Statement | P24: Source: own calculations
B25: D&A as % of sales | D25: 0.06481235 | E25: 0.07157662 | F25: 0.069710807 | G25: 0.05003557 | H25: 0.044163354 | I25: =AVERAGE($D$25:$H$25) -> 0.06005974 | J25: =AVERAGE($D$25:$H$25) -> 0.06005974 | K25: =AVERAGE($D$25:$H$25) -> 0.06005974 | L25: =AVERAGE($D$25:$H$25) -> 0.06005974 | M25: =AVERAGE($D$25:$H$25) -> 0.06005974
B26: Capex as % of sales | D26: 0.085706681 | E26: 0.11869559 | F26: 0.10216134 | G26: 0.061180934 | H26: 0.073726057 | I26: =AVERAGE($E$26:$H$26) -> 0.088940981 | J26: =AVERAGE($E$26:$H$26) -> 0.088940981 | K26: =AVERAGE($E$26:$H$26) -> 0.088940981 | L26: =AVERAGE($E$26:$H$26) -> 0.088940981 | M26: =AVERAGE($E$26:$H$26) -> 0.088940981
B27: Source: own calculations
Q30: =W16/W14 -> -0.35292453

Sheet 3. Financial Statements>>>

Sheet 3.1 Income Statements
B5: Pfizer Inc (PFE US) - Adjusted
B7: In Millions of USD except Per Share | C7: FY 1997 | D7: FY 1998 | E7: FY 1999 | F7: FY 2000 | G7: FY 2001 | H7: FY 2002 | I7: FY 2003 | J7: FY 2004 | K7: FY 2005 | L7: FY 2006 | M7: FY 2007 | N7: FY 2008 | O7: FY 2009 | P7: FY 2010 | Q7: FY 2011 | R7: FY 2012 | S7: FY 2013 | T7: FY 2014 | U7: FY 2015 | V7: FY 2016 | W7: FY 2017
B8: 12 Months Ending | C8: 12/31/1997 | D8: 12/31/1998 | E8: 12/31/1999 | F8: 12/31/2000 | G8: 12/31/2001 | H8: 12/31/2002 | I8: 12/31/2003 | J8: 12/31/2004 | K8: 12/31/2005 | L8: 12/31/2006 | M8: 12/31/2007 | N8: 12/31/2008 | O8: 12/31/2009 | P8: 12/31/2010 | Q8: 12/31/2011 | R8: 12/31/2012 | S8: 12/31/2013 | T8: 12/31/2014 | U8: 12/31/2015 | V8: 12/31/2016 | W8: 12/31/2017
B9: Revenue | C9: 12504 | D9: 13544 | E9: 27376 | F9: 29355 | G9: 29024 | H9: 32373 | I9: 45188 | J9: 52516 | K9: 47405 | L9: 48371 | M9: 48418 | N9: 48296 | O9: 49934 | P9: 67039 | Q9: 65259 | R9: 54657 | S9: 51452 | T9: 49605 | U9: 48851 | V9: 52824 | W9: 52546
B10: + Sales & Services Revenue | C10: — | D10: — | E10: — | F10: — | G10: — | H10: — | I10: — | J10: — | K10: — | L10: — | M10: — | N10: — | O10: 49934 | P10: 67039 | Q10: 65259 | R10: 54657 | S10: 51452 | T10: 49605 | U10: 48851 | V10: 52824 | W10: 52546
B11: - Cost of Revenue | C11: 1776 | D11: 2094 | E11: 5464 | F11: 5007 | G11: 3823 | H11: 4045 | I11: 6932 | J11: 7541 | K11: 7232 | L11: 7640 | M11: 7745 | N11: 7040 | O11: 8649 | P11: 15083 | Q11: 13264 | R11: 9493 | S11: 9250 | T11: 9139 | U11: 9433 | V11: 11630 | W11: 11154
B12: + Cost of Goods & Services | C12: — | D12: — | E12: — | F12: — | G12: — | H12: — | I12: — | J12: — | K12: — | L12: — | M12: — | N12: — | O12: 8649 | P12: 15083 | Q12: 13264 | R12: 9493 | S12: 9250 | T12: 9139 | U12: 9433 | V12: 11630 | W12: 11154
B13: Gross Profit | C13: 10728 | D13: 11450 | E13: 21912 | F13: 24348 | G13: 25201 | H13: 28328 | I13: 38256 | J13: 44975 | K13: 40173 | L13: 40731 | M13: 40673 | N13: 41256 | O13: 41285 | P13: 51956 | Q13: 51995 | R13: 45164 | S13: 42202 | T13: 40466 | U13: 39418 | V13: 41194 | W13: 41392
B14: + Other Operating Income | C14: — | D14: — | E14: — | F14: — | G14: — | H14: — | I14: — | J14: — | K14: — | L14: — | M14: — | N14: 0 | O14: 0 | P14: 0 | Q14: 0 | R14: 0 | S14: 0 | T14: 0 | U14: 0 | V14: 0 | W14: 0
B15: - Operating Expenses | C15: 6206 | D15: 8856 | E15: 14846 | F15: 15658 | G15: 14493 | H15: 16012 | I15: 22166 | J15: 27887 | K15: 25968 | L15: 26449 | M15: 25893 | N15: 24200 | O15: 25270 | P15: 34045 | Q15: 32673 | R15: 27082 | S15: 25314 | T15: 25001 | U15: 24009 | V15: 22703 | W15: 25476
B16: + Selling, General & Admin | C16: — | D16: 5568 | E16: 10810 | F16: 11223 | G16: — | H16: — | I16: — | J16: 16903 | K16: 15313 | L16: 15589 | M16: 15626 | N16: 14537 | O16: 14637 | P16: 19302 | Q16: 18733 | R16: 15018 | S16: 14164 | T16: 13720 | U16: 14325 | V16: 14745 | W16: 14768
B17: + Research & Development | C17: 1805 | D17: 2279 | E17: 2776 | F17: 4435 | G17: 4847 | H17: — | I17: — | J17: — | K17: — | L17: — | M17: — | N17: — | O17: 7776 | P17: 9340 | Q17: 8396 | R17: 6955 | S17: 6551 | T17: 7150 | U17: 7646 | V17: 7841 | W17: 7596
B18: + Other Operating Expense | C18: — | D18: — | E18: — | F18: — | G18: — | H18: — | I18: — | J18: — | K18: — | L18: — | M18: — | N18: — | O18: 2857 | P18: 5403 | Q18: 5544 | R18: 5109 | S18: 4599 | T18: 4131 | U18: 2038 | V18: 117 | W18: 3112
B19: Operating Income (Loss) | C19: 3073 | D19: 2594 | E19: 7066 | F19: 8690 | G19: 10708 | H19: 12316 | I19: 16090 | J19: 17088 | K19: 14205 | L19: 14282 | M19: 14780 | N19: 17056 | O19: 16015 | P19: 17911 | Q19: 19322 | R19: 18082 | S19: 16888 | T19: 15465 | U19: 15409 | V19: 18491 | W19: 15916
B20: - Non-Operating (Income) Loss | C20: — | D20: — | E20: — | F20: — | G20: — | H20: — | I20: — | J20: — | K20: — | L20: — | M20: — | N20: — | O20: -771 | P20: 551 | Q20: 692 | R20: 855 | S20: 66 | T20: -393 | U20: 1075 | V20: 1351 | W20: 316
B21: + Interest Expense, Net | C21: — | D21: -42 | E21: -64 | F21: -126 | G21: -273 | H21: -131 | I21: -76 | J21: 1 | K21: -269 | L21: -408 | M21: -1099 | N21: -726 | O21: 487 | P21: 1395 | Q21: 1225 | R21: 1140 | S21: 1011 | T21: 935 | U21: 728 | V21: 716 | W21: 879
B22: + Interest Expense | C22: 147 | D22: 143 | E22: 363 | F22: 432 | G22: 266 | H22: 251 | I22: 270 | J22: 347 | K22: 471 | L22: 517 | M22: 397 | N22: 562 | O22: 1233 | P22: 1797 | Q22: 1681 | R22: 1522 | S22: 1414 | T22: 1360 | U22: 1199 | V22: 1186 | W22: 1270
B23: - Interest Income | C23: — | D23: 185 | E23: 427 | F23: 558 | G23: 539 | H23: 382 | I23: 346 | J23: 346 | K23: 740 | L23: 925 | M23: 1496 | N23: 1288 | O23: 746 | P23: 402 | Q23: 456 | R23: 382 | S23: 403 | T23: 425 | U23: 471 | V23: 470 | W23: 391
B24: + Foreign Exch (Gain) Loss | C24: 26 | D24: — | E24: 11 | F24: 59 | G24: 0 | H24: 40 | I24: 1 | J24: 81 | K24: 8 | L24: — | M24: 0 | N24: 0 | O24: 0 | P24: 0 | Q24: 0 | R24: 0 | S24: 0 | T24: 0 | U24: 806 | V24: 0 | W24: 0
B25: + Other Non-Op (Income) Loss | C25: — | D25: — | E25: — | F25: — | G25: — | H25: — | I25: — | J25: — | K25: — | L25: — | M25: — | N25: — | O25: -1258 | P25: -844 | Q25: -533 | R25: -285 | S25: -945 | T25: -1328 | U25: -459 | V25: 635 | W25: -563
B26: Pretax Income (Loss), Adjusted | C26: 2867 | D26: 2594 | E26: 6945 | F26: 5781 | G26: 9984 | H26: 11796 | I26: 3263 | J26: 14007 | K26: 10800 | L26: 13028 | M26: 9278 | N26: 9694 | O26: 16786 | P26: 17360 | Q26: 18630 | R26: 17227 | S26: 16822 | T26: 15858 | U26: 14334 | V26: 17140 | W26: 15600
B27: - Abnormal Losses (Gains) | C27: -10 | D27: 2156.769 | E27: 343 | F27: 3257 | G27: 853 | H27: 716 | I27: 13108 | J27: 4018 | K27: 9867 | L27: 6116 | M27: 6890 | N27: 3308 | O27: 5959 | P27: 8078 | Q27: 6326 | R27: 5985 | S27: 1106 | T27: 3618 | U27: 5369 | V27: 8789 | W27: 3295
B28: + Acquired In-Process R&D | C28: — | D28: — | E28: — | F28: — | G28: — | H28: — | I28: — | J28: — | K28: — | L28: — | M28: — | N28: — | O28: 20 | P28: 125 | Q28: — | R28: — | S28: — | T28: — | U28: — | V28: — | W28: —
B29: + Merger/Acquisition Expense | C29: — | D29: — | E29: — | F29: — | G29: — | H29: — | I29: — | J29: — | K29: — | L29: — | M29: — | N29: — | O29: 4026 | P29: 3989 | Q29: 1979 | R29: 946 | S29: 376 | T29: 183 | U29: 909 | V29: 1364 | W29: 502
B30: + Disposal of Assets | C30: — | D30: — | E30: — | F30: — | G30: — | H30: — | I30: — | J30: — | K30: — | L30: — | M30: — | N30: — | O30: — | P30: — | Q30: — | R30: — | S30: — | T30: -288 | U30: -232 | V30: -171 | W30: —
B31: + Early Extinguishment of Debt | C31: — | D31: — | E31: — | F31: — | G31: — | H31: — | I31: — | J31: — | K31: — | L31: — | M31: — | N31: — | O31: — | P31: — | Q31: — | R31: — | S31: — | T31: — | U31: — | V31: 162 | W31: 999
B32: + Asset Write-Down | C32: — | D32: 213 | E32: — | F32: — | G32: — | H32: — | I32: — | J32: — | K32: — | L32: — | M32: 2798 | N32: — | O32: — | P32: — | Q32: — | R32: — | S32: — | T32: 469 | U32: 1282 | V32: 3716 | W32: 434
B33: + Impairment of Intangibles | C33: — | D33: — | E33: — | F33: — | G33: — | H33: — | I33: — | J33: — | K33: — | L33: — | M33: — | N33: — | O33: — | P33: — | Q33: — | R33: — | S33: — | T33: — | U33: 323 | V33: 869 | W33: —
B34: + Legal Settlement | C34: — | D34: — | E34: — | F34: — | G34: — | H34: — | I34: — | J34: — | K34: — | L34: — | M34: — | N34: — | O34: — | P34: — | Q34: — | R34: — | S34: — | T34: 993 | U34: 968 | V34: 494 | W34: 237
B35: + Restructuring | C35: — | D35: — | E35: — | F35: — | G35: — | H35: — | I35: — | J35: — | K35: — | L35: — | M35: — | N35: — | O35: — | P35: — | Q35: — | R35: — | S35: — | T35: 168 | U35: 1451 | V35: 1685 | W35: 567
B36: + Other Abnormal Items | C36: — | D36: — | E36: — | F36: — | G36: — | H36: — | I36: — | J36: — | K36: — | L36: — | M36: — | N36: — | O36: 1913 | P36: 3964 | Q36: 4347 | R36: 5039 | S36: 730 | T36: 2093 | U36: 668 | V36: 670 | W36: 556
B37: Pretax Income (Loss), GAAP | C37: 2867 | D37: 2594 | E37: 6945 | F37: 5781 | G37: 9984 | H37: 11796 | I37: 3263 | J37: 14007 | K37: 10800 | L37: 13028 | M37: 9278 | N37: 9694 | O37: 10827 | P37: 9282 | Q37: 12304 | R37: 11242 | S37: 15716 | T37: 12240 | U37: 8965 | V37: 8351 | W37: 12305
B38: - Income Tax Expense (Benefit) | C38: 775 | D38: 642 | E38: 1968 | F38: 2049 | G38: 2433 | H38: 2609 | I38: 1621 | J38: 2665 | K38: 3178 | L38: 1992 | M38: 1023 | N38: 1645 | O38: 2197 | P38: 1071 | Q38: 3909 | R38: 2221 | S38: 4306 | T38: 3120 | U38: 1990 | V38: 1123 | W38: -9048
B39: + Current Income Tax | C39: — | D39: — | E39: — | F39: — | G39: — | H39: — | I39: — | J39: — | K39: — | L39: — | M39: — | N39: — | O39: 11779 | P39: -866 | Q39: 3602 | R39: 1435 | S39: 2580 | T39: 2800 | U39: 2010 | V39: 1823 | W39: 17156
B40: + Deferred Income Tax | C40: — | D40: — | E40: — | F40: — | G40: — | H40: — | I40: — | J40: — | K40: — | L40: — | M40: — | N40: — | O40: -9582 | P40: 1937 | Q40: 307 | R40: 786 | S40: 1726 | T40: 320 | U40: -20 | V40: -700 | W40: -26204
B41: Income (Loss) from Cont Ops | C41: 2092 | D41: 1952 | E41: 4977 | F41: 3732 | G41: 7551 | H41: 9187 | I41: 1642 | J41: 11342 | K41: 7622 | L41: 11036 | M41: 8255 | N41: 8049 | O41: 8630 | P41: 8211 | Q41: 8395 | R41: 9021 | S41: 11410 | T41: 9120 | U41: 6975 | V41: 7228 | W41: 21353
B42: - Net Extraordinary Losses (Gains) | C42: -131 | D42: -1401 | E42: 20 | F42: -8 | G42: -251 | H42: 55 | I42: -2271 | J42: -29 | K42: -475 | L42: -8313 | M42: 69 | N42: -78 | O42: -14 | P42: -77 | Q42: -1654 | R42: -5577 | S42: -10662 | T42: -48 | U42: -11 | V42: -18 | W42: -2
B43: + Discontinued Operations | C43: — | D43: -1401 | E43: 20 | F43: — | G43: — | H43: — | I43: — | J43: — | K43: -498 | L43: -8313 | M43: 69 | N43: — | O43: -14 | P43: -77 | Q43: -1654 | R43: -5577 | S43: -10662 | T43: -48 | U43: -11 | V43: -18 | W43: -2
B44: + XO & Accounting Changes | C44: — | D44: — | E44: — | F44: — | G44: — | H44: — | I44: — | J44: — | K44: 23 | L44: — | M44: — | N44: — | O44: 0 | P44: 0 | Q44: 0 | R44: 0 | S44: 0 | T44: 0 | U44: 0 | V44: 0 | W44: 0
B45: Income (Loss) Incl. MI | C45: 2223 | D45: 3353 | E45: 4957 | F45: 3740 | G45: 7802 | H45: 9132 | I45: 3913 | J45: 11371 | K45: 8097 | L45: 19349 | M45: 8186 | N45: 8127 | O45: 8644 | P45: 8288 | Q45: 10049 | R45: 14598 | S45: 22072 | T45: 9168 | U45: 6986 | V45: 7246 | W45: 21355
...

Sheet 3.2 Balance Sheets
C4: Pfizer Inc (PFE US) - Standardized
C6: In Millions of USD except Per Share | D6: FY 1997 | E6: FY 1998 | F6: FY 1999 | G6: FY 2000 | H6: FY 2001 | I6: FY 2002 | J6: FY 2003 | K6: FY 2004 | L6: FY 2005 | M6: FY 2006 | N6: FY 2007 | O6: FY 2008 | P6: FY 2009 | Q6: FY 2010 | R6: FY 2011 | S6: FY 2012 | T6: FY 2013 | U6: FY 2014 | V6: FY 2015 | W6: FY 2016 | X6: FY 2017
C7: 12 Months Ending | D7: 12/31/1997 | E7: 12/31/1998 | F7: 12/31/1999 | G7: 12/31/2000 | H7: 12/31/2001 | I7: 12/31/2002 | J7: 12/31/2003 | K7: 12/31/2004 | L7: 12/31/2005 | M7: 12/31/2006 | N7: 12/31/2007 | O7: 12/31/2008 | P7: 12/31/2009 | Q7: 12/31/2010 | R7: 12/31/2011 | S7: 12/31/2012 | T7: 12/31/2013 | U7: 12/31/2014 | V7: 12/31/2015 | W7: 12/31/2016 | X7: 12/31/2017
C8: Total Assets
C9: + Cash, Cash Equivalents & STI | D9: 1589 | E9: 3929 | F9: 6386 | G9: 6863 | H9: 8615 | I9: 12551 | J9: 11952 | K9: 19893 | L9: 22226 | M9: 27713 | N9: 25475 | O9: 23731 | P9: 25969 | Q9: 28012 | R9: 26452 | S9: 32399 | T9: 32408 | U9: 36122 | V9: 23290 | W9: 17850 | X9: 19992
C10: + Cash & Cash Equivalents | D10: 877 | E10: 1552 | F10: 2358 | G10: 1099 | H10: 1036 | I10: 1878 | J10: 1520 | K10: 1808 | L10: 2247 | M10: 1827 | N10: 3406 | O10: 2122 | P10: 1978 | Q10: 1735 | R10: 3182 | S10: 10081 | T10: 2183 | U10: 3343 | V10: 3641 | W10: 2595 | X10: 1342
C11: + ST Investments | D11: 712 | E11: 2377 | F11: 4028 | G11: 5764 | H11: 7579 | I11: 10673 | J11: 10432 | K11: 18085 | L11: 19979 | M11: 25886 | N11: 22069 | O11: 21609 | P11: 23991 | Q11: 26277 | R11: 23270 | S11: 22318 | T11: 30225 | U11: 32779 | V11: 19649 | W11: 15255 | X11: 18650
C12: + Accounts & Notes Receiv | D12: 2335 | E12: 2914 | F12: 5368 | G12: 5489 | H12: 5067 | I12: 6184 | J12: 8775 | K12: 9367 | L12: 9103 | M12: 9392 | N12: 9843 | O12: 8958 | P12: 14645 | Q12: 13380 | R12: 13058 | S12: 10675 | T12: 9357 | U12: 8401 | V12: 8176 | W12: 8225 | X12: 8221
C13: + Accounts Receivable, Net | D13: — | E13: 2914 | F13: 5368 | G13: 5489 | H13: 4798 | I13: 5785 | J13: 8775 | K13: 9367 | L13: 9103 | M13: 9392 | N13: 9843 | O13: 8958 | P13: 14645 | Q13: 13380 | R13: 13058 | S13: 10675 | T13: 9357 | U13: 8401 | V13: 8176 | W13: 8225 | X13: 8221
C14: + Notes Receivable, Net | D14: — | E14: — | F14: — | G14: — | H14: — | I14: — | J14: — | K14: — | L14: — | M14: — | N14: — | O14: — | P14: 0 | Q14: 0 | R14: 0 | S14: 0 | T14: 0 | U14: 0 | V14: 0 | W14: 0 | X14: 0
C15: + Inventories | D15: 1461 | E15: 1828 | F15: 2588 | G15: 2702 | H15: 2485 | I15: 2678 | J15: 5837 | K15: 6660 | L15: 5478 | M15: 6111 | N15: 5302 | O15: 4381 | P15: 12403 | Q15: 8275 | R15: 6610 | S15: 6076 | T15: 6166 | U15: 5663 | V15: 7513 | W15: 6783 | X15: 7579
C16: + Raw Materials | D16: 211 | E16: 241 | F16: 464 | G16: 433 | H16: 412 | I16: 403 | J16: 1310 | K16: 1314 | L16: 1349 | M16: 1262 | N16: 885 | O16: 830 | P16: 1378 | Q16: 883 | R16: 785 | S16: 448 | T16: 505 | U16: 510 | V16: 867 | W16: 793 | X16: 788
C17: + Work In Process | D17: 808 | E17: 890 | F17: 977 | G17: 1074 | H17: 1062 | I17: 1142 | J17: 2219 | K17: 2496 | L17: 2373 | M17: 3198 | N17: 2353 | O17: 1527 | P17: 5776 | Q17: 3727 | R17: 3514 | S17: 3374 | T17: 3445 | U17: 3248 | V17: 3932 | W17: 3696 | X17: 3908
C18: + Finished Goods | D18: 442 | E18: 697 | F18: 1147 | G18: 1195 | H18: 1011 | I18: 1133 | J18: 2308 | K18: 2850 | L18: 1756 | M18: 1651 | N18: 2064 | O18: 2024 | P18: 5249 | Q18: 3665 | R18: 2311 | S18: 2254 | T18: 2216 | U18: 1905 | V18: 2714 | W18: 2294 | X18: 2883
C19: + Other Inventory | D19: — | E19: — | F19: — | G19: 0 | H19: 0 | I19: 0 | J19: 0 | K19: 0 | L19: 0 | M19: — | N19: 0 | O19: 0 | P19: 0 | Q19: 0 | R19: 0 | S19: 0 | T19: 0 | U19: 0 | V19: 0 | W19: 0 | X19: 0
C20: + Other ST Assets | D20: 2057 | E20: 1260 | F20: 1969 | G20: 2133 | H20: 3045 | I20: 3368 | J20: 3177 | K20: 3774 | L20: 10028 | M20: 4442 | N20: 6229 | O20: 6006 | P20: 8653 | Q20: 11346 | R20: 14697 | S20: 15681 | T20: 8313 | U20: 5409 | V20: 4825 | W20: 6091 | X20: 5349
C21: + Derivative & Hedging Assets | D21: — | E21: — | F21: — | G21: — | H21: — | I21: — | J21: — | K21: — | L21: — | M21: — | N21: — | O21: — | P21: 526 | Q21: 515 | R21: 357 | S21: 296 | T21: 286 | U21: 1059 | V21: 586 | W21: 566 | X21: —
C22: + Assets Held-for-Sale | D22: — | E22: — | F22: — | G22: — | H22: — | I22: — | J22: — | K22: — | L22: — | M22: — | N22: — | O22: — | P22: 496 | Q22: — | R22: — | S22: — | T22: — | U22: — | V22: 9 | W22: 801 | X22: 12
C23: + Deferred Tax Assets | D23: — | E23: — | F23: — | G23: — | H23: — | I23: — | J23: — | K23: — | L23: — | M23: — | N23: — | O23: — | P23: — | Q23: — | R23: — | S23: 6170 | T23: 4624 | U23: 2566 | V23: 2662 | W23: 3041 | X23: 3050
C24: + Discontinued Operations | D24: — | E24: — | F24: — | G24: — | H24: — | I24: — | J24: — | K24: — | L24: — | M24: — | N24: — | O24: — | P24: — | Q24: 1439 | R24: 5317 | S24: 5944 | T24: 76 | U24: — | V24: — | W24: — | X24: —
C25: + Misc ST Assets | D25: — | E25: — | F25: — | G25: — | H25: — | I25: — | J25: — | K25: — | L25: — | M25: — | N25: — | O25: — | P25: 7631 | Q25: 9392 | R25: 9023 | S25: 3271 | T25: 3327 | U25: 1784 | V25: 1568 | W25: 1683 | X25: 2287
C26: Total Current Assets | D26: 7442 | E26: 9931 | F26: 16311 | G26: 17187 | H26: 19212 | I26: 24781 | J26: 29741 | K26: 39694 | L26: 46835 | M26: 47658 | N26: 46849 | O26: 43076 | P26: 61670 | Q26: 61013 | R26: 60817 | S26: 64831 | T26: 56244 | U26: 55595 | V26: 43804 | W26: 38949 | X26: 41141
C27: + Property, Plant & Equip, Net | D27: 3793 | E27: 4415 | F27: 8685 | G27: 9425 | H27: 9783 | I27: 10712 | J27: 18287 | K27: 18385 | L27: 16233 | M27: 16632 | N27: 15734 | O27: 13287 | P27: 22780 | Q27: 18645 | R27: 15921 | S27: 13213 | T27: 12397 | U27: 11760 | V27: 13766 | W27: 13318 | X27: 13865
C28: Geographic Segments | D28: — | E28: — | F28: — | G28: — | H28: — | I28: — | J28: — | K28: — | L28: — | M28: — | N28: — | O28: — | P28: — | Q28: — | R28: 15921 | S28: 13213 | T28: 12397 | U28: 11761 | V28: 13766 | W28: 13318 | X28: 13865
C29: United States | D29: — | E29: — | F29: — | G29: — | H29: — | I29: — | J29: — | K29: — | L29: — | M29: — | N29: — | O29: — | P29: — | Q29: — | R29: 7893 | S29: 6485 | T29: 5885 | U29: 5575 | V29: 7072 | W29: 6649 | X29: 6971
