Workbook
Name acq: [1]Assumptions!$H$8
Name acq_fye: [1]Assumptions!$H$32
Name acq_price: [1]Assumptions!$J$11
Name assume: [1]Assumptions!$T$11
Name base_year: [2]Control!$D$11
Name case: [1]Assumptions!$T$7
Name cash_rate: [1]Assumptions!$T$20
Name circ: [2]Control!$D$13
Name comments: 'France 10-Year Bond Yield'!$A$211
Name curr: [2]Control!$D$9
Name debt_rate: [1]Assumptions!$T$16
Name eps: [1]Assumptions!$T$41
Name fees: [1]Assumptions!$T$24
Name libor: [3]LBO!$AF$34
Name min_cash: [1]Assumptions!$T$21
Name pct_cash: [1]Assumptions!$T$8
Name project: [2]Control!$D$5
Name sec_338: [1]Assumptions!$T$13
Name synergies: [1]Assumptions!$T$28
Name tax_rate: [1]Assumptions!$T$39
Name tgt: [1]Assumptions!$L$8
Name tgt_price: [1]Assumptions!$N$11
Name type: [1]Assumptions!$T$12
Name year: [1]Assumptions!$T$40

Sheet DATA >>>>

Sheet Capital structure
A1: source Annual reports SANOFI 2011, 2012, 2013, 2014, 2015
A3: Capital structure of Sanofi
A4: (€ million) | B4: 2006 | C4: 2007 | D4: 2008 | E4: 2009 | F4: 2010 | G4: 2011 | H4: 2012 | I4: 2013 | J4: 2014 | K4: 2015
A5: Total Assets | B5: 77763 | C5: 71914 | D5: 71987 | E5: 80049 | F5: 85264 | G5: 100165 | H5: 100407 | I5: 96065 | J5: 97392 | K5: 102321
A6: Equity | B6: 45600 | C6: 44719 | D6: 44571 | E6: 48446 | F6: 53097 | G6: 56219 | H6: 57338 | I6: 56885 | J6: 56120 | K6: 58049
A7: LT Debt | B7: 4499 | C7: 3734 | D7: 4173 | E7: 5961 | F7: 6695 | G7: 12499 | H7: 10719 | I7: 10414 | J7: 13276 | K7: 13118
A9: Debt/Assets | B9: =B7/B5 -> 0.057855278 | C9: =C7/C5 -> 0.05192313 | D9: =D7/D5 -> 0.0579688 | E9: =E7/E5 -> 0.074466889 | F9: =F7/F5 -> 0.078520829 | G9: =G7/G5 -> 0.12478411 | H9: =H7/H5 -> 0.10675551 | I9: =I7/I5 -> 0.10840577 | ... K9: =K7/K5 -> 0.12820438 | L9: =AVERAGE(G9:K9) -> 0.12089297
A10: D/(D+E) | B10: =B7/(B6+B7) -> 0.089802192 | C10: =C7/(C6+C7) -> 0.077064372 | D10: =D7/(D6+D7) -> 0.085610537 | E10: =E7/(E6+E7) -> 0.10956311 | F10: =F7/(F6+F7) -> 0.1119715 | G10: =G7/(G6+G7) -> 0.1818883 | H10: =H7/(H6+H7) -> 0.15750033 | I10: =I7/(I6+I7) -> 0.15474227 | ... K10: =K7/(K6+K7) -> 0.18432701 | L10: =AVERAGE(G10:K10) -> 0.17395315
A11: D/E | B11: =B7/B6 -> 0.098662281 | C11: =C7/C6 -> 0.083499184 | D11: =D7/D6 -> 0.0936259 | E11: =E7/E6 -> 0.12304421 | F11: =F7/F6 -> 0.12608999 | G11: =G7/G6 -> 0.22232697 | H11: =H7/H6 -> 0.18694409 | I11: =I7/I6 -> 0.18307111 | ... K11: =K7/K6 -> 0.2259815 | L11: =AVERAGE(G11:K11) -> 0.21097763

Sheet cost of equity(use Fama French)
A1: Date | B1: Rm-Rf | C1: Year | D1: Mkt-RF % | E1: Mkt-RF | K1: Date | L1: RF | O1: Alpha
A2: 40543 | B2: 0.053727234 | C2: 1991 | D2: 4.77 | E2: =D2/100 -> 0.0477 | F2: Average Market Risk Premium (MRP) | K2: 40543 | L2: ='Raw material'!J2 -> 0.0001 | N2: Monthly: | O2: 0 | P2: Insignificant statistically
A3: 40512 | B3: -0.058287035 | C3: 1992 | D3: -11.31 | E3: =D3/100 -> -0.1131 | F3: in the last 10 years: | N3: Yearly: | O3: =(1+O2)^12-1 -> 0
A4: 40480 | B4: 0.031747717 | C4: 1993 | D4: 25.54 | E4: =D4/100 -> 0.2554 | K4: Yearly risk-free return: | L4: =(1+L2)^12-1 -> 0.0012006602
A5: 40451 | B5: 0.064180578 | C5: 1994 | D5: -0.5 | E5: =D5/100 -> -0.005 | F5: Monthly average: | G5: =AVERAGE(B2:B247) -> 0.0012702854 | O5: Beta:
A6: 40421 | B6: -0.041918322 | C6: 1995 | D6: 13.36 | E6: =D6/100 -> 0.1336 | F6: Yearly average MRP: | G6: =(1+G5)^12-1 -> 0.015350377 | O6: 0.6 | P6: Significant statistically
A7: 40389 | B7: 0.058063345 | C7: 1996 | D7: 16.54 | E7: =D7/100 -> 0.1654
A8: 40359 | B8: -0.018537318 | C8: 1997 | D8: 14.86 | E8: =D8/100 -> 0.1486 | F8: Fama French Annual Mkt-RF in 2010 (European): | G8: =E21 -> 0.0604
A9: 40329 | B9: -0.081166495 | C9: 1998 | D9: 20.51 | E9: =D9/100 -> 0.2051
A10: 40298 | B10: -0.039611727 | C10: 1999 | D10: 14.93 | E10: =D10/100 -> 0.1493
A11: 40268 | B11: 0.071408305 | C11: 2000 | D11: -15.89 | E11: =D11/100 -> -0.1589
A12: 40235 | B12: -0.0081990448 | C12: 2001 | D12: -24.15 | E12: =D12/100 -> -0.2415
A13: 40207 | B13: -0.050013591 | C13: 2002 | D13: -15.92 | E13: =D13/100 -> -0.1592
A14: 40178 | B14: 0.069511293 | C14: 2003 | D14: 41.78 | E14: =D14/100 -> 0.4178
A15: 40147 | B15: 0.020084874 | C15: 2004 | D15: 22.54 | E15: =D15/100 -> 0.2254
A16: 40116 | B16: -0.049459742 | C16: 2005 | D16: 8.73 | E16: =D16/100 -> 0.0873
A17: 40086 | B17: 0.038730833 | C17: 2006 | D17: 32.23 | E17: =D17/100 -> 0.3223
A18: 40056 | B18: 0.066231608 | C18: 2007 | D18: 9.59 | E18: =D18/100 -> 0.0959
A19: 40025 | B19: 0.090915909 | C19: 2008 | D19: -47.58 | E19: =D19/100 -> -0.4758
A20: 39994 | B20: -0.04196231 | C20: 2009 | D20: 35.24 | E20: =D20/100 -> 0.3524
A21: 39962 | B21: 0.037280251 | C21: 2010 | D21: 6.04 | E21: =D21/100 -> 0.0604
A22: 39933 | B22: 0.12546726
A23: 39903 | B23: 0.038601397
A24: 39871 | B24: -0.091373471
A25: 39843 | B25: -0.075839737
A26: 39813 | B26: -0.013703459
A27: 39780 | B27: -0.064649153
A28: 39752 | B28: -0.13597274
A29: 39721 | B29: -0.10199971
A30: 39689 | B30: 0.019244764
A31: 39660 | B31: -0.011080933
A32: 39629 | B32: -0.11725597
A33: 39598 | B33: 0.0017504569
... A247: 33085 | B247: -0.040932175

Sheet LR1
A1: SUMMARY OUTPUT
A3: 回归统计
A4: Multiple R | B4: 0.53941259
A5: R Square | B5: 0.29096594
A6: Adjusted R Square | B6: 0.27874122
A7: 标准误差 | B7: 0.051321093
A8: 观测值 | B8: 60
A10: 方差分析
B11: df | C11: SS | D11: MS | E11: F | F11: Significance F
A12: 回归分析 | B12: 1 | C12: 0.062689507 | D12: 0.062689507 | E12: 23.80143 | F12: 8.70172e-06
A13: 残差 | B13: 58 | C13: 0.15276357 | D13: 0.0026338546
A14: 总计 | B14: 59 | C14: 0.21545308
B16: Coefficients | C16: 标准误差 | D16: t Stat | E16: P-value | F16: Lower 95% | G16: Upper 95% | H16: 下限 95.0% | I16: 上限 95.0%
A17: Intercept | B17: -0.0018291615 | C17: 0.0066426816 | D17: -0.27536492 | E17: 0.78401454 | F17: -0.015125933 | G17: 0.01146761 | H17: -0.015125933 | I17: 0.01146761
A18: Market Premium | B18: 0.59595671 | C18: 0.12215555 | D18: 4.878671 | E18: 8.70172e-06 | F18: 0.35143582 | G18: 0.8404776 | H18: 0.35143582 | I18: 0.8404776
B19: 2006-2010

Sheet Raw material
A1: Date | B1: SNY Stock Price | C1: Dividend | D1: # Stocks | E1: Value | F1: Return | G1: Market Index | H1: Market Return | I1: Rf(%) | J1: Rf | K1: Market Premium | L1: SNY Premium
A2: 40543 | B2: 47.85 | D2: =(D3*C2)/B2+D3 -> 1.4976877 | E2: =B2*D2 -> 71.664355 | F2: =E2/E3-1 -> 0.027264921 | G2: 3804.78 | H2: =(G2/G3)-1 -> 0.053827234 | I2: 0.01 | J2: =I2/100 -> 0.0001 | K2: =H2-J2 -> 0.053727234 | L2: =F2-J2 -> 0.027164921
A3: 40512 | B3: 46.58 | D3: =(D4*C3)/B3+D4 -> 1.4976877 | E3: =B3*D3 -> 69.762291 | F3: =E3/E4-1 -> -0.07174173 | G3: 3610.44 | H3: =(G3/G4)-1 -> -0.058187035 | I3: 0.01 | J3: =I3/100 -> 0.0001 | K3: =H3-J3 -> -0.058287035 | L3: =F3-J3 -> -0.07184173
A4: 40480 | B4: 50.18 | D4: =(D5*C4)/B4+D5 -> 1.4976877 | E4: =B4*D4 -> 75.153967 | F4: =E4/E5-1 -> 0.026700767 | G4: 3833.5 | H4: =(G4/G5)-1 -> 0.031847717 | I4: 0.01 | J4: =I4/100 -> 0.0001 | K4: =H4-J4 -> 0.031747717 | L4: =F4-J4 -> 0.026600767
A5: 40451 | B5: 48.875 | D5: =(D6*C5)/B5+D6 -> 1.4976877 | E5: =B5*D5 -> 73.199484 | F5: =E5/E6-1 -> 0.079633311 | G5: 3715.18 | H5: =(G5/G6)-1 -> 0.064280578 | I5: 0.01 | J5: =I5/100 -> 0.0001 | K5: =H5-J5 -> 0.064180578 | L5: =F5-J5 -> 0.079533311
A6: 40421 | B6: 45.27 | D6: =(D7*C6)/B6+D7 -> 1.4976877 | E6: =B6*D6 -> 67.80032 | F6: =E6/E7-1 -> 0.015705632 | G6: 3490.79 | H6: =(G6/G7)-1 -> -0.041818322 | I6: 0.01 | J6: =I6/100 -> 0.0001 | K6: =H6-J6 -> -0.041918322 | L6: =F6-J6 -> 0.015605632
A7: 40389 | B7: 44.57 | D7: =(D8*C7)/B7+D8 -> 1.4976877 | E7: =B7*D7 -> 66.751939 | F7: =E7/E8-1 -> -0.10014133 | G7: 3643.14 | H7: =(G7/G8)-1 -> 0.058163345 | I7: 0.01 | J7: =I7/100 -> 0.0001 | K7: =H7-J7 -> 0.058063345 | L7: =F7-J7 -> -0.10024133
A8: 40359 | B8: 49.53 | D8: =(D9*C8)/B8+D9 -> 1.4976877 | E8: =B8*D8 -> 74.18047 | F8: =E8/E9-1 -> 0.0016177958 | G8: 3442.89 | H8: =(G8/G9)-1 -> -0.018437318 | I8: 0.01 | J8: =I8/100 -> 0.0001 | K8: =H8-J8 -> -0.018537318 | L8: =F8-J8 -> 0.0015177958
A9: 40329 | B9: 49.45 | C9: 2.4 | D9: =(D10*C9)/B9+D10 -> 1.4976877 | E9: =B9*D9 -> 74.060655 | F9: =E9/E10-1 -> 0.0036778939 | G9: 3507.56 | H9: =(G9/G10)-1 -> -0.081066495 | I9: 0.01 | J9: =I9/100 -> 0.0001 | K9: =H9-J9 -> -0.081166495 | L9: =F9-J9 -> 0.0035778939
A10: 40298 | B10: 51.66 | D10: =(D11*C10)/B10+D11 -> 1.4283636 | E10: =B10*D10 -> 73.789266 | F10: =E10/E11-1 -> -0.063960862 | G10: 3816.99 | H10: =(G10/G11)-1 -> -0.039511727 | I10: 0.01 | J10: =I10/100 -> 0.0001 | K10: =H10-J10 -> -0.039611727 | L10: =F10-J10 -> -0.064060862
A11: 40268 | B11: 55.19 | D11: =(D12*C11)/B11+D12 -> 1.4283636 | E11: =B11*D11 -> 78.831389 | F11: =E11/E12-1 -> 0.02736411 | G11: 3974.01 | H11: =(G11/G12)-1 -> 0.071508305 | I11: 0.01 | J11: =I11/100 -> 0.0001 | K11: =H11-J11 -> 0.071408305 | L11: =F11-J11 -> 0.02726411
A12: 40235 | B12: 53.72 | D12: =(D13*C12)/B12+D13 -> 1.4283636 | E12: =B12*D12 -> 76.731695 | F12: =E12/E13-1 -> 0.002238806 | G12: 3708.8 | H12: =(G12/G13)-1 -> -0.0081990448 | I12: 0 | J12: =I12/100 -> 0 | K12: =H12-J12 -> -0.0081990448 | L12: =F12-J12 -> 0.002238806
A13: 40207 | B13: 53.6 | D13: =(D14*C13)/B13+D14 -> 1.4283636 | E13: =B13*D13 -> 76.560291 | F13: =E13/E14-1 -> -0.026516527 | G13: 3739.46 | H13: =(G13/G14)-1 -> -0.050013591 | I13: 0 | J13: =I13/100 -> 0 | K13: =H13-J13 -> -0.050013591 | L13: =F13-J13 -> -0.026516527
A14: 40178 | B14: 55.06 | D14: =(D15*C14)/B14+D15 -> 1.4283636 | E14: =B14*D14 -> 78.645702 | F14: =E14/E15-1 -> 0.094197138 | G14: 3936.33 | H14: =(G14/G15)-1 -> 0.069611293 | I14: 0.01 | J14: =I14/100 -> 0.0001 | K14: =H14-J14 -> 0.069511293 | L14: =F14-J14 -> 0.094097138
A15: 40147 | B15: 50.32 | D15: =(D16*C15)/B15+D16 -> 1.4283636 | E15: =B15*D15 -> 71.875258 | F15: =E15/E16-1 -> 0.011558951 | G15: 3680.15 | H15: =(G15/G16)-1 -> 0.020084874 | I15: 0 | J15: =I15/100 -> 0 | K15: =H15-J15 -> 0.020084874 | L15: =F15-J15 -> 0.011558951
A16: 40116 | B16: 49.745 | D16: =(D17*C16)/B16+D17 -> 1.4283636 | E16: =B16*D16 -> 71.053949 | F16: =E16/E17-1 -> -0.0080757727 | G16: 3607.69 | H16: =(G16/G17)-1 -> -0.049459742 | I16: 0 | J16: =I16/100 -> 0 | K16: =H16-J16 -> -0.049459742 | L16: =F16-J16 -> -0.0080757727
A17: 40086 | B17: 50.15 | D17: =(D18*C17)/B17+D18 -> 1.4283636 | E17: =B17*D17 -> 71.632437 | F17: =E17/E18-1 -> 0.059805579 | G17: 3795.41 | H17: =(G17/G18)-1 -> 0.038830833 | I17: 0.01 | J17: =I17/100 -> 0.0001 | K17: =H17-J17 -> 0.038730833 | L17: =F17-J17 -> 0.059705579
A18: 40056 | B18: 47.32 | D18: =(D19*C18)/B18+D19 -> 1.4283636 | E18: =B18*D18 -> 67.590168 | F18: =E18/E19-1 -> 0.029590949 | G18: 3653.54 | H18: =(G18/G19)-1 -> 0.066331608 | I18: 0.01 | J18: =I18/100 -> 0.0001 | K18: =H18-J18 -> 0.066231608 | L18: =F18-J18 -> 0.029490949
A19: 40025 | B19: 45.96 | D19: =(D20*C19)/B19+D20 -> 1.4283636 | E19: =B19*D19 -> 65.647593 | F19: =E19/E20-1 -> 0.097683305 | G19: 3426.27 | H19: =(G19/G20)-1 -> 0.091015909 | I19: 0.01 | J19: =I19/100 -> 0.0001 | K19: =H19-J19 -> 0.090915909 | L19: =F19-J19 -> 0.097583305
A20: 39994 | B20: 41.87 | D20: =(D21*C20)/B20+D21 -> 1.4283636 | E20: =B20*D20 -> 59.805586 | F20: =E20/E21-1 -> -0.068520578 | G20: 3140.44 | H20: =(G20/G21)-1 -> -0.04186231 | I20: 0.01 | J20: =I20/100 -> 0.0001 | K20: =H20-J20 -> -0.04196231 | L20: =F20-J20 -> -0.068620578
A21: 39962 | B21: 44.95 | D21: =(D22*C21)/B21+D22 -> 1.4283636 | E21: =B21*D21 -> 64.204946 | F21: =E21/E22-1 -> 0.026959104 | G21: 3277.65 | H21: =(G21/G22)-1 -> 0.037280251 | I21: 0 | J21: =I21/100 -> 0 | K21: =H21-J21 -> 0.037280251 | L21: =F21-J21 -> 0.026959104
A22: 39933 | B22: 43.77 | C22: 2.2 | D22: =(D23*C22)/B22+D23 -> 1.4283636 | E22: =B22*D22 -> 62.519477 | F22: =E22/E23-1 -> 0.084709769 | G22: 3159.85 | H22: =(G22/G23)-1 -> 0.12556726 | I22: 0.01 | J22: =I22/100 -> 0.0001 | K22: =H22-J22 -> 0.12546726 | L22: =F22-J22 -> 0.084609769
A23: 39903 | B23: 42.38 | D23: =(D24*C23)/B23+D24 -> 1.360006 | E23: =B23*D23 -> 57.637055 | F23: =E23/E24-1 -> 0.035805939 | G23: 2807.34 | H23: =(G23/G24)-1 -> 0.038801397 | I23: 0.02 | J23: =I23/100 -> 0.0002 | K23: =H23-J23 -> 0.038601397 | L23: =F23-J23 -> 0.035605939
A24: 39871 | B24: 40.915 | D24: =(D25*C24)/B24+D25 -> 1.360006 | E24: =B24*D24 -> 55.644646 | F24: =E24/E25-1 -> -0.071906544 | G24: 2702.48 | H24: =(G24/G25)-1 -> -0.091273471 | I24: 0.01 | J24: =I24/100 -> 0.0001 | K24: =H24-J24 -> -0.091373471 | L24: =F24-J24 -> -0.072006544
A25: 39843 | B25: 44.085 | D25: =(D26*C25)/B25+D26 -> 1.360006 | E25: =B25*D25 -> 59.955865 | F25: =E25/E26-1 -> -0.028964758 | G25: 2973.92 | H25: =(G25/G26)-1 -> -0.075839737 | I25: 0 | J25: =I25/100 -> 0 | K25: =H25-J25 -> -0.075839737 | L25: =F25-J25 -> -0.028964758
A26: 39813 | B26: 45.4 | D26: =(D27*C26)/B26+D27 -> 1.360006 | E26: =B26*D26 -> 61.744273 | F26: =E26/E27-1 -> 0.044879171 | G26: 3217.97 | H26: =(G26/G27)-1 -> -0.013703459 | I26: 0 | J26: =I26/100 -> 0 | K26: =H26-J26 -> -0.013703459 | L26: =F26-J26 -> 0.044879171
A27: 39780 | B27: 43.45 | D27: =(D28*C27)/B27+D28 -> 1.360006 | E27: =B27*D27 -> 59.092261 | F27: =E27/E28-1 -> -0.12097916 | G27: 3262.68 | H27: =(G27/G28)-1 -> -0.064349153 | I27: 0.03 | J27: =I27/100 -> 0.0003 | K27: =H27-J27 -> -0.064649153 | L27: =F27-J27 -> -0.12127916
A28: 39752 | B28: 49.43 | D28: =(D29*C28)/B28+D29 -> 1.360006 | E28: =B28*D28 -> 67.225097 | F28: =E28/E29-1 -> 0.061868958 | G28: 3487.07 | H28: =(G28/G29)-1 -> -0.13517274 | I28: 0.08 | J28: =I28/100 -> 0.0008 | K28: =H28-J28 -> -0.13597274 | L28: =F28-J28 -> 0.061068958
A29: 39721 | B29: 46.55 | D29: =(D30*C29)/B29+D30 -> 1.360006 | E29: =B29*D29 -> 63.30828 | F29: =E29/E30-1 -> -0.042378111 | G29: 4032.1 | H29: =(G29/G30)-1 -> -0.10049971 | I29: 0.15 | J29: =I29/100 -> 0.0015 | K29: =H29-J29 -> -0.10199971 | L29: =F29-J29 -> -0.043878111
A30: 39689 | B30: 48.61 | D30: =(D31*C30)/B30+D31 -> 1.360006 | E30: =B30*D30 -> 66.109892 | F30: =E30/E31-1 -> 0.078544486 | G30: 4482.6 | H30: =(G30/G31)-1 -> 0.020544764 | I30: 0.13 | J30: =I30/100 -> 0.0013 | K30: =H30-J30 -> 0.019244764 | L30: =F30-J30 -> 0.077244486
A31: 39660 | B31: 45.07 | D31: =(D32*C31)/B31+D32 -> 1.360006 | E31: =B31*D31 -> 61.295471 | F31: =E31/E32-1 -> 0.062220127 | G31: 4392.36 | H31: =(G31/G32)-1 -> -0.0095809328 | I31: 0.15 | J31: =I31/100 -> 0.0015 | K31: =H31-J31 -> -0.011080933 | L31: =F31-J31 -> 0.060720127
A32: 39629 | B32: 42.43 | D32: =(D33*C32)/B32+D33 -> 1.360006 | E32: =B32*D32 -> 57.705055 | F32: =E32/E33-1 -> -0.11438113 | G32: 4434.85 | H32: =(G32/G33)-1 -> -0.11555597 | I32: 0.17 | J32: =I32/100 -> 0.0017 | K32: =H32-J32 -> -0.11725597 | L32: =F32-J32 -> -0.11608113
A33: 39598 | B33: 47.91 | C33: 2.07 | D33: =(D34*C33)/B33+D34 -> 1.360006 | E33: =B33*D33 -> 65.157888 | F33: =E33/E34-1 -> -0.0033898305 | G33: 5014.28 | H33: =(G33/G34)-1 -> 0.0035504569 | I33: 0.18 | J33: =I33/100 -> 0.0018 | K33: =H33-J33 -> 0.0017504569 | L33: =F33-J33 -> -0.0051898305
A34: 39568 | B34: 50.15 | D34: =(D35*C34)/B34+D35 -> 1.3036792 | E34: =B34*D34 -> 65.379514 | F34: =E34/E35-1 -> 0.055345118 | G34: 4996.54 | H34: =(G34/G35)-1 -> 0.061496855 | I34: 0.18 | J34: =I34/100 -> 0.0018 | K34: =H34-J34 -> 0.059696855 | L34: =F34-J34 -> 0.053545118
A35: 39538 | B35: 47.52 | D35: =(D36*C35)/B35+D36 -> 1.3036792 | E35: =B35*D35 -> 61.950837 | F35: =E35/E36-1 -> -0.026029924 | G35: 4707.07 | H35: =(G35/G36)-1 -> -0.017448535 | I35: 0.17 | J35: =I35/100 -> 0.0017 | K35: =H35-J35 -> -0.019148535 | L35: =F35-J35 -> -0.027729924
A36: 39507 | B36: 48.79 | D36: =(D37*C36)/B36+D37 -> 1.3036792 | E36: =B36*D36 -> 63.60651 | F36: =E36/E37-1 -> -0.10229991 | G36: 4790.66 | H36: =(G36/G37)-1 -> -0.016249161 | I36: 0.13 | J36: =I36/100 -> 0.0013 | K36: =H36-J36 -> -0.017549161 | L36: =F36-J36 -> -0.10359991
A37: 39478 | B37: 54.35 | D37: =(D38*C37)/B37+D38 -> 1.3036792 | E37: =B37*D37 -> 70.854967 | F37: =E37/E38-1 -> -0.13702763 | G37: 4869.79 | H37: =(G37/G38)-1 -> -0.1325756 | I37: 0.21 | J37: =I37/100 -> 0.0021 | K37: =H37-J37 -> -0.1346756 | L37: =F37-J37 -> -0.13912763
A38: 39447 | B38: 62.98 | D38: =(D39*C38)/B38+D39 -> 1.3036792 | E38: =B38*D38 -> 82.105718 | F38: =E38/E39-1 -> -0.031225965 | G38: 5614.08 | H38: =(G38/G39)-1 -> -0.0099619615 | I38: 0.27 | J38: =I38/100 -> 0.0027 | K38: =H38-J38 -> -0.012661961 | L38: =F38-J38 -> -0.033925965
A39: 39416 | B39: 65.01 | D39: =(D40*C39)/B39+D40 -> 1.3036792 | E39: =B39*D39 -> 84.752187 | F39: =E39/E40-1 -> 0.073835481 | G39: 5670.57 | H39: =(G39/G40)-1 -> -0.030331997 | I39: 0.34 | J39: =I39/100 -> 0.0034 | K39: =H39-J39 -> -0.033731997 | L39: =F39-J39 -> 0.070435481
A40: 39386 | B40: 60.54 | D40: =(D41*C40)/B40+D41 -> 1.3036792 | E40: =B40*D40 -> 78.924741 | F40: =E40/E41-1 -> 0.019535197 | G40: 5847.95 | H40: =(G40/G41)-1 -> 0.023139813 | I40: 0.32 | J40: =I40/100 -> 0.0032 | K40: =H40-J40 -> 0.019939813 | L40: =F40-J40 -> 0.016335197
...

Sheet use 10-year bond
A1: Date | B1: SNY Stock Price | C1: Dividend | D1: # Stocks | E1: Value | F1: Return | G1: Market Index | H1: Market Return | I1: Rf(%) | J1: Rf | K1: Market Premium | L1: SNY Premium
A2: 40543 | B2: 47.85 | D2: =(D3*C2)/B2+D3 -> 1.4976877 | E2: =B2*D2 -> 71.664355 | F2: =E2/E3-1 -> 0.027264921 | G2: 3804.78 | H2: =(G2/G3)-1 -> 0.053827234 | I2: 3.35 | J2: =I2/100 -> 0.0335 | K2: =H2-J2 -> 0.020327234 | L2: =F2-J2 -> -0.0062350794
A3: 40512 | B3: 46.58 | D3: =(D4*C3)/B3+D4 -> 1.4976877 | E3: =B3*D3 -> 69.762291 | F3: =E3/E4-1 -> -0.07174173 | G3: 3610.44 | H3: =(G3/G4)-1 -> -0.058187035 | I3: 3.164 | J3: =I3/100 -> 0.03164 | K3: =H3-J3 -> -0.089827035 | L3: =F3-J3 -> -0.10338173
A4: 40480 | B4: 50.18 | D4: =(D5*C4)/B4+D5 -> 1.4976877 | E4: =B4*D4 -> 75.153967 | F4: =E4/E5-1 -> 0.026700767 | G4: 3833.5 | H4: =(G4/G5)-1 -> 0.031847717 | I4: 2.91 | J4: =I4/100 -> 0.0291 | K4: =H4-J4 -> 0.0027477167 | L4: =F4-J4 -> -0.0023992327
A5: 40451 | B5: 48.875 | D5: =(D6*C5)/B5+D6 -> 1.4976877 | E5: =B5*D5 -> 73.199484 | F5: =E5/E6-1 -> 0.079633311 | G5: 3715.18 | H5: =(G5/G6)-1 -> 0.064280578 | I5: 2.673 | J5: =I5/100 -> 0.02673 | K5: =H5-J5 -> 0.037550578 | L5: =F5-J5 -> 0.052903311
A6: 40421 | B6: 45.27 | D6: =(D7*C6)/B6+D7 -> 1.4976877 | E6: =B6*D6 -> 67.80032 | F6: =E6/E7-1 -> 0.015705632 | G6: 3490.79 | H6: =(G6/G7)-1 -> -0.041818322 | I6: 2.475 | J6: =I6/100 -> 0.02475 | K6: =H6-J6 -> -0.066568322 | L6: =F6-J6 -> -0.0090443684
A7: 40389 | B7: 44.57 | D7: =(D8*C7)/B7+D8 -> 1.4976877 | E7: =B7*D7 -> 66.751939 | F7: =E7/E8-1 -> -0.10014133 | G7: 3643.14 | H7: =(G7/G8)-1 -> 0.058163345 | I7: 2.956 | J7: =I7/100 -> 0.02956 | K7: =H7-J7 -> 0.028603345 | L7: =F7-J7 -> -0.12970133
A8: 40359 | B8: 49.53 | D8: =(D9*C8)/B8+D9 -> 1.4976877 | E8: =B8*D8 -> 74.18047 | F8: =E8/E9-1 -> 0.0016177958 | G8: 3442.89 | H8: =(G8/G9)-1 -> -0.018437318 | I8: 3.055 | J8: =I8/100 -> 0.03055 | K8: =H8-J8 -> -0.048987318 | L8: =F8-J8 -> -0.028932204
A9: 40329 | B9: 49.45 | C9: 2.4 | D9: =(D10*C9)/B9+D10 -> 1.4976877 | E9: =B9*D9 -> 74.060655 | F9: =E9/E10-1 -> 0.0036778939 | G9: 3507.56 | H9: =(G9/G10)-1 -> -0.081066495 | I9: 2.916 | J9: =I9/100 -> 0.02916 | K9: =H9-J9 -> -0.11022649 | L9: =F9-J9 -> -0.025482106
A10: 40298 | B10: 51.66 | D10: =(D11*C10)/B10+D11 -> 1.4283636 | E10: =B10*D10 -> 73.789266 | F10: =E10/E11-1 -> -0.063960862 | G10: 3816.99 | H10: =(G10/G11)-1 -> -0.039511727 | I10: 3.3 | J10: =I10/100 -> 0.033 | K10: =H10-J10 -> -0.072511727 | L10: =F10-J10 -> -0.096960862
A11: 40268 | B11: 55.19 | D11: =(D12*C11)/B11+D12 -> 1.4283636 | E11: =B11*D11 -> 78.831389 | F11: =E11/E12-1 -> 0.02736411 | G11: 3974.01 | H11: =(G11/G12)-1 -> 0.071508305 | I11: 3.439 | J11: =I11/100 -> 0.03439 | K11: =H11-J11 -> 0.037118305 | L11: =F11-J11 -> -0.0070258898
A12: 40235 | B12: 53.72 | D12: =(D13*C12)/B12+D13 -> 1.4283636 | E12: =B12*D12 -> 76.731695 | F12: =E12/E13-1 -> 0.002238806 | G12: 3708.8 | H12: =(G12/G13)-1 -> -0.0081990448 | I12: 3.423 | J12: =I12/100 -> 0.03423 | K12: =H12-J12 -> -0.042429045 | L12: =F12-J12 -> -0.031991194
A13: 40207 | B13: 53.6 | D13: =(D14*C13)/B13+D14 -> 1.4283636 | E13: =B13*D13 -> 76.560291 | F13: =E13/E14-1 -> -0.026516527 | G13: 3739.46 | H13: =(G13/G14)-1 -> -0.050013591 | I13: 3.468 | J13: =I13/100 -> 0.03468 | K13: =H13-J13 -> -0.084693591 | L13: =F13-J13 -> -0.061196527
A14: 40178 | B14: 55.06 | D14: =(D15*C14)/B14+D15 -> 1.4283636 | E14: =B14*D14 -> 78.645702 | F14: =E14/E15-1 -> 0.094197138 | G14: 3936.33 | H14: =(G14/G15)-1 -> 0.069611293 | I14: 3.613 | J14: =I14/100 -> 0.03613 | K14: =H14-J14 -> 0.033481293 | L14: =F14-J14 -> 0.058067138
A15: 40147 | B15: 50.32 | D15: =(D16*C15)/B15+D16 -> 1.4283636 | E15: =B15*D15 -> 71.875258 | F15: =E15/E16-1 -> 0.011558951 | G15: 3680.15 | H15: =(G15/G16)-1 -> 0.020084874 | I15: 3.421 | J15: =I15/100 -> 0.03421 | K15: =H15-J15 -> -0.014125126 | L15: =F15-J15 -> -0.022651049
A16: 40116 | B16: 49.745 | D16: =(D17*C16)/B16+D17 -> 1.4283636 | E16: =B16*D16 -> 71.053949 | F16: =E16/E17-1 -> -0.0080757727 | G16: 3607.69 | H16: =(G16/G17)-1 -> -0.049459742 | I16: 3.523 | J16: =I16/100 -> 0.03523 | K16: =H16-J16 -> -0.084689742 | L16: =F16-J16 -> -0.043305773
A17: 40086 | B17: 50.15 | D17: =(D18*C17)/B17+D18 -> 1.4283636 | E17: =B17*D17 -> 71.632437 | F17: =E17/E18-1 -> 0.059805579 | G17: 3795.41 | H17: =(G17/G18)-1 -> 0.038830833 | I17: 3.542 | J17: =I17/100 -> 0.03542 | K17: =H17-J17 -> 0.0034108326 | L17: =F17-J17 -> 0.024385579
A18: 40056 | B18: 47.32 | D18: =(D19*C18)/B18+D19 -> 1.4283636 | E18: =B18*D18 -> 67.590168 | F18: =E18/E19-1 -> 0.029590949 | G18: 3653.54 | H18: =(G18/G19)-1 -> 0.066331608 | I18: 3.534 | J18: =I18/100 -> 0.03534 | K18: =H18-J18 -> 0.030991608 | L18: =F18-J18 -> -0.0057490513
A19: 40025 | B19: 45.96 | D19: =(D20*C19)/B19+D20 -> 1.4283636 | E19: =B19*D19 -> 65.647593 | F19: =E19/E20-1 -> 0.097683305 | G19: 3426.27 | H19: =(G19/G20)-1 -> 0.091015909 | I19: 3.57 | J19: =I19/100 -> 0.0357 | K19: =H19-J19 -> 0.055315909 | L19: =F19-J19 -> 0.061983305
A20: 39994 | B20: 41.87 | D20: =(D21*C20)/B20+D21 -> 1.4283636 | E20: =B20*D20 -> 59.805586 | F20: =E20/E21-1 -> -0.068520578 | G20: 3140.44 | H20: =(G20/G21)-1 -> -0.04186231 | I20: 3.732 | J20: =I20/100 -> 0.03732 | K20: =H20-J20 -> -0.07918231 | L20: =F20-J20 -> -0.10584058
A21: 39962 | B21: 44.95 | D21: =(D22*C21)/B21+D22 -> 1.4283636 | E21: =B21*D21 -> 64.204946 | F21: =E21/E22-1 -> 0.026959104 | G21: 3277.65 | H21: =(G21/G22)-1 -> 0.037280251 | I21: 3.955 | J21: =I21/100 -> 0.03955 | K21: =H21-J21 -> -0.0022697494 | L21: =F21-J21 -> -0.012590896
A22: 39933 | B22: 43.77 | C22: 2.2 | D22: =(D23*C22)/B22+D23 -> 1.4283636 | E22: =B22*D22 -> 62.519477 | F22: =E22/E23-1 -> 0.084709769 | G22: 3159.85 | H22: =(G22/G23)-1 -> 0.12556726 | I22: 3.583 | J22: =I22/100 -> 0.03583 | K22: =H22-J22 -> 0.089737263 | L22: =F22-J22 -> 0.048879769
A23: 39903 | B23: 42.38 | D23: =(D24*C23)/B23+D24 -> 1.360006 | E23: =B23*D23 -> 57.637055 | F23: =E23/E24-1 -> 0.035805939 | G23: 2807.34 | H23: =(G23/G24)-1 -> 0.038801397 | I23: 3.633 | J23: =I23/100 -> 0.03633 | K23: =H23-J23 -> 0.0024713972 | L23: =F23-J23 -> -0.00052406086
A24: 39871 | B24: 40.915 | D24: =(D25*C24)/B24+D25 -> 1.360006 | E24: =B24*D24 -> 55.644646 | F24: =E24/E25-1 -> -0.071906544 | G24: 2702.48 | H24: =(G24/G25)-1 -> -0.091273471 | I24: 3.657 | J24: =I24/100 -> 0.03657 | K24: =H24-J24 -> -0.12784347 | L24: =F24-J24 -> -0.10847654
A25: 39843 | B25: 44.085 | D25: =(D26*C25)/B25+D26 -> 1.360006 | E25: =B25*D25 -> 59.955865 | F25: =E25/E26-1 -> -0.028964758 | G25: 2973.92 | H25: =(G25/G26)-1 -> -0.075839737 | I25: 3.819 | J25: =I25/100 -> 0.03819 | K25: =H25-J25 -> -0.11402974 | L25: =F25-J25 -> -0.067154758
A26: 39813 | B26: 45.4 | D26: =(D27*C26)/B26+D27 -> 1.360006 | E26: =B26*D26 -> 61.744273 | F26: =E26/E27-1 -> 0.044879171 | G26: 3217.97 | H26: =(G26/G27)-1 -> -0.013703459 | I26: 3.414 | J26: =I26/100 -> 0.03414 | K26: =H26-J26 -> -0.047843459 | L26: =F26-J26 -> 0.010739171
A27: 39780 | B27: 43.45 | D27: =(D28*C27)/B27+D28 -> 1.360006 | E27: =B27*D27 -> 59.092261 | F27: =E27/E28-1 -> -0.12097916 | G27: 3262.68 | H27: =(G27/G28)-1 -> -0.064349153 | I27: 3.685 | J27: =I27/100 -> 0.03685 | K27: =H27-J27 -> -0.10119915 | L27: =F27-J27 -> -0.15782916
A28: 39752 | B28: 49.43 | D28: =(D29*C28)/B28+D29 -> 1.360006 | E28: =B28*D28 -> 67.225097 | F28: =E28/E29-1 -> 0.061868958 | G28: 3487.07 | H28: =(G28/G29)-1 -> -0.13517274 | I28: 4.304 | J28: =I28/100 -> 0.04304 | K28: =H28-J28 -> -0.17821274 | L28: =F28-J28 -> 0.018828958
A29: 39721 | B29: 46.55 | D29: =(D30*C29)/B29+D30 -> 1.360006 | E29: =B29*D29 -> 63.30828 | F29: =E29/E30-1 -> -0.042378111 | G29: 4032.1 | H29: =(G29/G30)-1 -> -0.10049971 | I29: 4.339 | J29: =I29/100 -> 0.04339 | K29: =H29-J29 -> -0.14388971 | L29: =F29-J29 -> -0.085768111
A30: 39689 | B30: 48.61 | D30: =(D31*C30)/B30+D31 -> 1.360006 | E30: =B30*D30 -> 66.109892 | F30: =E30/E31-1 -> 0.078544486 | G30: 4482.6 | H30: =(G30/G31)-1 -> 0.020544764 | I30: 4.375 | J30: =I30/100 -> 0.04375 | K30: =H30-J30 -> -0.023205236 | L30: =F30-J30 -> 0.034794486
A31: 39660 | B31: 45.07 | D31: =(D32*C31)/B31+D32 -> 1.360006 | E31: =B31*D31 -> 61.295471 | F31: =E31/E32-1 -> 0.062220127 | G31: 4392.36 | H31: =(G31/G32)-1 -> -0.0095809328 | I31: 4.532 | J31: =I31/100 -> 0.04532 | K31: =H31-J31 -> -0.054900933 | L31: =F31-J31 -> 0.016900127
A32: 39629 | B32: 42.43 | D32: =(D33*C32)/B32+D33 -> 1.360006 | E32: =B32*D32 -> 57.705055 | F32: =E32/E33-1 -> -0.11438113 | G32: 4434.85 | H32: =(G32/G33)-1 -> -0.11555597 | I32: 4.825 | J32: =I32/100 -> 0.04825 | K32: =H32-J32 -> -0.16380597 | L32: =F32-J32 -> -0.16263113
A33: 39598 | B33: 47.91 | C33: 2.07 | D33: =(D34*C33)/B33+D34 -> 1.360006 | E33: =B33*D33 -> 65.157888 | F33: =E33/E34-1 -> -0.0033898305 | G33: 5014.28 | H33: =(G33/G34)-1 -> 0.0035504569 | I33: 4.606 | J33: =I33/100 -> 0.04606 | K33: =H33-J33 -> -0.042509543 | L33: =F33-J33 -> -0.049449831
A34: 39568 | B34: 50.15 | D34: =(D35*C34)/B34+D35 -> 1.3036792 | E34: =B34*D34 -> 65.379514 | F34: =E34/E35-1 -> 0.055345118 | G34: 4996.54 | H34: =(G34/G35)-1 -> 0.061496855 | I34: 4.326 | J34: =I34/100 -> 0.04326 | K34: =H34-J34 -> 0.018236855 | L34: =F34-J34 -> 0.012085118
A35: 39538 | B35: 47.52 | D35: =(D36*C35)/B35+D36 -> 1.3036792 | E35: =B35*D35 -> 61.950837 | F35: =E35/E36-1 -> -0.026029924 | G35: 4707.07 | H35: =(G35/G36)-1 -> -0.017448535 | I35: 4.114 | J35: =I35/100 -> 0.04114 | K35: =H35-J35 -> -0.058588535 | L35: =F35-J35 -> -0.067169924
A36: 39507 | B36: 48.79 | D36: =(D37*C36)/B36+D37 -> 1.3036792 | E36: =B36*D36 -> 63.60651 | F36: =E36/E37-1 -> -0.10229991 | G36: 4790.66 | H36: =(G36/G37)-1 -> -0.016249161 | I36: 4.111 | J36: =I36/100 -> 0.04111 | K36: =H36-J36 -> -0.057359161 | L36: =F36-J36 -> -0.14340991
A37: 39478 | B37: 54.35 | D37: =(D38*C37)/B37+D38 -> 1.3036792 | E37: =B37*D37 -> 70.854967 | F37: =E37/E38-1 -> -0.13702763 | G37: 4869.79 | H37: =(G37/G38)-1 -> -0.1325756 | I37: 4.139 | J37: =I37/100 -> 0.04139 | K37: =H37-J37 -> -0.1739656 | L37: =F37-J37 -> -0.17841763
A38: 39447 | B38: 62.98 | D38: =(D39*C38)/B38+D39 -> 1.3036792 | E38: =B38*D38 -> 82.105718 | F38: =E38/E39-1 -> -0.031225965 | G38: 5614.08 | H38: =(G38/G39)-1 -> -0.0099619615 | I38: 4.423 | J38: =I38/100 -> 0.04423 | K38: =H38-J38 -> -0.054191961 | L38: =F38-J38 -> -0.075455965
A39: 39416 | B39: 65.01 | D39: =(D40*C39)/B39+D40 -> 1.3036792 | E39: =B39*D39 -> 84.752187 | F39: =E39/E40-1 -> 0.073835481 | G39: 5670.57 | H39: =(G39/G40)-1 -> -0.030331997 | I39: 4.192 | J39: =I39/100 -> 0.04192 | K39: =H39-J39 -> -0.072251997 | L39: =F39-J39 -> 0.031915481
A40: 39386 | B40: 60.54 | D40: =(D41*C40)/B40+D41 -> 1.3036792 | E40: =B40*D40 -> 78.924741 | F40: =E40/E41-1 -> 0.019535197 | G40: 5847.95 | H40: =(G40/G41)-1 -> 0.023139813 | I40: 4.297 | J40: =I40/100 -> 0.04297 | K40: =H40-J40 -> -0.019830187 | L40: =F40-J40 -> -0.023434803
...

Sheet France 10-Year Bond Yield
A1: Date | B1: Price | C1: Open | D1: High | E1: Low | F1: Change%
A2: 42842 | B2: 0.899 | C2: 0.964 | D2: 0.987 | E2: 0.865 | F2: -0.0684
A3: 42811 | B3: 0.965 | C3: 0.915 | D3: 1.148 | E3: 0.892 | F3: 0.0941
A4: 42783 | B4: 0.882 | C4: 1.064 | D4: 1.154 | E4: 0.866 | F4: -0.142
A5: 42752 | B5: 1.028 | C5: 0.695 | D5: 1.115 | E5: 0.631 | F5: 0.5051
A6: 43085 | B6: 0.683 | C6: 0.785 | D6: 0.922 | E6: 0.632 | F6: -0.072
A7: 43055 | B7: 0.736 | C7: 0.484 | D7: 0.885 | E7: 0.423 | F7: 0.5365
A8: 43024 | B8: 0.479 | C8: 0.132 | D8: 0.505 | E8: 0.119 | F8: 3.0252
A9: 42994 | B9: 0.119 | C9: 0.189 | D9: 0.317 | E9: 0.084 | F9: -0.2654
A10: 42963 | B10: 0.162 | C10: 0.104 | D10: 0.218 | E10: 0.095 | F10: 0.4464
A11: 42932 | B11: 0.112 | C11: 0.195 | D11: 0.269 | E11: 0.094 | F11: -0.4428
A12: 42902 | B12: 0.201 | C12: 0.49 | D12: 0.511 | E12: 0.198 | F12: -0.5864
A13: 42871 | B13: 0.486 | C13: 0.641 | D13: 0.643 | E13: 0.453 | F13: -0.2535
... A212: 36434 | B212: 5.291 | C212: 5.291 | D212: 5.291 | E212: 5.291 | F212: 0.0063
A213: 36404 | B213: 5.258 | C213: 5.258 | D213: 5.258 | E213: 5.258 | F213: 0.0445 | G213: 5.258
A214: 36373 | B214: 5.034 | C214: 5.034 | D214: 5.034 | E214: 5.034 | F214: 0.0178 | G214: 5.034
A215: 36342 | B215: 4.946 | C215: 4.946 | D215: 4.946 | E215: 4.946 | F215: 0.0577 | G215: 4.946
A216: 36312 | B216: 4.676 | C216: 4.676 | D216: 4.676 | E216: 4.676 | F216: 0.1047 | G216: 4.676
A217: 36281 | B217: 4.233 | C217: 4.233 | D217: 4.233 | E217: 4.233 | F217: 0.0851 | G217: 4.233
A218: 36251 | B218: 3.901 | C218: 3.901 | D218: 3.901 | E218: 3.901 | F218: -0.049
A219: 36220 | B219: 4.102 | C219: 4.102 | D219: 4.102 | E219: 4.102 | F219: 0.0064
A220: 36192 | B220: 4.076 | C220: 4.076 | D220: 4.076 | E220: 4.076 | F220: 0.0981
A221: 36161 | B221: 3.712 | C221: 3.712 | D221: 3.712 | E221: 3.712 | F221: -0.0453
A222: 36130 | B222: 3.888 | C222: 3.888 | D222: 3.888 | E222: 3.888 | F222: -0.0398
A223: 36100 | B223: 4.049 | C223: 4.049 | D223: 4.049 | E223: 4.049 | F223: -0.0511
A224: 36069 | B224: 4.267 | C224: 4.267 | D224: 4.267 | E224: 4.267 | F224: 0.0652
A225: 36039 | B225: 4.006 | C225: 4.006 | D225: 4.006 | E225: 4.006 | F225: -0.0733
A226: 36008 | B226: 4.323 | C226: 4.323 | D226: 4.323 | E226: 4.323 | F226: -0.0895
A227: 35977 | B227: 4.748 | C227: 4.748 | D227: 4.748 | E227: 4.748 | F227: -0.0192
A228: 35947 | B228: 4.841 | C228: 4.841 | D228: 4.841 | E228: 4.841 | F228: -0.0159
A229: 35916 | B229: 4.919 | C229: 4.919 | D229: 4.919 | E229: 4.919 | F229: -0.0393
... A279: 34394 | B279: 6.466 | C279: 6.466 | D279: 6.466 | E279: 6.466 | F279: 0.0458
A280: Highest: 8.281 | B280: Lowest: 0.084 | C280: Difference: 8.197 | D280: Average: 3.969 | E280: Change %: -85.460
A281: Add a Comment
A282: Comment Guidelines
A284: Post
A287: Latest France 10-Year Comments
A289: Miguel Vieira May 03, 2016 7:13PM GMT
A290: I can't see why general information is telling me here that french 10y bond yield has climbed 1,38% while graphics show a falling yield for the same day, and same maturity of french bonds... Is there any error on the information given? Or am I interpreting wrongly?
A291: Reply
...

Sheet LR2
A1: SUMMARY OUTPUT
A3: 回归统计
A4: Multiple R | B4: 0.55269065
A5: R Square | B5: 0.30546696
A6: Adjusted R Square | B6: 0.29349225
A7: 标准误差 | B7: 0.051259811
A8: 观测值 | B8: 60
A10: 方差分析
B11: df | C11: SS | D11: MS | E11: F | F11: Significance F
A12: 回归分析 | B12: 1 | C12: 0.067027546 | D12: 0.067027546 | E12: 25.509346 | F12: 4.6751591e-06
A13: 残差 | B13: 58 | C13: 0.15239896 | D13: 0.0026275682
A14: 总计 | B14: 59 | C14: 0.2194265
B16: Coefficients | C16: 标准误差 | D16: t Stat | E16: P-value | F16: Lower 95% | G16: Upper 95% | H16: 下限 95.0% | I16: 上限 95.0%
A17: Intercept | B17: -0.016237988 | C17: 0.0081735788 | D17: -1.9866436 | E17: 0.051693094 | F17: -0.032599183 | G17: 0.00012320795 | H17: -0.032599183 | I17: 0.00012320795
A18: Market Premium | B18: 0.60248109 | C18: 0.11928718 | D18: 5.0506777 | E18: 4.6751591e-06 | F18: 0.36370186 | G18: 0.84126032 | H18: 0.36370186 | I18: 0.84126032

Sheet cost of equity(use French bond)
A1: Date | B1: Rm-Rf | H1: Date | I1: RF | L1: Alpha
A2: 40543 | B2: 0.020327234 | C2: Average Market Risk Premium (MRP) | H2: 40543 | I2: 0.0335 | K2: Monthly: | L2: 0 | M2: Insignificant statistically
A3: 40512 | B3: -0.089827035 | C3: in the last 10 years: | K3: Yearly: | L3: =(1+L2)^12-1 -> 0
A4: 40480 | B4: 0.0027477167 | H4: Yearly risk-free return: | I4: =(1+I2)^12-1 -> 0.48499767
A5: 40451 | B5: 0.037550578 | C5: Monthly average: | D5: =AVERAGE(B2:B203) -> -0.043751491 | L5: Beta:
A6: 40421 | B6: -0.066568322 | C6: Yearly average MRP: | D6: =(1+D5)^12-1 -> -0.41541287 | L6: 0.6 | M6: Significant statistically
A7: 40389 | B7: 0.028603345
A8: 40359 | B8: -0.048987318
A9: 40329 | B9: -0.11022649
A10: 40298 | B10: -0.072511727
A11: 40268 | B11: 0.037118305
A12: 40235 | B12: -0.042429045
A13: 40207 | B13: -0.084693591
A14: 40178 | B14: 0.033481293
A15: 40147 | B15: -0.014125126
A16: 40116 | B16: -0.084689742
A17: 40086 | B17: 0.0034108326
A18: 40056 | B18: 0.030991608
... A20: 39994 | B20: -0.07918231
A21: 39962 | B21: -0.0022697494 | C21: 21 | E21: Using instead used beta from the Oct 2002 to Sep 2007 period we would get:
A22: 39933 | B22: 0.089737263
A23: 39903 | B23: 0.0024713972
A24: 39871 | B24: -0.12784347
A25: 39843 | B25: -0.11402974
A26: 39813 | B26: -0.047843459
A27: 39780 | B27: -0.10119915
A28: 39752 | B28: -0.17821274
A29: 39721 | B29: -0.14388971
A30: 39689 | B30: -0.023205236
A31: 39660 | B31: -0.054900933
A32: 39629 | B32: -0.16380597
A33: 39598 | B33: -0.042509543
... A203: 34424 | B203: -0.13441684

Sheet WACC >>>>

Sheet Cost of Equity
B1: equity beta (monthly) | C1: Index | D1: Marginal tax rate(2010) | E1: E/V | F1: unlevered Beta | G1: D/V | H1: D/E | I1: Return on Asset | J1: Asset Beta
A2: pfizer | B2: 0.708 | C2: SPX | D2: 0.4 | E2: 0.824 | F2: =B2*E2 -> 0.583392 | G2: =1-E2 -> 0.176 | H2: =G2/E2 -> 0.21359223 | I2: =$B$30+F2*$B$29 -> 0.036437537 | J2: =B2/(1+H2*(1-D2)) -> 0.62757315
A3: roche | B3: 0.681 | C3: SMI | D3: 0.1875 | E3: 0.798 | F3: =B3*E3 -> 0.543438 | G3: =1-E3 -> 0.202 | H3: =G3/E3 -> 0.25313283 | I3: =$B$30+F3*$B$29 -> 0.034024315 | J3: =B3/(1+H3*(1-D3)) -> 0.56483097
A4: Bayer | B4: 0.706 | C4: DAX | D4: 0.2941 | E4: 0.802 | F4: =B4*E4 -> 0.566212 | G4: =1-E4 -> 0.198 | H4: =G4/E4 -> 0.24688279 | I4: =$B$30+F4*$B$29 -> 0.035399865 | J4: =B4/(1+H4*(1-D4)) -> 0.60122225
A5: Merck | B5: 0.715 | C5: SPX | D5: 0.4 | E5: 0.861 | F5: =B5*E5 -> 0.615615 | G5: =1-E5 -> 0.139 | H5: =G5/E5 -> 0.16144019 | I5: =$B$30+F5*$B$29 -> 0.038383806 | J5: =B5/(1+H5*(1-D5)) -> 0.65185832
A6: gilead | B6: 0.401 | C6: SPX | D6: 0.4 | E6: 0.911 | F6: =B6*E6 -> 0.365311 | G6: =1-E6 -> 0.089 | H6: =G6/E6 -> 0.097694841 | I6: =$B$30+F6*$B$29 -> 0.023265445 | J6: =B6/(1+H6*(1-D6)) -> 0.37879614
A7: GSK | B7: 0.464 | C7: UKX | D7: 0.28 | E7: 0.81 | F7: =B7*E7 -> 0.37584 | G7: =1-E7 -> 0.19 | H7: =G7/E7 -> 0.2345679 | I7: =$B$30+F7*$B$29 -> 0.023901396 | J7: =B7/(1+H7*(1-D7)) -> 0.39695817
A8: ELI LILLY & CO | B8: 0.786 | C8: SPX | D8: 0.4 | E8: 0.854 | F8: =B8*E8 -> 0.671244 | G8: =1-E8 -> 0.146 | H8: =G8/E8 -> 0.17096019 | I8: =$B$30+F8*$B$29 -> 0.041743798 | J8: =B8/(1+H8*(1-D8)) -> 0.71287596
A9: astrazeneca | B9: 0.378 | C9: UKX | D9: 0.28 | E9: 0.874 | F9: =B9*E9 -> 0.330372 | G9: =1-E9 -> 0.126 | H9: =G9/E9 -> 0.14416476 | I9: =$B$30+F9*$B$29 -> 0.021155129 | J9: =B9/(1+H9*(1-D9)) -> 0.34245377
A10: amgen | B10: 0.468 | C10: SPX | D10: 0.4 | E10: 0.793 | F10: =B10*E10 -> 0.371124 | G10: =1-E10 -> 0.207 | H10: =G10/E10 -> 0.26103405 | I10: =$B$30+F10*$B$29 -> 0.02361655 | J10: =B10/(1+H10*(1-D10)) -> 0.40462713
A11: allergan | B11: 0.47 | C11: SPX | D11: 0.4 | E11: 0.865 | F11: =B11*E11 -> 0.40655 | G11: =1-E11 -> 0.135 | H11: =G11/E11 -> 0.15606936 | I11: =$B$30+F11*$B$29 -> 0.02575628 | J11: =B11/(1+H11*(1-D11)) -> 0.42975687
A12: Teva | B12: 0.205 | C12: SPX | D12: 0.4 | E12: 0.897 | F12: =B12*E12 -> 0.183885 | G12: =1-E12 -> 0.103 | H12: =G12/E12 -> 0.1148272 | I12: =$B$30+F12*$B$29 -> 0.012307314 | J12: =B12/(1+H12*(1-D12)) -> 0.19178661
A13: NOVO NORDISK | B13: 0.33 | C13: KFX | D13: 0.25 | E13: 0.997 | F13: =B13*E13 -> 0.32901 | G13: =1-E13 -> 0.003 | H13: =G13/E13 -> 0.0030090271 | I13: =$B$30+F13*$B$29 -> 0.021072864 | J13: =B13/(1+H13*(1-D13)) -> 0.32925694
... A24: CHUGAI | B24: 0.782 | C24: TPX | D24: 0.4069 | E24: 1 | F24: =B24*E24 -> 0.782 | G24: =1-E24 -> 0 | H24: =G24/E24 -> 0 | I24: =$B$30+F24*$B$29 -> 0.04843346 | J24: =B24/(1+H24*(1-D24)) -> 0.782
A25: Average | E25: =AVERAGE(E2:E24) -> 0.847 | F25: =AVERAGE(F2:F24) -> 0.508153 | G25: =AVERAGE(G2:G24) -> 0.153 | H25: =AVERAGE(H2:H24) -> 0.33826071 | I25: =AVERAGE(I2:I24) -> 0.031893101 | J25: =AVERAGE(J2:J24) -> 0.53261406
A28: Tax Rate | B28: 0.3333 | C28: marginal tax rate for France-2010
A29: market premium | B29: ='cost of equity(use Fama French)'!G8 -> 0.0604 | C29: Fama French Average Annual Mkt-RF from 1990-2010 (European) | H29: Pablo Fernandez market risk premium. Ivo Valic | K29: use bloomberg
A30: risk free return | B30: ='cost of equity(use Fama French)'!L4 -> 0.0012006602 | C30: Fama French Annual RF for 2010 (European)
A33: return on asset | B33: =B30+F25*B29 -> 0.031893101
A34: Asset Beta | B34: =J25 -> 0.53261406 | E34: Sanofi | F34: E/V= | G34: =G35/G37 -> 0.82129141 | H34: D/V= | I34: =G36/G37 -> 0.17870859
A35: Equity Beta | B35: =B34/G34 -> 0.64850802 | E35: (millions of EUR) | F35: E= | G35: =I35*I36 -> 62444.25 | H35: Outstanding shares | I35: 1305
F36: D= | G36: ='Cost of Debt'!F47+'Operating lease converter'!C30 -> 13587.533 | H36: Price | I36: 47.85
A37: Cost of Equity | B37: =$B$30+B29*$B$35 -> 0.040370545 | F37: V= | G37: =G35+G36 -> 76031.783
A38: Cost of Debt | B38: 0.0428
A43: WACC | B43: =B37*G34+B38*I34*(1-B28) -> 0.038255388

Sheet Cost of Debt
A1: Source: Annual Repot on Form 20-F 2010
A2: The weighted average interest rate on debt at December 31, 2010 was 3.6%
A4: ISIN | B4: Description | D4: Millions of euro | F4: Discount Rate | H4: Weight | J4: Weighted Discount Rate
A5: - | B5: June 2008 issue of ¥15 billion (€138 million), maturing June 2013, bearing interest at a floating rate indexed to 3-month JPY Libor, and swapped into euros at a floating rate indexed to 3-month Euribor | C5: € | D5: 138 | F5: =B18 -> 0.01001 | H5: =IF($A$22="NO",D5/(SUM($D$5:$D$12)),D5/(SUM($D$5:$D$12,$D$22,$D$23))) -> 0.013640407 | J5: =H5*F5 -> 0.00013654048
A6: XS0428037666 | B6: May 2009 issue [ISIN: XS0428037666] of €1.5 billion, maturing May 2013, bearing annual interest at 3.5% | D6: 1500 | F6: 0.035 | H6: =IF($A$22="NO",D6/(SUM($D$5:$D$12)),D6/(SUM($D$5:$D$12,$D$22,$D$23))) -> 0.1482653 | J6: =H6*F6 -> 0.0051892854
A7: XS0428037740 | B7: May 2009 issue [ISIN: XS0428037740] of €1.5 billion, maturing May 2016, bearing annual interest at 4.5% | D7: 1500 | F7: 0.045 | H7: =IF($A$22="NO",D7/(SUM($D$5:$D$12)),D7/(SUM($D$5:$D$12,$D$22,$D$23))) -> 0.1482653 | J7: =H7*F7 -> 0.0066719383
A8: XS0456451938 | B8: October 2009 issue [ISIN: XS0456451938] of €1.2 billion (including supplementary tranche issued in April 2010), maturing October 2014, bearing annual interest at 3.125% | D8: 1200 | F8: 0.03125 | H8: =IF($A$22="NO",D8/(SUM($D$5:$D$12)),D8/(SUM($D$5:$D$12,$D$22,$D$23))) -> 0.11861224 | J8: =H8*F8 -> 0.0037066324
A9: XS0456451771 | B9: October 2009 issue [ISIN: XS0456451771] of €800 million, maturing October 2019, bearing annual interest at 4.125% | D9: 800 | F9: 0.04125 | H9: =IF($A$22="NO",D9/(SUM($D$5:$D$12)),D9/(SUM($D$5:$D$12,$D$22,$D$23))) -> 0.079074825 | J9: =H9*F9 -> 0.0032618365
A10: CH0035703070 | B10: December 2007 and February 2008 issues [ISIN: CH0035703070] of CHF400 million (€320 million), maturing December 2015, bearing annual interest at 3.375%, and swapped into euros at a fixed rate of 4.867% | D10: 320 | F10: 0.04867 | H10: =IF($A$22="NO",D10/(SUM($D$5:$D$12)),D10/(SUM($D$5:$D$12,$D$22,$D$23))) -> 0.03162993 | J10: =H10*F10 -> 0.0015394287
A11: CH0048787532 | B11: December 2008 and January 2009 issues [ISIN: CH0048787532] amounting to CHF275 million at a fixed rate of 4.894%, maturing December 2012 | D11: 220 | F11: 0.04894 | H11: =IF($A$22="NO",D11/(SUM($D$5:$D$12)),D11/(SUM($D$5:$D$12,$D$22,$D$23))) -> 0.021745577 | J11: =H11*F11 -> 0.0010642285
A12: CH0048787532 | B12: December 2008 and January 2009 issues [ISIN: CH0048787532] amounting to CHF250 million at a floating rate indexed to 3-month Euribor | D12: 200 | F12: =B18 -> 0.01001 | H12: =IF($A$22="NO",D12/(SUM($D$5:$D$12)),D12/(SUM($D$5:$D$12,$D$22,$D$23))) -> 0.019768706 | J12: =H12*F12 -> 0.00019788475
J13: 0.037465903 | K13: Cost of debt without Provisions and other non current liabilities
A14: XS0176128675 | B14: September 2003 issue [ISIN: XS0176128675] with a nominal value of €1,500 million, maturing September 2010, bearing annual interest at 4.25% | D14: 1500 | F14: =(1+0.0425)^(257/365)-1 -> 0.029739873 | H14: =IF($A$22="NO",D14/(SUM($D$5:$D$12)),D14/(SUM($D$5:$D$12,$D$22,$D$23))) -> 0.1482653 | J14: =H14*F14 -> 0.0044093911
A15: ISIN: XS0282647634 | B15: January 2007 issue [ISIN: XS0282647634] amounting to £200 million (€225 million), maturing January 2010, bearing annual interest at 5.50% and swapped into euros at a floating rate indexed to 3-month Euribor | D15: 227 | F15: =(1+F12)^(18/365)-1 -> 0.00049131017 | H15: =IF($A$22="NO",D15/(SUM($D$5:$D$12)),D15/(SUM($D$5:$D$12,$D$22,$D$23))) -> 0.022437481 | J15: =H15*F15 -> 1.1023763e-05
A16: CH0035703021 | B16: December 2007 issue [ISIN: CH0035703021] amounting to CHF200 million (€135 million), maturing January 2010, bearing annual interest of 2.75%, and swapped into euros at a floating rate indexed to 6-month Euribor | D16: 136 | F16: =(1+B19)^(21/365)-1 -> 0.00070018922 | H16: =IF($A$22="NO",D16/(SUM($D$5:$D$12)),D16/(SUM($D$5:$D$12,$D$22,$D$23))) -> 0.01344272 | J16: =H16*F16 -> 9.4124478e-06
D17: =SUM(D5:D12) -> 5878
A18: Euribor 3M | B18: 0.01001
A19: Euribor 6M | B19: 0.01224
A20: Source: 3M Euribor rate = 03-01-2011 1,001 % http://www.euribor-rates.eu/euribor-2011.asp?i1=6&i2=1
A22: YES | B22: Provisions and other non-current liabilities | D22: =F36 -> 3854 | F22: =G36 -> 0.0497 | H22: =D22/SUM(D22,D23,D5:D12) -> 0.38094297 | J22: =F22*H22 -> 0.018932865
D23: =H36 -> 385 | F23: =I36 -> 0.0545 | H23: =D23/SUM(D23,D22,D6:D12) -> 0.03858102 | J23: =F23*H23 -> 0.0021026656
A25: YES | J25: =IF(A22="NO",SUM(J5:J12),SUM(J5:J12,J22,J23)) -> 0.042803306 | K25: Cost of Debt
A26: NO
B28: CONSOLIDATED BALANCE SHEET
B29: (€ million) | C29: Note | D29: December 31, 2010
B30: LIABILITIES & EQUITY
B31: Equity attributable to equity holders of sanofi-aventis | D31: 53097
B32: Equity attributable to non-controlling interests | D32: 191
B33: Total equity | D33: 53288
B34: Long-term debt | C34: D17 | D34: 6695 | E34: 1
B35: Non-current liabilities related to business combinations and to non-controlling interests | C35: D18 | D35: 388 | E35: 0
B36: Provisions and other non-current liabilities | C36: D19 | D36: 9326 | E36: 1 | F36: 3854 | G36: 0.0497 | H36: 385 | I36: 0.0545 | J36: Pensions and other long term benefits
B37: Deferred tax liabilities | C37: D14 | D37: 3808 | E37: 0
B38: Non-current liabilities | D38: 20217
B39: Accounts payable | D39: 2800 | E39: 0
B40: Other current liabilities | C40: D19,4 | D40: 5624 | E40: 0
B41: Current liabilities related to business combinations and to non-controlling interests | C41: D18 | D41: 98 | E41: 0
B42: Short-term debt and current portion of long-term debt | C42: D17 | D42: 1565 | E42: 1
B43: Current liabilities | D43: 10087 | J43: Equity | K43: 62444.25
B44: Liabilities related to assets held for sale or exchange | C44: D8 | D44: 1672 | J44: Debt | K44: =D34+D42+'Operating lease converter'!F64+H36+F36 -> 12499
...

Sheet WACC
B2: Marginal tax rate | D2: 0.3333
B4: Value of Equity | D4: ='Cost of Equity'!G35 -> 62444.25
B5: Value of Debt | D5: ='Cost of Equity'!G36 -> 13587.533 | E5: =D5/D6 -> 0.17870859
D6: =D4+D5 -> 76031.783
B8: Cost of Equity | D8: ='Cost of Equity'!B37 -> 0.040370545 | E8: 0.1003 | F8: Bloomberg
B9: Cost of Debt | D9: ='Cost of Debt'!J25 -> 0.042803306
B11: After-tax WACC | D11: =D4/D6*E8+D5/D6*D9*(1-D2) -> 0.087475329 | E11: =D4/D6*D8+D5/D6*D9*(1-D2) -> 0.038255782

Sheet FINANCIALS >>>>

Sheet Assumption
S1: Acquisition
E2: Choice of the scenario | H2: Acquisition | S2: Increased prices
A4: M&A
A5: Assumptions | D5: Actual | F5: Projections
A6: €m | D6: 2006 | E6: 2007 | F6: 2008 | G6: 2009 | H6: 2010 | I6: 2011 | J6: 2012 | K6: 2013 | L6: 2014 | M6: 2015
B8: Operating assumptions 1 - Acquisition of a biotech to offset the loss of patents
D9: 2006 | E9: 2007 | F9: 2008 | G9: 2009 | H9: 2010 | I9: 2011 | J9: 2012 | K9: 2013 | L9: 2014 | M9: 2015
B10: Income statement
B11: Sales growth | D11: NA | E11: ='Income Statement'!E7/'Income Statement'!D7-1 -> -0.011313573 | F11: ='Income Statement'!F7/'Income Statement'!E7-1 -> -0.017253672 | G11: ='Income Statement'!G7/'Income Statement'!F7-1 -> 0.063044109 | H11: ='Income Statement'!H7/'Income Statement'!G7-1 -> 0.036784276 | I11: =H11-(G11-H11) -> 0.010524443 | J11: =I11+5% -> 0.060524443 | K11: 0.011 | L11: 0.061 | M11: 0.011 | O11: Follow acquistion trend: 2009 jump in sales then decrease
B12: Other revenues | D12: NA | E12: ='Income Statement'!E8/'Income Statement'!D8-1 -> 0.034946237 | F12: ='Income Statement'!F8/'Income Statement'!E8-1 -> 0.081385281 | G12: ='Income Statement'!G8/'Income Statement'!F8-1 -> 0.15532426 | H12: ='Income Statement'!H8/'Income Statement'!G8-1 -> 0.14414414 | I12: =AVERAGE($E$12:$H$12) -> 0.10394998 | J12: =AVERAGE($E$12:$H$12) -> 0.10394998 | K12: =AVERAGE($E$12:$H$12) -> 0.10394998 | L12: =AVERAGE($E$12:$H$12) -> 0.10394998 | M12: =AVERAGE($E$12:$H$12) -> 0.10394998 | O12: Should remain stable on average because of acquisition and loss a patents offsetting
B13: COGS as % of sales | D13: =-'Income Statement'!D9/'Income Statement'!D7 -> 0.26740211 | E13: =-'Income Statement'!E9/'Income Statement'!E7 -> 0.26989163 | F13: =-'Income Statement'!F9/'Income Statement'!F7 -> 0.2661419 | G13: =-'Income Statement'!G9/'Income Statement'!G7 -> 0.26888692 | H13: =-'Income Statement'!H9/'Income Statement'!H7 -> 0.28689442 | I13: =AVERAGE($D$13:$H$13) -> 0.2718434 | J13: =AVERAGE($D$13:$H$13) -> 0.2718434 | K13: =AVERAGE($D$13:$H$13) -> 0.2718434 | L13: =AVERAGE($D$13:$H$13) -> 0.2718434 | M13: =AVERAGE($D$13:$H$13) -> 0.2718434 | O13: Average
B14: SG&A as % of sales | D14: =-'Income Statement'!D10/'Income Statement'!D7 -> 0.2826631 | E14: =-'Income Statement'!E10/'Income Statement'!E7 -> 0.26928561 | F14: =-'Income Statement'!F10/'Income Statement'!F7 -> 0.26001161 | G14: =-'Income Statement'!G10/'Income Statement'!G7 -> 0.24994882 | H14: =-'Income Statement'!H10/'Income Statement'!H7 -> 0.24904555 | I14: =(I6-$D$6)*(-0.0087)+0.2882 -> 0.2447 | J14: =(J6-$D$6)*(-0.0087)+0.2882 -> 0.236 | K14: =(K6-$D$6)*(-0.0087)+0.2882 -> 0.2273 | L14: =(L6-$D$6)*(-0.0087)+0.2882 -> 0.2186 | M14: =(M6-$D$6)*(-0.0087)+0.2882 -> 0.2099 | O14: Follows linear regression
B15: R&D as % of sales | D15: =-'Income Statement'!D11/'Income Statement'!D7 -> 0.15613435 | E15: =-'Income Statement'!E11/'Income Statement'!E7 -> 0.16173535 | F15: =-'Income Statement'!F11/'Income Statement'!F7 -> 0.16595328 | G15: =-'Income Statement'!G11/'Income Statement'!G7 -> 0.15638436 | H15: =-'Income Statement'!H11/'Income Statement'!H7 -> 0.14484597 | I15: =AVERAGE(D15:H15) -> 0.15701066 | J15: =I15+0.02 -> 0.17701066 | K15: =AVERAGE(F15:J15) -> 0.16024099 | L15: =K15+0.02 -> 0.18024099 | M15: =AVERAGE(H15:L15) -> 0.16386985 | O15: Follows acquisition trend: loss of important patents in 2012. Loss of top 3 product patents in 2014. After acquistions we model a jump in R&D expenses because Biotech companies are R&D intensive
B16: Effective tax rate | D16: ='Free Cash Flow'!D14 -> 0.17 | E16: ='Free Cash Flow'!E14 -> 0.12 | F16: ='Free Cash Flow'!F14 -> 0.16 | G16: ='Free Cash Flow'!G14 -> 0.22 | H16: ='Free Cash Flow'!H14 -> 0.22 | I16: 0.33 | J16: 0.33 | K16: 0.33 | L16: 0.33 | M16: 0.33
B18: Balance Sheet
B19: NC-WC as % of sales | D19: ='Balance Sheet'!D47/'Income Statement'!D7 -> 0.1157086 | E19: ='Balance Sheet'!E47/'Income Statement'!E7 -> 0.12049052 | F19: ='Balance Sheet'!F47/'Income Statement'!F7 -> 0.13294399 | G19: ='Balance Sheet'!G47/'Income Statement'!G7 -> 0.16177575 | H19: ='Balance Sheet'!H47/'Income Statement'!H7 -> 0.16640337 | I19: =H19+AVERAGE(E19-D19,F19-E19) -> 0.17502107 | J19: =I19+G19-F19 -> 0.20385282 | K19: =J19+0.004 -> 0.20785282 | L19: =K19+0.013 -> 0.22085282 | M19: =L19+AVERAGE(K19-J19,L19-K19) -> 0.22935282 | O19: Follow acquisition trend: 2004, 2009, 2012 jumps in WC as observe in 2005 and 2009
B21: Cash Flow Statement
B22: D&A growth rate | D22: NA | E22: ='Cash Flow Statement'!E7/'Cash Flow Statement'!D7-1 -> -0.23703583 | F22: ='Cash Flow Statement'!F7/'Cash Flow Statement'!E7-1 -> 0.28323328 | G22: ='Cash Flow Statement'!G7/'Cash Flow Statement'!F7-1 -> -0.16274018 | H22: ='Cash Flow Statement'!H7/'Cash Flow Statement'!G7-1 -> 0.023548194 | I22: =AVERAGE($E$22:$H$22) -> -0.023248635 | J22: =AVERAGE($E$22:$H$22) -> -0.023248635 | K22: =AVERAGE($E$22:$H$22) -> -0.023248635 | L22: =AVERAGE($E$22:$H$22) -> -0.023248635 | M22: =AVERAGE($E$22:$H$22) -> -0.023248635 | O22: Should correspond to last years average because the Capex follow the same trend
B24: PPE as % of sales | D24: =-'Cash Flow Statement'!D9/'Income Statement'!D7 -> 0.051245903 | E24: =-'Cash Flow Statement'!E9/'Income Statement'!E7 -> 0.057393412 | F24: =-'Cash Flow Statement'!F9/'Income Statement'!F7 -> 0.058255949 | G24: =-'Cash Flow Statement'!G9/'Income Statement'!G7 -> 0.060909029 | H24: =-'Cash Flow Statement'!H9/'Income Statement'!H7 -> 0.051770669 | I24: =AVERAGE($D$24:$H$24) -> 0.055914992 | J24: =AVERAGE($D$24:$H$24) -> 0.055914992 | K24: =AVERAGE($D$24:$H$24) -> 0.055914992 | L24: =AVERAGE($D$24:$H$24) -> 0.055914992 | M24: =AVERAGE($D$24:$H$24) -> 0.055914992 | O24: Should remain stable on average
B25: Acquisition as % of sales | D25: =-'Cash Flow Statement'!D10/'Income Statement'!D7 -> 0.01793959 | E25: =-'Cash Flow Statement'!E10/'Income Statement'!E7 -> 0.0076286896 | F25: =-'Cash Flow Statement'!F10/'Income Statement'!F7 -> 0.023977075 | G25: =-'Cash Flow Statement'!G10/'Income Statement'!G7 -> 0.18982461 | H25: =-'Cash Flow Statement'!H10/'Income Statement'!H7 -> 0.054601106 | I25: =AVERAGE($H$25,$F$25,$E$25,$D$25) -> 0.026036615 | J25: 0.21 | K25: =AVERAGE($H$25,$F$25,$E$25,$D$25) -> 0.026036615 | L25: 0.21 | M25: =AVERAGE($H$25,$F$25,$E$25,$D$25) -> 0.026036615 | O25: Should remain stable on average except for acquistion year
B26: Capex as % of sales | D26: =SUM(D24,D25) -> 0.069185493 | E26: =SUM(E24,E25) -> 0.065022102 | F26: =SUM(F24,F25) -> 0.082233024 | G26: =SUM(G24,G25) -> 0.25073364 | H26: =SUM(H24,H25) -> 0.10637177 | I26: =SUM(I24,I25) -> 0.081951608 | J26: =SUM(J24,J25) -> 0.26591499 | K26: =SUM(K24,K25) -> 0.081951608 | ... M26: =SUM(M24,M25) -> 0.081951608 | O26: Follow acquisition trend: 2004, 2009, 2012 jumps in acquisition capex observed in 2009. We think the acquistion will be similar to Merial around 7 billion€
B27: Figure 1: Table of assumptions for scenario 1
B29: Operating assumptions 2 - Sanofi manages to keep a dynamic growth rate before the loss of patents collapse
D30: 2006 | E30: 2007 | F30: 2008 | G30: 2009 | H30: 2010 | I30: 2011 | J30: 2012 | K30: 2013 | L30: 2014 | M30: 2015
B31: Income statement
B32: Sales growth | D32: =D11 -> NA | E32: =E11 -> -0.011313573 | F32: =F11 -> -0.017253672 | G32: =G11 -> 0.063044109 | H32: =H11 -> 0.036784276 | I32: =H32 -> 0.036784276 | J32: =I32 -> 0.036784276 | K32: 0 | L32: -0.025 | M32: -0.05
B33: Other revenues | D33: =D12 -> NA | E33: =E12 -> 0.034946237 | F33: =F12 -> 0.081385281 | G33: =G12 -> 0.15532426 | H33: =H12 -> 0.14414414 | I33: =AVERAGE($E$33:$H$33) -> 0.10394998 | J33: =AVERAGE($E$33:$H$33) -> 0.10394998 | K33: =AVERAGE($E$33:$H$33) -> 0.10394998 | L33: =AVERAGE($E$33:$H$33) -> 0.10394998 | M33: =AVERAGE($E$33:$H$33) -> 0.10394998
B34: COGS as % of sales | D34: =D13 -> 0.26740211 | E34: =E13 -> 0.26989163 | F34: =F13 -> 0.2661419 | G34: =G13 -> 0.26888692 | H34: =H13 -> 0.28689442 | I34: =(H6-$E$6)*0.0038+0.2604 -> 0.2718 | J34: =(I6-$E$6)*0.0038+0.2604 -> 0.2756 | K34: =(J6-$E$6)*0.0038+0.2604 -> 0.2794 | L34: =(K6-$E$6)*0.0038+0.2604 -> 0.2832 | M34: =(L6-$E$6)*0.0038+0.2604 -> 0.287
B35: SG&A as % of sales | D35: =D14 -> 0.2826631 | E35: =E14 -> 0.26928561 | F35: =F14 -> 0.26001161 | G35: =G14 -> 0.24994882 | H35: =H14 -> 0.24904555 | I35: =(I6-$D$6)*(-0.0087)+0.2882 -> 0.2447 | J35: =(J6-$D$6)*(-0.0087)+0.2882 -> 0.236 | K35: =(K6-$D$6)*(-0.0087)+0.2882 -> 0.2273 | L35: =(L6-$D$6)*(-0.0087)+0.2882 -> 0.2186 | M35: =(M6-$D$6)*(-0.0087)+0.2882 -> 0.2099
B36: R&D as % of sales | D36: =D15 -> 0.15613435 | E36: =E15 -> 0.16173535 | F36: =F15 -> 0.16595328 | G36: =G15 -> 0.15638436 | H36: =H15 -> 0.14484597 | I36: =AVERAGE(E36:H36)+0.005 -> 0.16222974 | J36: =I36+0.005 -> 0.16722974 | K36: =J36+0.005 -> 0.17222974 | L36: =K36+0.005 -> 0.17722974 | M36: =L36+0.005 -> 0.18222974
B37: Effective tax rate | D37: =D16 -> 0.17 | E37: =E16 -> 0.12 | F37: =F16 -> 0.16 | G37: =G16 -> 0.22 | H37: =H16 -> 0.22 | I37: 0.33 | J37: 0.33 | K37: 0.33 | L37: 0.33 | M37: 0.33
B39: Balance Sheet
B40: NC-WC as % of sales | D40: 0.1157086 | E40: 0.12049052 | F40: 0.13294399 | G40: 0.16177575 | H40: 0.16640337 | I40: =AVERAGE($G$40:$H$40) -> 0.16408956 | J40: =AVERAGE($G$40:$H$40) -> 0.16408956 | K40: =AVERAGE($G$40:$H$40) -> 0.16408956 | L40: =AVERAGE($G$40:$H$40) -> 0.16408956 | M40: =AVERAGE($G$40:$H$40) -> 0.16408956
B42: Cash Flow Statement
B43: D&A growth rate | D43: NA | E43: -0.23703583 | F43: 0.28323328 | G43: -0.16274018 | H43: 0.023548194 | I43: =AVERAGE($E$43:$H$43) -> -0.023248635 | J43: =AVERAGE($E$43:$H$43) -> -0.023248635 | K43: =AVERAGE($E$43:$H$43) -> -0.023248635 | L43: =AVERAGE($E$43:$H$43) -> -0.023248635 | M43: =AVERAGE($E$43:$H$43) -> -0.023248635
B44: Capex as % of sales | D44: 0.069185493 | E44: 0.065022102 | F44: 0.082233024 | G44: 0.25073364 | H44: 0.10637177 | I44: =AVERAGE($H$44,$F$44,$E$44,$D$44) -> 0.080703098 | J44: =AVERAGE($H$44,$F$44,$E$44,$D$44) -> 0.080703098 | K44: =AVERAGE($H$44,$F$44,$E$44,$D$44) -> 0.080703098 | L44: =AVERAGE($H$44,$F$44,$E$44,$D$44) -> 0.080703098 | M44: =AVERAGE($H$44,$F$44,$E$44,$D$44) -> 0.080703098
B46: Figure 2: Table of assumptions for scenario 2
I104: 5951 | J104: =-'Income Statement'!D15 -> 6113
J105: =(J104-I104)/I104 -> 0.027222316
I110: 27.311 | J110: =I110/(-I111-I112) -> 0.039401682
...

Sheet Balance Sheet
A1: Project EBS
A2: Income Statement | D2: Actual | F2: Projections
A3: €m | D3: 2006 | E3: 2007 | F3: 2008 | G3: 2009 | H3: 2010 | I3: 2011 | J3: 2012 | K3: 2013 | L3: 2014 | M3: 2015
B5: Assets
B7: Cash & cash equivalents | D7: 1153 | E7: 1711 | F7: 4226 | G7: 4692 | H7: 6465
B8: Inventory | D8: 3659 | E8: 3729 | F8: 3590 | G8: 4444 | H8: 5020
B9: Accounts receivable | D9: 5032 | E9: 4904 | F9: 5303 | G9: 6015 | H9: 6507
B10: Other current assets | D10: 2316 | E10: 2209 | F10: 2284 | G10: 2381 | H10: 2051
B11: Total current assets | D11: =SUM(D7:D10) -> 12160 | E11: =SUM(E7:E10) -> 12553 | F11: =SUM(F7:F10) -> 15403 | G11: =SUM(G7:G10) -> 17532 | H11: =SUM(H7:H10) -> 20043
B13: PP&E | D13: 6219 | E13: 6538 | F13: 6961 | G13: 7830 | H13: 8155
B14: Goodwill | D14: 28472 | E14: 27199 | F14: 28163 | G14: 29733 | H14: 31932
B15: Other fixed assets | D15: 30912 | E15: 25624 | F15: 21460 | G15: 18612 | H15: 18098
B16: Total fixed assets | D16: =SUM(D13:D15) -> 65603 | E16: =SUM(E13:E15) -> 59361 | F16: =SUM(F13:F15) -> 56584 | G16: =SUM(G13:G15) -> 56175 | H16: =SUM(H13:H15) -> 58185
B18: Assets held for sale of exchange | D18: 0 | E18: 0 | F18: 0 | G18: 6544 | H18: 7036
B19: Total assets | D19: =D11+D16+D18 -> 77763 | E19: =E11+E16+E18 -> 71914 | F19: =F11+F16+F18 -> 71987 | G19: =G11+G16+G18 -> 80251 | H19: =H11+H16+H18 -> 85264
B21: Equity and Liabilities
B23: Accounts payable | D23: 3008 | E23: 2749 | F23: 2791 | G23: 2654 | H23: 2800
B24: Short-term debt and current portion of long-term debt | D24: 2554 | E24: 2207 | F24: 1833 | G24: 2866 | H24: 1565
B25: Other current liabilities | D25: 4716 | E25: 4713 | F25: 4721 | G25: 5445 | H25: 5722
B26: Total current libailities | D26: =SUM(D23:D25) -> 10278 | E26: =SUM(E23:E25) -> 9669 | F26: =SUM(F23:F25) -> 9345 | G26: =SUM(G23:G25) -> 10965 | H26: =SUM(H23:H25) -> 10087
B28: Long-term debt | D28: 4499 | E28: 3734 | F28: 4173 | G28: 5961 | H28: 6695
B29: Provisions and other non-current liabilities | D29: 7920 | E29: 6857 | F29: 7730 | G29: 8236 | H29: 9326
B30: Other non-current liabilities | D30: 9246 | E30: 6935 | F30: 5668 | G30: 5008 | H30: 4196
B31: Total liabilities | D31: =D26+SUM(D28:D30) -> 31943 | E31: =E26+SUM(E28:E30) -> 27195 | F31: =F26+SUM(F28:F30) -> 26916 | G31: =G26+SUM(G28:G30) -> 30170 | H31: =H26+SUM(H28:H30) -> 30304
B33: Equity attributable to equity holders of the Company | D33: 45600 | E33: 44542 | F33: 44866 | G33: 48322 | H33: 53097
B34: Minority interests | D34: 220 | E34: 177 | F34: 205 | G34: 258 | H34: 191
B35: Total equity | D35: =SUM(D33:D34) -> 45820 | E35: =SUM(E33:E34) -> 44719 | F35: =SUM(F33:F34) -> 45071 | G35: =SUM(G33:G34) -> 48580 | H35: =SUM(H33:H34) -> 53288
B37: Liabilities related to assets held for sale or exchange | D37: 0 | E37: 0 | F37: 0 | G37: 1501 | H37: 1672
B38: Total equity and liabilities | D38: =D31+D35+D37 -> 77763 | E38: =E31+E35+E37 -> 71914 | F38: =F31+F35+F37 -> 71987 | G38: =G31+G35+G37 -> 80251 | H38: =H31+H35+H37 -> 85264
B39: check | D39: =IF(ROUND(D38-D19,1)=0,"ok!",D38-D19) -> ok! | E39: =IF(ROUND(E38-E19,1)=0,"ok!",E38-E19) -> ok! | F39: =IF(ROUND(F38-F19,1)=0,"ok!",F38-F19) -> ok! | G39: =IF(ROUND(G38-G19,1)=0,"ok!",G38-G19) -> ok! | H39: =IF(ROUND(H38-H19,1)=0,"ok!",H38-H19) -> ok!
B42: Operating Working Capital | C42: 2005 | D42: 2006 | E42: 2007 | F42: 2008 | G42: 2009 | H42: 2010 | I42: 2011 | J42: 2012 | K42: 2013 | L42: 2014 | M42: 2015
B43: Total current assets | C43: 13121 | D43: =D11 -> 12160 | E43: =E11 -> 12553 | F43: =F11 -> 15403 | G43: =G11 -> 17532 | H43: =H11 -> 20043
B44: - Cash and Cash equivalents | C44: 1249 | D44: =D7 -> 1153 | E44: =E7 -> 1711 | F44: =F7 -> 4226 | G44: =G7 -> 4692 | H44: =H7 -> 6465
B45: -Total curent liabilities | C45: 15420 | D45: =D26 -> 10278 | E45: =E26 -> 9669 | F45: =F26 -> 9345 | G45: =G26 -> 10965 | H45: =H26 -> 10087
B46: + Short-term debt and current portion of long-term debt | C46: 6425 | D46: =D24 -> 2554 | E46: =E24 -> 2207 | F46: =F24 -> 1833 | G46: =G24 -> 2866 | H46: =H24 -> 1565
B47: NET NON-CASH WORKING CAPITAL | C47: =C43-C44-C45+C46 -> 2877 | D47: =D43-D44-D45+D46 -> 3283 | E47: =E43-E44-E45+E46 -> 3380 | F47: =F43-F44-F45+F46 -> 3665 | G47: =G43-G44-G45+G46 -> 4741 | H47: =H43-H44-H45+H46 -> 5056 | I47: =IF(Assumption!$H$2=Assumption!$S$1,Assumption!I19*'Income Statement'!I7,IF(Assumption!$H$2=Assumption!$S$2,'Income Statement'!I7*Assumption!I40,Assumption!#REF!*'Income Statement'!I7)) -> 5373.8075 | J47: =IF(Assumption!$H$2=Assumption!$S$1,Assumption!J19*'Income Statement'!J7,IF(Assumption!$H$2=Assumption!$S$2,'Income Statement'!J7*Assumption!J40,Assumption!#REF!*'Income Statement'!J7)) -> 6637.8767 | K47: =IF(Assumption!$H$2=Assumption!$S$1,Assumption!K19*'Income Statement'!K7,IF(Assumption!$H$2=Assumption!$S$2,'Income Statement'!K7*Assumption!K40,Assumption!#REF!*'Income Statement'!K7)) -> 6842.5745 | L47: =IF(Assumption!$H$2=Assumption!$S$1,Assumption!L19*'Income Statement'!L7,IF(Assumption!$H$2=Assumption!$S$2,'Income Statement'!L7*Assumption!L40,Assumption!#REF!*'Income Statement'!L7)) -> 7714.041 | M47: =IF(Assumption!$H$2=Assumption!$S$1,Assumption!M19*'Income Statement'!M7,IF(Assumption!$H$2=Assumption!$S$2,'Income Statement'!M7*Assumption!M40,Assumption!#REF!*'Income Statement'!M7)) -> 8099.0529
B49: Δ NET NON-CASH WORKING CAPITAL | D49: =D47-C47 -> 406 | E49: =E47-D47 -> 97 | F49: =F47-E47 -> 285 | G49: =G47-F47 -> 1076 | H49: =H47-G47 -> 315 | I49: =I47-H47 -> 317.80746 | J49: =J47-I47 -> 1264.0692 | K49: =K47-J47 -> 204.69779 | ... M49: =M47-L47 -> 385.01186

Sheet Income Statement
A1: Project EBS
