Workbook
Name ScenarioSelection: '[1]Table of Contents'!$H$4:$H$7
Name ScenarioSelection: '[2]Table of Contents'!$J$1:$J$3
Name ScenarioSelection: '[1]Table of Contents'!$H$4:$H$7
Name ScenarioSelection: '[3]Table of Contents'!$H$9:$H$11
Name ScenarioSelection: '[4]Cover Sheet'!$B$1:$B$3
Name ScenarioSelection: 'Table of Contents'!$J$1:$J$3

Sheet Table of Contents
I1: Scenario Selection: | J1: Scenario 1: Base Case
A2: NIKE Inc (NKE US) - Table of Contents | J2: Scenario 2: Bull Case
J3: Scenario 3: Bear Case
A4: Table of Contents | D4: Click here:
A6: Key Results: | B6: Table of Contents | C6: >> | D6: Table of Contents'!A1
B7: Summary of Results | C7: >> | D7: Summary!A1
B8: Business Opportunity | C8: >> | D8: Business Opportunity'!A1
A10: Calculations: | B10: Free Cash Flows | C10: >> | D10: Free Cash Flows'!A1
B11: Beta Calculation | C11: >> | D11: Beta Calculation'!A1
B12: Cost of Equity | C12: >> | D12: Cost of Equity'!A1
B13: Cost of Debt | C13: >> | D13: Cost of Debt'!A1
B14: WACC | C14: >> | D14: WACC!A1
B15: DCF | C15: >> | D15: DCF!A1
B16: APV | C16: >> | D16: APV!A1
B17: Trading Multiples | C17: >> | D17: Trading Multiples'!A1
A19: Supporting Calculations: | B19: Growth Scenarios | C19: >> | D19: Growth Scenarios'!A1
B20: Marginal Tax Rate | C20: >> | D20: Marginal Tax Rate'!A1
B21: Cost of Debt per Bond | C21: >> | D21: Corporate Bond 1'!A1
A23: Appendices: | B23: Balance Sheet | C23: >> | D23: Balance Sheet'!A1
B24: Income Statement | C24: >> | D24: Income Statement'!A1
B25: Cash Flow Statement | C25: >> | D25: Cash Flow Statement '!A1
B26: Share Prices | C26: >> | D26: Share Prices'!A1
B27: SPX | C27: >> | D27: SPX!A1
B28: Trading Multiples Bloomberg | C28: >> | D28: Trading Multiples Bloomberg'!A1

Sheet Summary
A2: NIKE Inc (NKE US) - Summary of Results
A4: Method of Calculating Expected Enterprise Value | C4: Expected Enterprise Value
A6: In Million USD | C6: Min | D6: 25th | E6: Median | F6: 75th | G6: Max | H6: Min Point | I6: 25th Point | J6: Median Point | K6: 75th Point | L6: Max Point
A8: Adjusted Present Value | C8: =MIN(C16:J16) -> 70813.15 | D8: =_xlfn.QUARTILE.EXC(C16:K16,1) -> 80857.012 | E8: =_xlfn.QUARTILE.EXC(C16:K16,2) -> 91411.225 | F8: =_xlfn.QUARTILE.EXC(C16:K16,3) -> 109169.7 | G8: =MAX(C16:K16) -> 124813.49 | H8: =C8 -> 70813.15 | I8: =D8-C8 -> 10043.863 | J8: =E8-D8 -> 10554.213 | K8: =F8-E8 -> 17758.477 | L8: =G8-F8 -> 15643.788
A9: Discounted Cash Flow | C9: =MIN(C15:K15) -> 67027.38 | D9: =_xlfn.QUARTILE.EXC(C15:K15,1) -> 79496.265 | E9: =_xlfn.QUARTILE.EXC(C15:K15,2) -> 94426.94 | F9: =_xlfn.QUARTILE.EXC(C15:K15,3) -> 116407.28 | G9: =MAX(C15:K15) -> 136587.54 | H9: =C9 -> 67027.38 | I9: =D9-C9 -> 12468.885 | J9: =E9-D9 -> 14930.675 | K9: =F9-E9 -> 21980.34 | L9: =G9-F9 -> 20180.26
A10: Multiples Based on Assets | C10: =MIN('Trading Multiples'!J46:J54) -> 23420.899 | D10: =_xlfn.QUARTILE.EXC('Trading Multiples'!J46:J53,1) -> 29877.297 | E10: ='Trading Multiples'!J55 -> 42250.429 | F10: =_xlfn.QUARTILE.EXC('Trading Multiples'!J46:J54,3) -> 75465.321 | G10: =MAX('Trading Multiples'!J46:J54) -> 88060.992 | H10: =C10 -> 23420.899 | I10: =D10-C10 -> 6456.3976 | J10: =E10-D10 -> 12373.132 | K10: =F10-E10 -> 33214.892 | L10: =G10-F10 -> 12595.672
A11: Price Multiples Based on Cash Flows (1) | C11: =MIN('Trading Multiples'!I65:I74) -> 57393.359 | D11: =_xlfn.QUARTILE.EXC('Trading Multiples'!I65:I73,1) -> 83043.973 | E11: ='Trading Multiples'!I74 -> 98271.31 | F11: =_xlfn.QUARTILE.EXC('Trading Multiples'!I65:I73,3) -> 160056.7 | G11: =MAX('Trading Multiples'!I65:I72) -> 187449.75 | H11: =C11 -> 57393.359 | I11: =D11-C11 -> 25650.613 | J11: =E11-D11 -> 15227.337 | K11: =F11-E11 -> 61785.39 | L11: =G11-F11 -> 27393.053
A12: Price Multiples Based on Cash Flows (2) | C12: =MIN('Trading Multiples'!J65:J73) -> 45327.081 | D12: =_xlfn.QUARTILE.EXC('Trading Multiples'!J65:J73,1) -> 65732.888 | E12: =_xlfn.QUARTILE.EXC('Trading Multiples'!J65:J73,2) -> 85843.569 | F12: =_xlfn.QUARTILE.EXC('Trading Multiples'!J65:J73,3) -> 126347.61 | G12: =MAX('Trading Multiples'!J65:J72) -> 148790.71 | H12: =C12 -> 45327.081 | I12: =D12-C12 -> 20405.806 | J12: =E12-D12 -> 20110.681 | K12: =F12-E12 -> 40504.04 | L12: =G12-F12 -> 22443.104
A13: Value Multiples Based on Cash Flows | C13: =MIN('Trading Multiples'!H27:H35) -> 39541.859 | D13: =_xlfn.QUARTILE.EXC('Trading Multiples'!H27:H35,1) -> 58723.315 | E13: ='Trading Multiples'!H36 -> 76319.658 | F13: =_xlfn.QUARTILE.EXC('Trading Multiples'!H27:H35,3) -> 85167.465 | G13: =MAX('Trading Multiples'!H27:H35) -> 96809.615 | H13: =C13 -> 39541.859 | I13: =D13-C13 -> 19181.457 | J13: =E13-D13 -> 17596.342 | K13: =F13-E13 -> 8847.807 | L13: =G13-F13 -> 11642.151
A15: Possible values DCF | C15: 94426.94 | D15: 124160.3 | E15: 76066.06 | F15: 103643.41 | G15: 136587.54 | H15: 83309.37 | I15: 82926.47 | J15: 108654.26 | K15: 67027.38
A16: Possible values APV | C16: 70813.15 | D16: 79180.65 | E16: 85886.1 | F16: 86089.77 | G16: 96732.68 | H16: 105261.88 | I16: 110472.31 | J16: 124813.49
A17: Football Field Expected Enterprise Value
A44: Enterprise Value Based on Discounted Cash Flows
A46: In Million USD | C46: PV Terminal Value | D46: PV Cash Flows | E46: Enterprise Value
A48: Base Case / Base Case | B48: Base/Base | C48: 72210.685 | D48: 21616.73 | E48: =D48+C48 -> 93827.415
A49: Base Case / Bull Case | B49: Base/Bull | C49: 100812.78 | D49: 22474.29 | E49: =D49+C49 -> 123287.07
A50: Base Case / Bear Case | B50: Base/Bear | C50: 54805.79 | D50: 20809.24 | E50: =D50+C50 -> 75615.03
A52: Bull Case / Base Case | B52: Bull/Base | C52: 80077 | D52: 22902.31 | E52: =D52+C52 -> 102979.31
A53: Bull Case / Bull Case | B53: Bull/Bull | C53: 111794.88 | D53: 23824.96 | E53: =D53+C53 -> 135619.84
A54: Bull Case / Bear Case | B54: Bull/Bear | C54: 60776.1 | D54: 22033.93 | E54: =D54+C54 -> 82810.03
A56: Bear Case / Base Case | B56: Bear/Base | C56: 62398.72 | D56: 20008.8 | E56: =D56+C56 -> 82407.52
A57: Bear Case / Bull Case | B57: Bear/Bull | C57: 87114.37 | D57: 20784.52 | E57: =D57+C57 -> 107898.89
A58: Bear Case / Bear Case | B58: Bear/Bear | C58: 47358.8 | D58: 19277.86 | E58: =D58+C58 -> 66636.66
A61: Discounted Cash Flow Method
A84: Enterprise Value based on Adjusted Present Value
A86: In Million USD | C86: PV Terminal Value | D86: PV Cash Flows | E86: PV Tax Shield | F86: Cost of Fin. Distress | G86: APV | I86: PV Terminal Value | J86: PV Cash Flows | K86: PV Tax Shield | L86: Cost of Fin. Distress | M86: APV
A88: Base Case / Base Case | C88: 72210.685 | D88: 21616.73 | E88: 9289.19 | F88: 6383.93 | G88: 96732.68 | H88: Base/Base | I88: 72210.685 | J88: 21616.73 | K88: 9289.19 | L88: 6383.93 | M88: 96732.68
A89: Base Case / Bull Case | C89: 100812.78 | D89: 22474.29 | E89: 9914.76 | F89: 8388.34 | G89: 124813.49 | H89: Base/Bull | I89: 100812.78 | J89: 22474.29 | K89: 9914.76 | L89: 8388.34 | M89: 124813.49
A90: Base Case / Bear Case | C90: 54805.79 | D90: 20809.24 | E90: 8710.4 | F90: 5144.78 | G90: 79180.65 | H90: Base/Bear | I90: 54805.79 | J90: 20809.24 | K90: 8710.4 | L90: 5144.78 | M90: 79180.65
A92: Bull Case / Base Case | C92: 80077 | D92: 22902.31 | E92: 9289.19 | F92: 7006.62 | G92: 105261.88 | H92: Bull/Base | I92: 80077 | J92: 22902.31 | K92: 9289.19 | L92: 7006.62 | M92: 105261.88
A93: Bull Case / Bull Case | C93: 111794.88 | D93: 23824.96 | E93: 9914.76 | F93: 9227.45 | G93: 136307.15 | H93: Bull/Bull | I93: 111794.88 | J93: 23824.96 | K93: 9914.76 | L93: 9227.45 | M93: 136307.15
A94: Bull Case / Bear Case | C94: 60776.1 | D94: 22033.93 | E94: 8710.4 | F94: 5634.32 | G94: 85886.1 | H94: Bull/Bear | I94: 60776.1 | J94: 22033.93 | K94: 8710.4 | L94: 5634.32 | M94: 85886.1
A96: Bear Case / Base Case | C96: 62398.72 | D96: 20008.8 | E96: 9289.19 | F96: 5606.93 | G96: 86089.77 | H96: Bear/Base | I96: 62398.72 | J96: 20008.8 | K96: 9289.19 | L96: 5606.93 | M96: 86089.77
A97: Bear Case / Bull Case | C97: 87114.37 | D97: 20784.52 | E97: 9914.76 | F97: 7341.34 | G97: 110472.31 | H97: Bear/Bull | I97: 87114.37 | J97: 20784.52 | K97: 9914.76 | L97: 7341.34 | M97: 110472.31
A98: Bear Case / Bear Case | C98: 47358.8 | D98: 19277.86 | E98: 8710.4 | F98: 4533.9 | G98: 70813.15 | H98: Bear/Bear | I98: 47358.8 | J98: 19277.86 | K98: 8710.4 | L98: 4533.9 | M98: 70813.15
A101: Adjusted Present Value Method

Sheet Business Opportunity
A2: NIKE Inc (NKE US) - Business Opportunity: Optimization of Capital Structure
A4: OPTIMIZATION CASE 1 | D4: OPTIMIZATION CASE 2 | G4: Summary of Results:
H5: =CONCATENATE("D/V: ",ROUND(WACC!B8*100,2),"%") -> D/V: 3,84% | I5: D/V: 5% | J5: D/V: 7%
G6: PV terminal value | H6: =APV!I29 -> 72210.685 | I6: =B36 -> 72210.685 | J6: =E36 -> 72210.685
A7: Total Capital terminal year | B7: ='Cost of Debt'!R33 -> 98166.089 | D7: Total Capital terminal year | E7: ='Cost of Debt'!R33 -> 98166.089 | G7: PV TS | H7: =APV!I30 -> 9289.1911 | I7: =B17 -> 20422.459 | J7: =E17 -> 28591.442
A8: Debt Ratio terminal year | B8: 0.05 | D8: Debt Ratio terminal year | E8: 0.07 | G8: C FD | H8: =APV!I31 -> 6383.9323 | I8: =B26 -> 6383.9323 | J8: =E26 -> 7170.0145
G9: PV TS - C FD | H9: =H7-H8 -> 2905.2588 | I9: =I7-I8 -> 14038.527 | J9: =J7-J8 -> 21421.428
A10: Present Value of Tax Shield | D10: Present Value of Tax Shield | G10: Enterprise Value | H10: =APV!I33 -> 96732.676 | I10: =B38 -> 107865.94 | J10: =E38 -> 115248.85
A12: Perpetuity growth rate | B12: =APV!B21 -> 0.0302 | D12: Perpetuity growth rate | E12: =APV!B21 -> 0.0302
A13: Discount factor | B13: =APV!B22 -> 0.63670591 | D13: Discount factor | E13: =APV!B22 -> 0.63670591
A14: Terminal year debt balance | B14: =B7*B8 -> 4908.3045 | D14: Terminal year debt balance | E14: =E7*E8 -> 6871.6262
A15: Terminal value of tax shield | B15: ='Marginal Tax Rate'!K18*B14*'Cost of Equity'!N12*(1+'Business Opportunity'!B12)/('Cost of Equity'!N12-'Business Opportunity'!B12)^2 -> 32075.183 | D15: Terminal value of tax shield | E15: ='Marginal Tax Rate'!K18*E14*'Cost of Equity'!N12*(1+'Business Opportunity'!E12)/('Cost of Equity'!N12-'Business Opportunity'!E12)^2 -> 44905.257
A17: Present value of tax shield (PVTS) | B17: =B15*B13 -> 20422.459 | D17: Present value of tax shield (PVTS) | E17: =E15*E13 -> 28591.442
A19: Costs of Financial Distress | D19: Costs of Financial Distress
A21: =APV!A28 -> q | B21: =APV!B28 -> 1.635 | D21: =A21 -> q | E21: =2.01 -> 2.01
A22: =APV!A29 -> ϕ | B22: =APV!B29 -> 16.5 | D22: =A22 -> ϕ | E22: =APV!B29 -> 16.5
A23: =APV!A30 -> rF | B23: =APV!B30 -> 2.33 | D23: =A23 -> rF | E23: =APV!B30 -> 2.33
A24: =APV!A31 -> Φ | B24: =APV!B31 -> 6.8039092 | D24: =A24 -> Φ | E24: =E21/(E21+E23)*E22 -> 7.6417051
A26: Costs of Financial Distress (CFD) | B26: =B24*(APV!I29+SUM(APV!I23:M23))/100 -> 6383.9323 | D26: Costs of Financial Distress (CFD) | E26: =E24*(APV!I29+SUM(APV!I23:M23))/100 -> 7170.0145
A28: PVTS - CFD | B28: =B17-B26 -> 14038.527 | D28: PVTS - CFD | E28: =E17-E26 -> 21421.428
D29: Enterprise Value
A30: rA | B30: =APV!I21 -> 0.094491073 | D30: rA | E30: =APV!I21 -> 0.094491073
A32: Free cash flow terminal year | B32: ='Free Cash Flows'!Q15 -> 6600.064 | D32: Free cash flow terminal year | E32: ='Free Cash Flows'!Q15 -> 6600.064
A33: Perpetuity growth rate | B33: =DCF!B19 -> 0.0343 | D33: Perpetuity growth rate | E33: =B33 -> 0.0343
A34: Terminal Value | B34: =B32*(1+B33)/(B30-B33) -> 113412.93 | D34: Terminal Value | E34: =E32*(1+E33)/(E30-E33) -> 113412.93
A35: Discount Factor | B35: =1/((1+B30)^5) -> 0.63670591 | D35: Discount Factor | E35: =1/((1+E30)^5) -> 0.63670591
A36: PV of Terminal Value | B36: =B34*B35 -> 72210.685 | D36: PV of Terminal Value | E36: =E34*E35 -> 72210.685
A38: Enterprise Value | B38: =B36+SUM(APV!I23:M23)+B28 -> 107865.94 | D38: Enterprise Value | E38: =E36+SUM(APV!I23:M23)+E28 -> 115248.85

Sheet Free Cash Flows
A2: NIKE Inc (NKE US) - Free Cash Flow Calculation
M4: Scenario 1: Base Case | S4: Scenario 2: Bull Case | Y4: Scenario 3: Bear Case
A6: In Millions of USD | B6: FY 2008 | C6: FY 2009 | D6: FY 2010 | E6: FY 2011 | F6: FY 2012 | G6: FY 2013 | H6: FY 2014 | I6: FY 2015 | J6: FY 2016 | K6: FY 2017 | M6: FY 2018E | N6: FY 2019E | O6: FY 2020E | P6: FY 2021E | Q6: FY 2022E | S6: FY 2018E | T6: FY 2019E | U6: FY 2020E | V6: FY 2021E | W6: FY 2022E | Y6: FY 2018E | Z6: FY 2019E | AA6: FY 2020E | AB6: FY 2021E | AC6: FY 2022E
A8: Tax Rate Tc | C8: ='Marginal Tax Rate'!C18 -> 0.29110854 | D8: ='Marginal Tax Rate'!D18 -> 0.29110854 | E8: ='Marginal Tax Rate'!E18 -> 0.29296488 | F8: ='Marginal Tax Rate'!F18 -> 0.29232702 | G8: ='Marginal Tax Rate'!G18 -> 0.29424393 | H8: ='Marginal Tax Rate'!H18 -> 0.29373906 | I8: ='Marginal Tax Rate'!I18 -> 0.29361558 | J8: ='Marginal Tax Rate'!J18 -> 0.29248053 | K8: ='Marginal Tax Rate'!K18 -> 0.29137263 | M8: =$K$8 -> 0.29137263 | N8: =$K$8 -> 0.29137263 | O8: =$K$8 -> 0.29137263 | P8: =$K$8 -> 0.29137263 | Q8: =$K$8 -> 0.29137263 | S8: =$K$8 -> 0.29137263 | T8: =$K$8 -> 0.29137263 | U8: =$K$8 -> 0.29137263 | V8: =$K$8 -> 0.29137263 | W8: =$K$8 -> 0.29137263 | Y8: =$K$8 -> 0.29137263 | Z8: =$K$8 -> 0.29137263 | AA8: =$K$8 -> 0.29137263 | AB8: =$K$8 -> 0.29137263 | AC8: =$K$8 -> 0.29137263
A9: Operating Profit | B9: ='Income Statement'!B12 -> 2433.7 | C9: ='Income Statement'!C12 -> 1858.5 | D9: ='Income Statement'!D12 -> 2474 | E9: ='Income Statement'!E12 -> 2815 | F9: ='Income Statement'!F12 -> 3040 | G9: ='Income Statement'!G12 -> 3254 | H9: ='Income Statement'!H12 -> 3680 | I9: ='Income Statement'!I12 -> 4175 | ... K9: ='Income Statement'!K12 -> 4749 | M9: ='Growth Scenarios'!M24 -> 5336.3817 | N9: ='Growth Scenarios'!N24 -> 5747.495 | O9: ='Growth Scenarios'!O24 -> 6190.2026 | P9: ='Growth Scenarios'!P24 -> 6666.9256 | Q9: ='Growth Scenarios'!Q24 -> 7180.27 | S9: ='Growth Scenarios'!M54 -> 5485.9713 | T9: ='Growth Scenarios'!N54 -> 6035.4972 | U9: ='Growth Scenarios'!O54 -> 6639.8551 | V9: ='Growth Scenarios'!P54 -> 7304.4906 | W9: ='Growth Scenarios'!Q54 -> 8035.3869 | Y9: ='Growth Scenarios'!M84 -> 5186.792 | Z9: ='Growth Scenarios'!N84 -> 5395.1314 | AA9: ='Growth Scenarios'!O84 -> 5611.6371 | AB9: ='Growth Scenarios'!P84 -> 5836.6169 | AC9: ='Growth Scenarios'!Q84 -> 6070.3894
A10: Depreciation | B10: ='Income Statement'!B43 -> 303.6 | C10: ='Income Statement'!C43 -> 335 | D10: ='Income Statement'!D43 -> 323.7 | E10: ='Income Statement'!E43 -> 335 | F10: ='Income Statement'!F43 -> 373 | G10: ='Income Statement'!G43 -> 438 | H10: ='Income Statement'!H43 -> 518 | I10: ='Income Statement'!I43 -> 606 | ... K10: ='Income Statement'!K43 -> 706 | M10: ='Growth Scenarios'!M23*-1 -> 757.57585 | N10: ='Growth Scenarios'!N23*-1 -> 824.14156 | O10: ='Growth Scenarios'!O23*-1 -> 896.55617 | P10: ='Growth Scenarios'!P23*-1 -> 975.33361 | Q10: ='Growth Scenarios'!Q23*-1 -> 1061.033 | S10: ='Growth Scenarios'!M53*-1 -> 778.46745 | T10: ='Growth Scenarios'!N53*-1 -> 870.22285 | U10: ='Growth Scenarios'!O53*-1 -> 972.79316 | V10: ='Growth Scenarios'!P53*-1 -> 1087.4531 | W10: ='Growth Scenarios'!Q53*-1 -> 1215.6276 | Y10: ='Growth Scenarios'!M83*-1 -> 736.68425 | Z10: ='Growth Scenarios'!N83*-1 -> 779.31375 | AA10: ='Growth Scenarios'!O83*-1 -> 824.41008 | AB10: ='Growth Scenarios'!P83*-1 -> 872.11598 | AC10: ='Growth Scenarios'!Q83*-1 -> 922.58247
A11: CAPEX | B11: ='Income Statement'!B46 -> -449.2 | C11: ='Income Statement'!C46 -> -455.7 | D11: ='Income Statement'!D46 -> -335.1 | E11: ='Income Statement'!E46 -> -432 | F11: ='Income Statement'!F46 -> -597 | G11: ='Income Statement'!G46 -> -598 | H11: ='Income Statement'!H46 -> -880 | I11: ='Income Statement'!I46 -> -963 | ... K11: ='Income Statement'!K46 -> -1105 | M11: ='Growth Scenarios'!M32 -> -1108.0762 | N11: ='Growth Scenarios'!N32 -> -1205.4392 | O11: ='Growth Scenarios'!O32 -> -1311.3572 | P11: ='Growth Scenarios'!P32 -> -1426.5818 | Q11: ='Growth Scenarios'!Q32 -> -1551.9309 | S11: ='Growth Scenarios'!M62 -> -1248.6378 | T11: ='Growth Scenarios'!N62 -> -1395.8106 | U11: ='Growth Scenarios'!O62 -> -1560.3302 | V11: ='Growth Scenarios'!P62 -> -1744.2412 | W11: ='Growth Scenarios'!Q62 -> -1949.8292 | Y11: ='Growth Scenarios'!M92 -> -967.51458 | Z11: ='Growth Scenarios'!N92 -> -1023.5015 | AA11: ='Growth Scenarios'!O92 -> -1082.7281 | AB11: ='Growth Scenarios'!P92 -> -1145.3821 | AC11: ='Growth Scenarios'!Q92 -> -1211.6616
A12: Change in Net Working Capital | C12: =('Balance Sheet'!C10+'Balance Sheet'!C11-'Balance Sheet'!C25)-('Balance Sheet'!B10+'Balance Sheet'!B11-'Balance Sheet'!B25) -> 262.9 | D12: =('Balance Sheet'!D10+'Balance Sheet'!D11-'Balance Sheet'!D25)-('Balance Sheet'!C10+'Balance Sheet'!C11-'Balance Sheet'!C25) -> -772.9 | E12: =('Balance Sheet'!E10+'Balance Sheet'!E11-'Balance Sheet'!E25)-('Balance Sheet'!D10+'Balance Sheet'!D11-'Balance Sheet'!D25) -> 947.9 | F12: =('Balance Sheet'!F10+'Balance Sheet'!F11-'Balance Sheet'!F25)-('Balance Sheet'!E10+'Balance Sheet'!E11-'Balance Sheet'!E25) -> 658 | G12: =('Balance Sheet'!G10+'Balance Sheet'!G11-'Balance Sheet'!G25)-('Balance Sheet'!F10+'Balance Sheet'!F11-'Balance Sheet'!F25) -> -87 | H12: =('Balance Sheet'!H10+'Balance Sheet'!H11-'Balance Sheet'!H25)-('Balance Sheet'!G10+'Balance Sheet'!G11-'Balance Sheet'!G25) -> 496 | I12: =('Balance Sheet'!I10+'Balance Sheet'!I11-'Balance Sheet'!I25)-('Balance Sheet'!H10+'Balance Sheet'!H11-'Balance Sheet'!H25) -> 113 | J12: =('Balance Sheet'!J10+'Balance Sheet'!J11-'Balance Sheet'!J25)-('Balance Sheet'!I10+'Balance Sheet'!I11-'Balance Sheet'!I25) -> 324 | K12: =('Balance Sheet'!K10+'Balance Sheet'!K11-'Balance Sheet'!K25)-('Balance Sheet'!J10+'Balance Sheet'!J11-'Balance Sheet'!J25) -> 796 | M12: ='Growth Scenarios'!M29 -> 392.8619 | N12: ='Growth Scenarios'!N29 -> 417.13309 | O12: ='Growth Scenarios'!O29 -> 442.90376 | P12: ='Growth Scenarios'!P29 -> 470.26655 | Q12: ='Growth Scenarios'!Q29 -> 499.31983 | S12: ='Growth Scenarios'!M59 -> 583.6319 | T12: ='Growth Scenarios'!N59 -> 637.1979 | U12: ='Growth Scenarios'!O59 -> 695.68021 | V12: ='Growth Scenarios'!P59 -> 759.53006 | W12: ='Growth Scenarios'!Q59 -> 829.24007 | Y12: ='Growth Scenarios'!M89 -> 202.0919 | Z12: ='Growth Scenarios'!N89 -> 208.51447 | AA12: ='Growth Scenarios'!O89 -> 215.14116 | AB12: ='Growth Scenarios'!P89 -> 221.97844 | AC12: ='Growth Scenarios'!Q89 -> 229.03301
A13: Change in Net Working Capital (short-term debt adjusted) | C13: =C12-'Balance Sheet'!C24 -> -80 | D13: =D12-'Balance Sheet'!D24 -> -911.5 | E13: =E12-'Balance Sheet'!E24 -> 760.9 | F13: =F12-'Balance Sheet'!F24 -> 550 | G13: =G12-'Balance Sheet'!G24 -> -208 | H13: =H12-'Balance Sheet'!H24 -> 329 | I13: =I12-'Balance Sheet'!I24 -> 39 | J13: =J12-'Balance Sheet'!J24 -> 323 | K13: =K12-'Balance Sheet'!K24 -> 471 | M13: =M12-'Growth Scenarios'!M36 -> 242.70079 | N13: =N12-'Growth Scenarios'!N36 -> 266.97197 | O13: =O12-'Growth Scenarios'!O36 -> 292.74265 | P13: =P12-'Growth Scenarios'!P36 -> 320.10544 | Q13: =Q12-'Growth Scenarios'!Q36 -> 349.15872 | S13: =S12-'Growth Scenarios'!M66 -> 433.47079 | T13: =T12-'Growth Scenarios'!N66 -> 487.03679 | U13: =U12-'Growth Scenarios'!O66 -> 545.5191 | V13: =V12-'Growth Scenarios'!P66 -> 609.36895 | W13: =W12-'Growth Scenarios'!Q66 -> 679.07896 | Y13: =Y12-'Growth Scenarios'!M96 -> 51.930789 | Z13: =Z12-'Growth Scenarios'!N96 -> 58.353361 | AA13: =AA12-'Growth Scenarios'!O96 -> 64.980045 | AB13: =AB12-'Growth Scenarios'!P96 -> 71.817329 | AC13: =AC12-'Growth Scenarios'!Q96 -> 78.871904
A15: Free Cash Flow (short-term debt adjusted) | C15: =(1-C8)*C9+C8*C10-C11-C13 -> 1950.6961 | D15: =(1-D8)*D9+D8*D10-D11-D13 -> 3094.6293 | E15: =(1-E8)*E9+E8*E10-E11-E13 -> 1759.5471 | F15: =(1-F8)*F9+F8*F10-F11-F13 -> 2307.3638 | G15: =(1-G8)*G9+G8*G10-G11-G13 -> 3231.4091 | H15: =(1-H8)*H9+H8*H10-H11-H13 -> 3302.1971 | I15: =(1-I8)*I9+I8*I10-I11-I13 -> 4051.086 | J15: =(1-J8)*J9+J8*J10-J11-J13 -> 4195.0725 | K15: =(1-K8)*K9+K8*K10-K11-K13 -> 4204.9804 | M15: =(1-M8)*M9+M8*M10-M11-M13 -> 4867.6183 | N15: =(1-N8)*N9+N8*N10-N11-N13 -> 5251.4318 | O15: =(1-O8)*O9+O8*O10-O11-O13 -> 5666.3935 | P15: =(1-P8)*P9+P8*P10-P11-P13 -> 6115.0279 | Q15: =(1-Q8)*Q9+Q8*Q10-Q11-Q13 -> 6600.064 | S15: =(1-S8)*S9+S8*S10-S11-S13 -> 4929.5005 | T15: =(1-T8)*T9+T8*T10-T11-T13 -> 5439.2514 | U15: =(1-U8)*U9+U8*U10-U11-U13 -> 6003.4395 | V15: =(1-V8)*V9+V8*V10-V11-V13 -> 6627.8883 | W15: =(1-W8)*W9+W8*W10-W11-W13 -> 7319.0459 | Y15: =(1-Y8)*Y9+Y8*Y10-Y11-Y13 -> 4805.7362 | Z15: =(1-Z8)*Z9+Z8*Z10-Z11-Z13 -> 5015.3565 | AA15: =(1-AA8)*AA9+AA8*AA10-AA11-AA13 -> 5234.5182 | AB15: =(1-AB8)*AB9+AB8*AB10-AB11-AB13 -> 5463.6619 | AC15: =(1-AC8)*AC9+AC8*AC10-AC11-AC13 -> 5703.249
A16: Source: own calculation
D21: =M6 -> FY 2018E | E21: =N6 -> FY 2019E | F21: =O6 -> FY 2020E | G21: =P6 -> FY 2021E | H21: =Q6 -> FY 2022E
A22: =$A$15 -> Free Cash Flow (short-term debt adjusted) | C22: ='Table of Contents'!J1 -> Scenario 1: Base Case | D22: =M15 -> 4867.6183 | E22: =N15 -> 5251.4318 | F22: =O15 -> 5666.3935 | G22: =P15 -> 6115.0279 | H22: =Q15 -> 6600.064
A23: =$A$15 -> Free Cash Flow (short-term debt adjusted) | C23: ='Table of Contents'!J2 -> Scenario 2: Bull Case | D23: =S15 -> 4929.5005 | E23: =T15 -> 5439.2514 | F23: =U15 -> 6003.4395 | G23: =V15 -> 6627.8883 | H23: =W15 -> 7319.0459
A24: =$A$15 -> Free Cash Flow (short-term debt adjusted) | C24: ='Table of Contents'!J3 -> Scenario 3: Bear Case | D24: =Y15 -> 4805.7362 | E24: =Z15 -> 5015.3565 | F24: =AA15 -> 5234.5182 | G24: =AB15 -> 5463.6619 | H24: =AC15 -> 5703.249

Sheet Beta Calculation
A2: NIKE Inc (NKE US) - Beta Calculation
A4: Monthly data for 5 and 10 years | G4: Daily data for 1 year
A6: Date | B6: S&P500 | C6: rm | D6: Nike Equity | E6: rNike Inc | G6: Date | H6: S&P500 | I6: rm | J6: Nike Equity | K6: rNike Inc
A7: 36830 | B7: 1429.4 | D7: 4.9922 | G7: 42648 | H7: 2159.73 | J7: 54.7305 | M7: Time horizon: 1 year
A8: 36860 | B8: 1314.95 | C8: =(B8-B7)/B7 -> -0.08006856 | D8: 5.3281 | E8: =(D8-D7)/D7 -> 0.067284965 | G8: 42649 | H8: 2160.77 | I8: =(H8-H7)/H7 -> 0.00048154167 | J8: 54.636 | K8: =(J8-J7)/J7 -> -0.0017266424
A9: 36889 | B9: 1320.28 | C9: =(B9-B8)/B8 -> 0.0040533861 | D9: 6.9916 | E9: =(D9-D8)/D8 -> 0.31221261 | G9: 42650 | H9: 2153.74 | I9: =(H9-H8)/H8 -> -0.0032534698 | J9: 54.384 | K9: =(J9-J8)/J8 -> -0.0046123435 | M9: β1year = | N9: =N27 -> 0.85865303 | P9: Calculatory test: | Q9: =_xlfn.COVARIANCE.S(K8:K258,I8:I258)/_xlfn.VAR.S(I8:I258) -> 0.85865303
A10: 36922 | B10: 1366.01 | C10: =(B10-B9)/B9 -> 0.034636592 | D10: 6.8923 | E10: =(D10-D9)/D9 -> -0.014202758 | G10: 42653 | H10: 2163.66 | I10: =(H10-H9)/H9 -> 0.0046059413 | J10: 54.384 | K10: =(J10-J9)/J9 -> 0
A11: 36950 | B11: 1239.94 | C11: =(B11-B10)/B10 -> -0.092290686 | D11: 4.8917 | E11: =(D11-D10)/D10 -> -0.29026595 | G11: 42654 | H11: 2136.73 | I11: =(H11-H10)/H10 -> -0.012446503 | J11: 54.4155 | K11: =(J11-J10)/J10 -> 0.00057921447 | M11: SUMMARY OUTPUT
A12: 36980 | B12: 1160.33 | C12: =(B12-B11)/B11 -> -0.06420472 | D12: 5.0947 | E12: =(D12-D11)/D11 -> 0.041498865 | G12: 42655 | H12: 2139.18 | I12: =(H12-H11)/H11 -> 0.0011466119 | J12: 55.0665 | K12: =(J12-J11)/J11 -> 0.011963503 | M12: Regression Statistics
A13: 37011 | B13: 1249.46 | C13: =(B13-B12)/B12 -> 0.076814355 | D13: 5.253 | E13: =(D13-D12)/D12 -> 0.031071506 | G13: 42656 | H13: 2132.55 | I13: =(H13-H12)/H12 -> -0.0030993184 | J13: 54.636 | K13: =(J13-J12)/J12 -> -0.0078178203 | M13: Multiple R | N13: 0.29192602
A14: 37042 | B14: 1255.82 | C14: =(B14-B13)/B13 -> 0.005090199 | D14: 5.1638 | E14: =(D14-D13)/D13 -> -0.016980773 | G14: 42657 | H14: 2132.98 | I14: =(H14-H13)/H13 -> 0.00020163654 | J14: 54.2054 | K14: =(J14-J13)/J13 -> -0.0078812505 | M14: R Square | N14: 0.085220799
A15: 37071 | B15: 1224.42 | C15: =(B15-B14)/B14 -> -0.025003583 | D15: 5.2907 | E15: =(D15-D14)/D14 -> 0.024574925 | G15: 42660 | H15: 2126.5 | I15: =(H15-H14)/H14 -> -0.0030380032 | J15: 53.5859 | K15: =(J15-J14)/J14 -> -0.011428751 | M15: Adjusted R Square | N15: 0.081546987
A16: 37103 | B16: 1211.23 | C16: =(B16-B15)/B15 -> -0.010772447 | D16: 5.9912 | E16: =(D16-D15)/D15 -> 0.13240214 | G16: 42661 | H16: 2139.6 | I16: =(H16-H15)/H15 -> 0.0061603574 | J16: 53.7854 | K16: =(J16-J15)/J15 -> 0.0037229943 | M16: Standard Error | N16: 0.013149599
A17: 37134 | B17: 1133.58 | C17: =(B17-B16)/B16 -> -0.064108386 | D17: 6.2999 | E17: =(D17-D16)/D16 -> 0.051525571 | G17: 42662 | H17: 2144.29 | I17: =(H17-H16)/H16 -> 0.0021919985 | J17: 54.3945 | K17: =(J17-J16)/J16 -> 0.011324635 | M17: Observations | N17: 251
A18: 37162 | B18: 1040.94 | C18: =(B18-B17)/B17 -> -0.08172339 | D18: 5.9131 | E18: =(D18-D17)/D17 -> -0.0613978 | G18: 42663 | H18: 2141.34 | I18: =(H18-H17)/H17 -> -0.0013757468 | J18: 54.489 | K18: =(J18-J17)/J17 -> 0.001737308
A19: 37195 | B19: 1059.78 | C19: =(B19-B18)/B18 -> 0.018099026 | D19: 6.2352 | E19: =(D19-D18)/D18 -> 0.054472273 | G19: 42664 | H19: 2141.16 | I19: =(H19-H18)/H18 -> -8.4059514e-05 | J19: 54.3629 | K19: =(J19-J18)/J18 -> -0.0023142286 | M19: ANOVA
A20: 37225 | B20: 1139.45 | C20: =(B20-B19)/B19 -> 0.07517598 | D20: 6.6938 | E20: =(D20-D19)/D19 -> 0.073550167 | G20: 42667 | H20: 2151.33 | I20: =(H20-H19)/H19 -> 0.0047497618 | J20: 54.468 | K20: =(J20-J19)/J19 -> 0.0019333038 | N20: df | P20: SS | Q20: MS | R20: F | S20: Significance F
A21: 37256 | B21: 1148.08 | C21: =(B21-B20)/B20 -> 0.0075738295 | D21: 7.1195 | E21: =(D21-D20)/D20 -> 0.063596164 | G21: 42668 | H21: 2143.16 | I21: =(H21-H20)/H20 -> -0.0037976508 | J21: 53.6069 | K21: =(J21-J20)/J20 -> -0.015809283 | M21: Regression | N21: 1 | P21: 0.0040110093 | Q21: 0.0040110093 | R21: 23.196831 | S21: 2.5414649e-06
A22: 37287 | B22: 1130.2 | C22: =(B22-B21)/B21 -> -0.015573828 | D22: 7.5841 | E22: =(D22-D21)/D21 -> 0.065257392 | G22: 42669 | H22: 2139.43 | I22: =(H22-H21)/H21 -> -0.0017404207 | J22: 54.573 | K22: =(J22-J21)/J21 -> 0.018021934 | M22: Residual | N22: 249 | P22: 0.043055075 | Q22: 0.00017291195
A23: 37315 | B23: 1106.73 | C23: =(B23-B22)/B22 -> -0.020766236 | D23: 7.4511 | E23: =(D23-D22)/D22 -> -0.017536689 | G23: 42670 | H23: 2133.04 | I23: =(H23-H22)/H22 -> -0.0029867769 | J23: 54.489 | K23: =(J23-J22)/J22 -> -0.0015392227 | M23: Total | N23: 250 | P23: 0.047066085
A24: 37343 | B24: 1147.39 | C24: =(B24-B23)/B23 -> 0.036738861 | D24: 7.6119 | E24: =(D24-D23)/D23 -> 0.021580706 | G24: 42671 | H24: 2126.41 | I24: =(H24-H23)/H23 -> -0.0031082399 | J24: 54.6255 | K24: =(J24-J23)/J23 -> 0.0025050928
A25: 37376 | B25: 1076.92 | C25: =(B25-B24)/B24 -> -0.061417652 | D25: 6.7646 | E25: =(D25-D24)/D24 -> -0.11131255 | G25: 42674 | H25: 2126.15 | I25: =(H25-H24)/H24 -> -0.00012227181 | J25: 52.6933 | K25: =(J25-J24)/J24 -> -0.035371759 | N25: Coefficients | P25: Standard Error | Q25: t Stat | R25: P-value | S25: Lower 95% | T25: Upper 95% | U25: Lower 95,0% | V25: Upper 95,0%
A26: 37407 | B26: 1067.14 | C26: =(B26-B25)/B25 -> -0.0090814545 | D26: 6.8179 | E26: =(D26-D25)/D25 -> 0.0078792538 | G26: 42675 | H26: 2111.72 | I26: =(H26-H25)/H25 -> -0.0067869153 | J26: 52.1053 | K26: =(J26-J25)/J25 -> -0.011158914 | M26: Intercept | N26: -0.00041776472 | P26: 0.00083813562 | Q26: -0.49844526 | R26: 0.61861024 | S26: -0.0020685037 | T26: 0.0012329743 | U26: -0.0020685037 | V26: 0.0012329743
A27: 37435 | B27: 989.81 | C27: =(B27-B26)/B26 -> -0.072464719 | D27: 6.8204 | E27: =(D27-D26)/D26 -> 0.00036668182 | G27: 42676 | H27: 2097.94 | I27: =(H27-H26)/H26 -> -0.0065254863 | J27: 52.2103 | K27: =(J27-J26)/J26 -> 0.0020151501 | M27: X Variable 1 | N27: 0.85865303 | P27: 0.17828031 | Q27: 4.8163089 | R27: 2.5414649e-06 | S27: 0.50752339 | T27: 1.2097827 | U27: 0.50752339 | V27: 1.2097827
A28: 37468 | B28: 911.62 | C28: =(B28-B27)/B27 -> -0.078994959 | D28: 6.2661 | E28: =(D28-D27)/D27 -> -0.081270893 | G28: 42677 | H28: 2088.66 | I28: =(H28-H27)/H27 -> -0.0044233868 | J28: 52.2208 | K28: =(J28-J27)/J27 -> 0.00020110974
A29: 37498 | B29: 916.07 | C29: =(B29-B28)/B28 -> 0.0048814199 | D29: 5.4894 | E29: =(D29-D28)/D28 -> -0.1239527 | G29: 42678 | H29: 2085.18 | I29: =(H29-H28)/H28 -> -0.00166614 | J29: 52.4623 | K29: =(J29-J28)/J28 -> 0.004624594
A30: 37529 | B30: 815.28 | C30: =(B30-B29)/B29 -> -0.11002434 | D30: 5.5046 | E30: =(D30-D29)/D29 -> 0.0027689729 | G30: 42681 | H30: 2131.52 | I30: =(H30-H29)/H29 -> 0.022223501 | J30: 53.4599 | K30: =(J30-J29)/J29 -> 0.01901556 | M30: Time horizon: 5 years
A31: 37560 | B31: 885.76 | C31: =(B31-B30)/B30 -> 0.086448827 | D31: 6.0158 | E31: =(D31-D30)/D30 -> 0.092867783 | G31: 42682 | H31: 2139.56 | I31: =(H31-H30)/H30 -> 0.0037719562 | J31: 53.6384 | K31: =(J31-J30)/J30 -> 0.0033389513
A32: 37589 | B32: 936.31 | C32: =(B32-B31)/B31 -> 0.057069635 | D32: 5.7086 | E32: =(D32-D31)/D31 -> -0.051065527 | G32: 42683 | H32: 2163.26 | I32: =(H32-H31)/H31 -> 0.011077044 | J32: 53.6804 | K32: =(J32-J31)/J31 -> 0.00078302112 | M32: β5years = | N32: =N50 -> 0.61417323 | P32: Calculatory test: | Q32: =_xlfn.COVARIANCE.S(E151:E210,C151:C210)/_xlfn.VAR.S(C151:C210) -> 0.61417323
A33: 37621 | B33: 879.82 | C33: =(B33-B32)/B32 -> -0.060332582 | D33: 5.6869 | E33: =(D33-D32)/D32 -> -0.0038012823 | G33: 42684 | H33: 2167.48 | I33: =(H33-H32)/H32 -> 0.0019507595 | J33: 52.9138 | K33: =(J33-J32)/J32 -> -0.014280818
A34: 37652 | B34: 855.7 | C34: =(B34-B33)/B33 -> -0.027414698 | D34: 5.6959 | E34: =(D34-D33)/D33 -> 0.0015825845 | G34: 42685 | H34: 2164.45 | I34: =(H34-H33)/H33 -> -0.0013979368 | J34: 53.3129 | K34: =(J34-J33)/J33 -> 0.0075424558 | M34: SUMMARY OUTPUT
A35: 37680 | B35: 841.15 | C35: =(B35-B34)/B34 -> -0.017003623 | D35: 5.9299 | E35: =(D35-D34)/D34 -> 0.041082182 | G35: 42688 | H35: 2164.2 | I35: =(H35-H34)/H34 -> -0.00011550278 | J35: 52.7248 | K35: =(J35-J34)/J34 -> -0.011031101 | M35: Regression Statistics
A36: 37711 | B36: 848.18 | C36: =(B36-B35)/B35 -> 0.0083576057 | D36: 6.5936 | E36: =(D36-D35)/D35 -> 0.11192432 | G36: 42689 | H36: 2180.39 | I36: =(H36-H35)/H35 -> 0.0074808243 | J36: 52.6408 | K36: =(J36-J35)/J35 -> -0.0015931782 | M36: Multiple R | N36: 0.31316928
A37: 37741 | B37: 916.92 | C37: =(B37-B36)/B36 -> 0.081044118 | D37: 6.8642 | E37: =(D37-D36)/D36 -> 0.041039796 | G37: 42690 | H37: 2176.94 | I37: =(H37-H36)/H36 -> -0.0015822857 | J37: 53.2184 | K37: =(J37-J36)/J36 -> 0.010972478 | M37: R Square | N37: 0.098074996
A38: 37771 | B38: 963.59 | C38: =(B38-B37)/B37 -> 0.050898661 | D38: 7.1796 | E38: =(D38-D37)/D37 -> 0.045948545 | G38: 42691 | H38: 2187.12 | I38: =(H38-H37)/H37 -> 0.0046762887 | J38: 54.1739 | K38: =(J38-J37)/J37 -> 0.017954317 | M38: Adjusted R Square | N38: 0.082524565
A39: 37802 | B39: 974.5 | C39: =(B39-B38)/B38 -> 0.011322243 | D39: 6.877 | E39: =(D39-D38)/D38 -> -0.042147195 | G39: 42692 | H39: 2181.9 | I39: =(H39-H38)/H38 -> -0.0023867003 | J39: 53.6594 | K39: =(J39-J38)/J38 -> -0.0094971933 | M39: Standard Error | N39: 0.051618379
A40: 37833 | B40: 990.31 | C40: =(B40-B39)/B39 -> 0.016223704 | D40: 6.652 | E40: =(D40-D39)/D39 -> -0.032717755 | G40: 42695 | H40: 2198.18 | I40: =(H40-H39)/H39 -> 0.0074613869 | J40: 53.8484 | K40: =(J40-J39)/J39 -> 0.0035222161 | M40: Observations | N40: 60
A41: 37862 | B41: 1008.01 | C41: =(B41-B40)/B40 -> 0.017873191 | D41: 7.3257 | E41: =(D41-D40)/D40 -> 0.10127781 | G41: 42696 | H41: 2202.94 | I41: =(H41-H40)/H40 -> 0.0021654278 | J41: 54.2999 | K41: =(J41-J40)/J40 -> 0.0083846502
A42: 37894 | B42: 995.97 | C42: =(B42-B41)/B41 -> -0.011944326 | D42: 7.8374 | E42: =(D42-D41)/D41 -> 0.06984998 | G42: 42697 | H42: 2204.72 | I42: =(H42-H41)/H41 -> 0.00080801111 | J42: 53.9114 | K42: =(J42-J41)/J41 -> -0.0071547093 | M42: ANOVA
A43: 37925 | B43: 1050.71 | C43: =(B43-B42)/B42 -> 0.054961495 | D43: 8.2343 | E43: =(D43-D42)/D42 -> 0.050641794 | G43: 42699 | H43: 2213.35 | I43: =(H43-H42)/H42 -> 0.0039143293 | J43: 54.1004 | K43: =(J43-J42)/J42 -> 0.003505752 | N43: df | P43: SS | Q43: MS | R43: F | S43: Significance F
...

Sheet Cost of Equity
A2: NIKE Inc (NKE US) - Cost of Equity
A4: Monthly data for 5 and 10 years
A6: Date | B6: S&P500 prices | C6: rm | D6: rf | E6: (rm - rf) | G6: Market Risk Premia | J6: Risk-free rate | M6: Cost of Equity
A7: 36830 | B7: 1429.4 | D7: 0.0056
A8: 36860 | B8: 1314.95 | C8: =(B8-B7)/B7 -> -0.08006856 | D8: 0.0051 | E8: =C8-D8 -> -0.08516856 | G8: Monthly MRP1year | H8: =AVERAGE(E199:E210) -> 0.012235197 | J8: Monthly rf 1year | K8: =AVERAGE(D199:D210) -> 0.00045833333 | M8: Average rE 1year | N8: =K12+'Beta Calculation'!N9*H12 -> 0.14042273
A9: 36889 | B9: 1320.28 | C9: =(B9-B8)/B8 -> 0.0040533861 | D9: 0.005 | E9: =C9-D9 -> -0.00094661394 | G9: Monthly MRP5years | H9: =AVERAGE(E151:E210) -> 0.0096034982 | J9: Monthly rf 5years | K9: =AVERAGE(D151:D210) -> 0.00012333333 | M9: Average rE 5years | N9: =K13+'Beta Calculation'!N32*H13 -> 0.076120312
A10: 36922 | B10: 1366.01 | C10: =(B10-B9)/B9 -> 0.034636592 | D10: 0.0054 | E10: =C10-D10 -> 0.029236592 | G10: Monthly MRP10years | H10: =AVERAGE(E91:E210) -> 0.0048574236 | J10: Monthly rf 10years | K10: =AVERAGE(D91:D210) -> 0.0002925 | M10: Average rE 10years | N10: =K14+'Beta Calculation'!N55*H14 -> 0.051533817
A11: 36950 | B11: 1239.94 | C11: =(B11-B10)/B10 -> -0.092290686 | D11: 0.0038 | E11: =C11-D11 -> -0.096090686
A12: 36980 | B12: 1160.33 | C12: =(B12-B11)/B11 -> -0.06420472 | D12: 0.0042 | E12: =C12-D12 -> -0.06840472 | G12: Yearly MRP1year | H12: =(1+H8)^12-1 -> 0.15711683 | J12: Yearly rf 1year | K12: =(1+K8)^12-1 -> 0.0055138858 | M12: Cost of Equity | N12: =0.4*N8+0.4*N9+0.2*N10 -> 0.09692398
A13: 37011 | B13: 1249.46 | C13: =(B13-B12)/B12 -> 0.076814355 | D13: 0.0039 | E13: =C13-D13 -> 0.072914355 | G13: Yearly MRP5years | H13: =(1+H9)^12-1 -> 0.1215281 | J13: Yearly rf 5years | K13: =(1+K9)^12-1 -> 0.0014810043
A14: 37042 | B14: 1255.82 | C14: =(B14-B13)/B13 -> 0.005090199 | D14: 0.0032 | E14: =C14-D14 -> 0.001890199 | G14: Yearly MRP10years | H14: =(1+H10)^12-1 -> 0.059871816 | J14: Yearly rf 10years | K14: =(1+K10)^12-1 -> 0.0035156522
A15: 37071 | B15: 1224.42 | C15: =(B15-B14)/B14 -> -0.025003583 | D15: 0.0028 | E15: =C15-D15 -> -0.027803583
A16: 37103 | B16: 1211.23 | C16: =(B16-B15)/B15 -> -0.010772447 | D16: 0.003 | E16: =C16-D16 -> -0.013772447
A17: 37134 | B17: 1133.58 | C17: =(B17-B16)/B16 -> -0.064108386 | D17: 0.0031 | E17: =C17-D17 -> -0.067208386
A18: 37162 | B18: 1040.94 | C18: =(B18-B17)/B17 -> -0.08172339 | D18: 0.0028 | E18: =C18-D18 -> -0.08452339
A19: 37195 | B19: 1059.78 | C19: =(B19-B18)/B18 -> 0.018099026 | D19: 0.0022 | E19: =C19-D19 -> 0.015899026
A20: 37225 | B20: 1139.45 | C20: =(B20-B19)/B19 -> 0.07517598 | D20: 0.0017 | E20: =C20-D20 -> 0.07347598
A21: 37256 | B21: 1148.08 | C21: =(B21-B20)/B20 -> 0.0075738295 | D21: 0.0015 | E21: =C21-D21 -> 0.0060738295
A22: 37287 | B22: 1130.2 | C22: =(B22-B21)/B21 -> -0.015573828 | D22: 0.0014 | E22: =C22-D22 -> -0.016973828
A23: 37315 | B23: 1106.73 | C23: =(B23-B22)/B22 -> -0.020766236 | D23: 0.0013 | E23: =C23-D23 -> -0.022066236
A24: 37344 | B24: 1147.39 | C24: =(B24-B23)/B23 -> 0.036738861 | D24: 0.0013 | E24: =C24-D24 -> 0.035438861
A25: 37376 | B25: 1076.92 | C25: =(B25-B24)/B24 -> -0.061417652 | D25: 0.0015 | E25: =C25-D25 -> -0.062917652
A26: 37407 | B26: 1067.14 | C26: =(B26-B25)/B25 -> -0.0090814545 | D26: 0.0014 | E26: =C26-D26 -> -0.010481455
... A210: 43007 | B210: 2519.36 | C210: =(B210-B209)/B209 -> 0.019302895 | D210: 0.0007 | E210: =C210-D210 -> 0.018602895
A211: Sources: Bloomberg, Kenneth R. French - Data Library

Sheet Cost of Debt
A2: NIKE Inc (NKE US) - Cost of Debt
A4: Corporate Bonds
A6: Maturities | B6: Original Principal | C6: Interest Rate | D6: Interest Payment | E6: first Cupon Date | F6: Par Amount | G6: Course October 4, 2017 | H6: Price October 4, 2017 | I6: rD | K6: Number of Bonds issued | L6: Market Value of debt October 4, 2017 | M6: Book Value of debt May 31, 2017 | P6: Book/Market Value Ratio
A7: May 1, 2023 | B7: 500000000 | C7: 0.0225 | D7: Semi-Anually | E7: 41579 | F7: 1000 | G7: 0.99787 | H7: =G7*F7 -> 997.87 | I7: ='Corporate Bond 1'!B21 -> 0.023012846 | K7: 500000 | L7: =K7*H7 -> 498935000 | M7: 497000000 | P7: =M7/L7 -> 0.99612174
A8: November 1, 2026 | B8: 1000000000 | C8: 0.0238 | D8: Semi-Anually | E8: 42856 | F8: 1000 | G8: 0.95349 | H8: =G8*F8 -> 953.49 | I8: ='Corporate Bond 2'!B28 -> 0.029666212 | K8: 1000000 | L8: =K8*H8 -> 9.5349e+08 | M8: 993000000 | P8: =M8/L8 -> 1.0414372
A9: May 1, 2043 | B9: 500000000 | C9: 0.0363 | D9: Semi-Anually | E9: 41579 | F9: 1000 | G9: 0.97935 | H9: =G9*F9 -> 979.35 | I9: ='Corporate Bond 3'!B61 -> 0.037903478 | K9: 500000 | L9: =K9*H9 -> 489675000 | M9: 495000000 | P9: =M9/L9 -> 1.0108746
A10: November 1, 2045 | B10: 1000000000 | C10: 0.0388 | D10: Semi-Anually | E10: 42491 | F10: 1000 | G10: 1.01553 | H10: =G10*F10 -> 1015.53 | I10: ='Corporate Bond 4'!B66 -> 0.038263357 | K10: 1000000 | L10: =K10*H10 -> 1.01553e+09 | M10: 981000000 | P10: =M10/L10 -> 0.96599805
A11: November 1, 2046 | B11: 500000000 | C11: 0.0388 | D11: Semi-Anually | E11: 42856 | F11: 1000 | G11: 0.93485 | H11: =G11*F11 -> 934.85 | I11: ='Corporate Bond 5'!B68 -> 0.038280396 | K11: 500000 | L11: =K11*H11 -> 4.67425e+08 | M11: 490000000 | P11: =M11/L11 -> 1.0482965
K12: TOTAL | L12: =SUM(L7:L11) -> 3425055000 | M12: =SUM(M7:M11) -> 3456000000 | O12: weighted average | P12: =P7*(M7/M12)+P8*(M8/M12)+P9*(M9/M12)+P10*(M10/M12)+P11*(M11/M12) -> 1.0101018
A13: Japanese Yen Notes
A15: Maturities | B15: Original Principal | C15: Interest Rate | D15: Interest Payment | L15: Market Value of debt outstanding October 4, 2017 | M15: Book Value of debt outstanding May 31, 2017
A16: August 20, 2001 through November 20, 2020 | B16: 9000000000 | C16: 0.026 | D16: Quarterly | L16: =M16*P12 -> 14141426 | M16: 14000000
A17: August 20, 2001 through November 20, 2020 | B17: 4000000000 | C17: 0.02 | D17: Quarterly | L17: =M17*P12 -> 7070712.9 | M17: 7000000
K18: TOTAL | L18: =SUM(L16:L17) -> 21212139 | M18: =SUM(M16:M17) -> 21000000
A19: weighted rD | B19: =I7*(L7/SUM(L7:L11,L16:L17))+I8*(L8/SUM(L7:L11,L16:L17))+I9*(L9/SUM(L7:L11,L16:L17))+I10*(L10/SUM(L7:L11,L16:L17))+I11*(L11/SUM(L7:L11,L16:L17))+C16*(L16/SUM(L7:L11,L16:L17))+C17*(L17/SUM(L7:L11,L16:L17)) -> 0.033540241
A21: Capital Structure
A23: In Millions of USD | B23: FY 2008 | C23: FY 2009 | D23: FY 2010 | E23: FY 2011 | F23: FY 2012 | G23: FY 2013 | H23: FY 2014 | I23: FY 2015 | K23: FY 2016 | L23: FY 2017 | M23: FY 2018E | O23: FY 2019E | P23: FY 2020E | Q23: FY 2021E | R23: FY 2022E
A25: Short-term Debt | B25: ='Balance Sheet'!B23+'Balance Sheet'!B24 -> 184 | C25: ='Balance Sheet'!C23+'Balance Sheet'!C24 -> 374.9 | D25: ='Balance Sheet'!D23+'Balance Sheet'!D24 -> 146 | E25: ='Balance Sheet'!E23+'Balance Sheet'!E24 -> 387 | F25: ='Balance Sheet'!F23+'Balance Sheet'!F24 -> 157 | G25: ='Balance Sheet'!G23+'Balance Sheet'!G24 -> 178 | H25: ='Balance Sheet'!H23+'Balance Sheet'!H24 -> 174 | I25: ='Balance Sheet'!I23+'Balance Sheet'!I24 -> 181 | K25: ='Balance Sheet'!J23+'Balance Sheet'!J24 -> 45 | L25: ='Balance Sheet'!K23+'Balance Sheet'!K24 -> 331 | M25: =M27*M33 -> 2098.6878 | O25: =O27*O33 -> 2131.3816 | P25: =P27*P33 -> 2164.5848 | Q25: =Q27*Q33 -> 2198.3052
A26: Long-term Debt | B26: ='Balance Sheet'!B30 -> 441.1 | C26: ='Balance Sheet'!C30 -> 437.2 | D26: ='Balance Sheet'!D30 -> 445.8 | E26: ='Balance Sheet'!E30 -> 276 | F26: ='Balance Sheet'!F30 -> 228 | G26: ='Balance Sheet'!G30 -> 1210 | H26: ='Balance Sheet'!H30 -> 1199 | I26: ='Balance Sheet'!I30 -> 1079 | K26: ='Balance Sheet'!J30 -> 2010 | L26: ='Balance Sheet'!K30 -> 3471 | R26: =R27*R33 -> 2232.5509
A27: weight of Debt | B27: =(B25+B26)/B33 -> 0.018276866 | C27: =(C25+C26)/C33 -> 0.028484767 | D27: =(D25+D26)/D33 -> 0.016645643 | E27: =(E25+E26)/E33 -> 0.016498447 | F27: =(F25+F26)/F33 -> 0.0077105727 | G27: =(G25+G26)/G33 -> 0.024561138 | H27: =(H25+H26)/H33 -> 0.020106993 | I27: =(I25+I26)/I33 -> 0.014254814 | K27: =(K25+K26)/K33 -> 0.021646381 | L27: =(L25+L26)/L33 -> 0.041842492 | M27: =(AVERAGE(G27:L27)+AVERAGE(B27:L27))/2 -> 0.022742587 | O27: =$M$27 -> 0.022742587 | P27: =$M$27 -> 0.022742587 | Q27: =$M$27 -> 0.022742587 | R27: =$M$27 -> 0.022742587
A29: historical Market Cap | B29: 33576.507 | C29: 27697.775 | D29: 34960.948 | E29: 39522.6 | F29: 49546.44 | G29: 55124.04 | H29: 66911.7 | I29: 87131.19 | K29: 92880.04 | L29: 87062.57
A30: preferred Equity | B30: ='Balance Sheet'!B33 -> 0.1 | C30: ='Balance Sheet'!C33 -> 0.1 | D30: ='Balance Sheet'!D33 -> 0.1 | E30: ='Balance Sheet'!E33 -> 0 | F30: ='Balance Sheet'!F33 -> 0 | G30: ='Balance Sheet'!G33 -> 0 | H30: ='Balance Sheet'!H33 -> 0 | I30: ='Balance Sheet'!I33 -> 0 | K30: ='Balance Sheet'!J33 -> 0 | L30: ='Balance Sheet'!K33 -> 0
A31: weight of Equity | B31: =(B29+B30)/B33 -> 0.98172313 | C31: =(C29+C30)/C33 -> 0.97151523 | D31: =(D29+D30)/D33 -> 0.98335436 | E31: =(E29+E30)/E33 -> 0.98350155 | F31: =(F29+F30)/F33 -> 0.99228943 | G31: =(G29+G30)/G33 -> 0.97543886 | H31: =(H29+H30)/H33 -> 0.97989301 | I31: =(I29+I30)/I33 -> 0.98574519 | K31: =(K29+K30)/K33 -> 0.97835362 | L31: =(L29+L30)/L33 -> 0.95815751
A33: Total Capital | B33: =B25+B26+B29+B30 -> 34201.707 | C33: =C25+C26+C29+C30 -> 28509.975 | D33: =D25+D26+D29+D30 -> 35552.848 | E33: =E25+E26+E29+E30 -> 40185.6 | F33: =F25+F26+F29+F30 -> 49931.44 | G33: =G25+G26+G29+G30 -> 56512.04 | H33: =H25+H26+H29+H30 -> 68284.7 | I33: =I25+I26+I29+I30 -> 88391.19 | K33: =K25+K26+K29+K30 -> 94935.04 | L33: =L25+L26+L29+L30 -> 90864.57 | M33: =L33*(1+$M$34) -> 92280.079 | O33: =M33*(1+$M$34) -> 93717.639 | P33: =O33*(1+$M$34) -> 95177.594 | Q33: =P33*(1+$M$34) -> 96660.293 | R33: =Q33*(1+$M$34) -> 98166.089
A34: % Change | C34: =(C33-B33)/B33 -> -0.16641661 | D34: =(D33-C33)/C33 -> 0.24703189 | E34: =(E33-D33)/D33 -> 0.13030607 | F34: =(F33-E33)/E33 -> 0.2425207 | G34: =(G33-F33)/F33 -> 0.13179271 | H34: =(H33-G33)/G33 -> 0.20832127 | I34: =(I33-H33)/H33 -> 0.29445088 | K34: =(K33-I33)/I33 -> 0.074032831 | L34: =(L33-K33)/K33 -> -0.042876371 | M34: =AVERAGE(K34:L34) -> 0.01557823
A35: Source: Bloomberg
A37: as of 04.10.2017
A38: Market value of debt | B38: =L18+L12 -> 3.4462671e+09
A39: Price per share | B39: ='Share Prices'!F13 -> 52.08
A40: Weighted average common shares outstanding | B40: 1657800000
A41: Diluted w. average common shares outstanding | B41: 1692000000
A43: Market value of equity = Market Cap | B43: =B39*B40 -> 86338224000

Sheet WACC
A2: NIKE Inc (NKE US) - WACC Calculation
E4: Sensitivity Analysis: rA | O4: After-tax WACC
A5: Market Value of Debt: D | B5: ='Cost of Debt'!L12+'Cost of Debt'!L18 -> 3.4462671e+09 | O5: ='Table of Contents'!J1 -> Scenario 1: Base Case | P5: =B20 -> 0.09411596
A6: Market Value of Equity: E | B6: ='Cost of Debt'!B43 -> 86338224000 | G6: Cost of Debt (rD) | O6: ='Table of Contents'!J2 -> Scenario 2: Bull Case | P6: =B21 -> 0.079998566
A7: Total Market Value of Debt and Equity: V | B7: =B6+B5 -> 8.9784491e+10 | F7: =B14 -> 0.094491073 | G7: 0.028509205 | H7: 0.030186217 | I7: 0.031863229 | J7: 0.033540241 | K7: 0.035217253 | L7: 0.036894265 | M7: 0.038571277 | O7: ='Table of Contents'!J3 -> Scenario 3: Bear Case | P7: =B22 -> 0.10823335
A8: D / V | B8: =B5/B7 -> 0.038383769 | E8: Cost of Equity (rE) | F8: 0.082385383 | G8: 0.080317412 | H8: 0.080381782 | I8: 0.080446152 | J8: 0.080510523 | K8: 0.080574893 | L8: 0.080639263 | M8: 0.080703633
A9: E / V | B9: =B6/B7 -> 0.96161623 | F9: 0.087231582 | G9: 0.084977596 | H9: 0.085041966 | I9: 0.085106336 | J9: 0.085170706 | K9: 0.085235076 | L9: 0.085299446 | M9: 0.085363816 | O9: rA
F10: 0.092077781 | G10: 0.08963778 | H10: 0.08970215 | I10: 0.08976652 | J10: 0.08983089 | K10: 0.08989526 | L10: 0.08995963 | M10: 0.090024 | O10: ='Table of Contents'!J1 -> Scenario 1: Base Case | P10: =B14 -> 0.094491073
A11: Cost of Debt (rD) | B11: ='Cost of Debt'!B19 -> 0.033540241 | F11: 0.09692398 | G11: 0.094297963 | H11: 0.094362333 | I11: 0.094426703 | J11: 0.094491073 | K11: 0.094555443 | L11: 0.094619814 | M11: 0.094684184 | O11: ='Table of Contents'!J2 -> Scenario 2: Bull Case | P11: =B15 -> 0.080317412
A12: Cost of Equity (rE) | B12: ='Cost of Equity'!N12 -> 0.09692398 | F12: 0.10177018 | G12: 0.098958147 | H12: 0.099022517 | I12: 0.099086887 | J12: 0.099151257 | K12: 0.099215627 | L12: 0.099279997 | M12: 0.099344367 | O12: ='Table of Contents'!J3 -> Scenario 3: Bear Case | P12: =B16 -> 0.10866473
F13: 0.10661638 | G13: 0.10361833 | H13: 0.1036827 | I13: 0.10374707 | J13: 0.10381144 | K13: 0.10387581 | L13: 0.10394018 | M13: 0.10400455
A14: rA Base Case | B14: =B8*B11+B9*B12 -> 0.094491073 | F14: 0.11146258 | G14: 0.10827851 | H14: 0.10834288 | I14: 0.10840725 | J14: 0.10847162 | K14: 0.10853599 | L14: 0.10860036 | M14: 0.10866473
A15: rA Bull Case | B15: =MIN(G8:M14) -> 0.080317412 | G15: 0.85 | H15: 0.9 | I15: 0.95 | J15: 1 | K15: 1.05 | L15: 1.1 | M15: 1.15
A16: rA Bear Case | B16: =MAX(G8:M14) -> 0.10866473 | F16: 0.85
F17: 0.9
A18: Marginal tax rate | B18: ='Marginal Tax Rate'!K18 -> 0.29137263 | F18: 0.95
F19: 1
A20: After-tax-WACC Base Case | B20: =B9*B12+B8*B11*(1-B18) -> 0.09411596 | F20: 1.05
A21: After-tax-WACC Bull Case | B21: =B9*F8+B8*G7*(1-B18) -> 0.079998566 | F21: 1.1
A22: After-tax-WACC Bear Case | B22: =B9*F14+B8*M7*(1-B18) -> 0.10823335 | F22: 1.15
A23: Source: own calculations

Sheet DCF
A2: NIKE Inc (NKE US) - Discounted Cash Flows
A4: Projected Cash Flows | H4: Discounted Cash Flows
A6: Case selection for cash flow projection: | H6: Case selection for WACC:
A7: Scenario 1: Base Case | H7: Scenario 1: Base Case | J7: >> WACC: | K7: =INDEX(WACC!O5:P7,MATCH(DCF!H7,WACC!O5:O7,0),2) -> 0.09411596
A9: In Millions of USD | B9: FY 2018E | C9: FY 2019E | D9: FY 2020E | E9: FY 2021E | F9: FY 2022E | H9: In Millions of USD | I9: FY 2018E | J9: FY 2019E | K9: FY 2020E | L9: FY 2021E | M9: FY 2022E
A11: Free Cash Flow | B11: {=INDEX('Free Cash Flows'!$D$22:$H$24,MATCH(DCF!$A$7,'Free Cash Flows'!$C$22:$C$24,0),MATCH(DCF!B9,'Free Cash Flows'!$D$21:$H$21,0))} -> 4867.6183 | C11: {=INDEX('Free Cash Flows'!$D$22:$H$24,MATCH(DCF!$A$7,'Free Cash Flows'!$C$22:$C$24,0),MATCH(DCF!C9,'Free Cash Flows'!$D$21:$H$21,0))} -> 5251.4318 | D11: {=INDEX('Free Cash Flows'!$D$22:$H$24,MATCH(DCF!$A$7,'Free Cash Flows'!$C$22:$C$24,0),MATCH(DCF!D9,'Free Cash Flows'!$D$21:$H$21,0))} -> 5666.3935 | E11: {=INDEX('Free Cash Flows'!$D$22:$H$24,MATCH(DCF!$A$7,'Free Cash Flows'!$C$22:$C$24,0),MATCH(DCF!E9,'Free Cash Flows'!$D$21:$H$21,0))} -> 6115.0279 | F11: {=INDEX('Free Cash Flows'!$D$22:$H$24,MATCH(DCF!$A$7,'Free Cash Flows'!$C$22:$C$24,0),MATCH(DCF!F9,'Free Cash Flows'!$D$21:$H$21,0))} -> 6600.064 | H11: Present Value of Free Cash Flow | I11: =I14*B11 -> 4448.9053 | J11: =J14*C11 -> 4386.8322 | K11: =K14*D11 -> 4326.3004 | L11: =L14*E11 -> 4267.2199 | M11: =M14*F11 -> 4209.5084
H13: Discounting Period | I13: 1 | J13: =I13+1 -> 2 | K13: =J13+1 -> 3 | L13: =K13+1 -> 4 | M13: =L13+1 -> 5
A14: Present Value of Nike Inc. | H14: Discounting Factor | I14: =1/((1+$K$7)^I13) -> 0.9139799 | J14: =1/((1+$K$7)^J13) -> 0.83535926 | K14: =1/((1+$K$7)^K13) -> 0.76350158 | L14: =1/((1+$K$7)^L13) -> 0.6978251 | M14: =1/((1+$K$7)^M13) -> 0.63779812
A16: Free cash flow terminal year | B16: =DCF!F11 -> 6600.064
A17: Inflation rate (as of 09/2017) | B17: 0.022
A18: GDP growth rate (as of Q2/2017) | B18: 0.0384
A19: Perpetuity growth rate | B19: =0.25*B17+0.75*B18 -> 0.0343
A20: Terminal Value | B20: =B16*(1+B19)/(K7-B19) -> 114124.16
A21: Discount Factor | B21: =1/((1+DCF!K7)^DCF!M13) -> 0.63779812
A22: PV of Terminal Value | B22: =B20*B21 -> 72788.174
A24: Enterprise Value (EV) | B24: =B22+DCF!I11+DCF!J11+DCF!K11+DCF!L11+DCF!M11 -> 94426.94 | E24: =ROUND(((B26-'Share Prices'!F13)/'Share Prices'!F13),3) -> 0.094
A26: Share Price (in $) | B26: =B24/'Income Statement'!K45 -> 56.959187 | C26: =IF(B26>'Share Prices'!F13,CONCATENATE("undervalued by ",(E24*100),"%"),CONCATENATE("overvalued by ",((-1*E24)*100),"%")) -> undervalued by 9,4%
A27: Source: own calculations
A29: Remark: If both scenarios are adapted - for instance, to the Bull Case - the derived EV will strongly deviate from the Base Case calculation due to the fact that an optimistic cash flow projection and an optimistic WACC will raise the EV to a much higher power. These extreme cases are assumed to be very unrealistic. Therefore, it is recommended to only change one of the parameters at a time in order to realistically calculate the EV. | I29: 93827.415 | J29: 94426.94
J30: =(J29-I29)/J29 -> 0.0063490982
J32: =J29/I29 -> 1.0063897

Sheet Share Prices
A2: NIKE Inc (NKE US) - Share Prices
A4: Share Prices | E4: Share Prices | I4: Total Returns | M4: Total Returns
A5: Security | B5: NKE US Equity | E5: Security | F5: NKE US Equity | I5: Security | J5: NKE US Equity | M5: Security | N5: NKE US Equity
A6: Start Date | B6: 36830 | E6: Start Date | F6: 40452 | I6: Start Date | J6: 36830 | M6: Start Date | N6: 41183
A7: End Date | B7: 43007 | E7: End Date | F7: 43013 | I7: End Date | J7: 43007 | M7: End Date | N7: 43027
A8: Period | B8: Monthly | E8: Period | F8: Daily | I8: Period | J8: Monthly | M8: Period | N8: Daily
A9: Currency | B9: USD | E9: Currency | F9: USD | I9: Currency | J9: USD | M9: Currency | N9: USD
A10: Source: | B10: Bloomberg | E10: Source: | F10: Bloomberg | I10: Source: | J10: Bloomberg | M10: Source: | N10: Bloomberg
A12: Date | B12: PX_LAST | C12: PX_VOLUME | E12: Date | F12: PX_LAST | G12: PX_VOLUME | I12: Date | J12: TOT_RETURN_INDEX_GROSS_DVDS | K12: TOT_RETURN_INDEX_NET_DVDS | M12: Date | N12: TOT_RETURN_INDEX_GROSS_DVDS | O12: TOT_RETURN_INDEX_NET_DVDS
A13: 43007 | B13: 51.85 | C13: 212311860 | E13: 43012 | F13: 52.08 | G13: 8204280 | I13: 36830 | J13: 4.9922 | K13: 4.9922 | M13: 43026 | N13: 55.6657 | O13: 55.6657
A14: 42978 | B14: 52.81 | C14: 174951250 | E14: 43011 | F14: 51.47 | G14: 8126729 | I14: 36860 | J14: 5.3281 | K14: 5.3281 | M14: 43025 | N14: 55.3464 | O14: 55.3464
A15: 42947 | B15: 59.05 | C15: 158127101 | E15: 43010 | F15: 51.87 | G15: 7516205 | I15: 36889 | J15: 6.9916 | K15: 6.9916 | M15: 43024 | N15: 54.6758 | O15: 54.6758
A16: 42916 | B16: 59 | C16: 275425135 | E16: 43007 | F16: 51.85 | G16: 12189882 | I16: 36922 | J16: 6.8923 | K16: 6.8923 | M16: 43021 | N16: 54.2607 | O16: 54.2607
A17: 42886 | B17: 52.99 | C17: 223448944 | E17: 43006 | F17: 52.63 | G17: 11334704 | I17: 36950 | J17: 4.8917 | K17: 4.8917 | M17: 43020 | N17: 54.1011 | O17: 54.1011
A18: 42853 | B18: 55.41 | C18: 137922961 | E18: 43005 | F18: 52.67 | G18: 36202500 | I18: 36980 | J18: 5.0947 | K18: 5.0947 | M18: 43019 | N18: 54.3139 | O18: 54.3139
A19: 42825 | B19: 55.73 | C19: 249523050 | E19: 43004 | F19: 53.7 | G19: 16183717 | I19: 37011 | J19: 5.253 | K19: 5.253 | M19: 43018 | N19: 54.8461 | O19: 54.8461
A20: 42794 | B20: 57.16 | C20: 178369648 | E20: 43003 | F20: 53.23 | G20: 12262360 | I20: 37042 | J20: 5.1638 | K20: 5.1638 | M20: 43017 | N20: 54.8355 | O20: 54.8355
A21: 42766 | B21: 52.9 | C21: 175931076 | E21: 43000 | F21: 53.24 | G21: 10962392 | I21: 37071 | J21: 5.2907 | K21: 5.2907 | M21: 43014 | N21: 55.7934 | O21: 55.7934
A22: 42734 | B22: 50.83 | C22: 215471219 | E22: 42999 | F22: 53.19 | G22: 8065367 | I22: 37103 | J22: 5.9912 | K22: 5.9912 | M22: 43013 | N22: 55.5379 | O22: 55.5379
A23: 42704 | B23: 50.07 | C23: 166220023 | E23: 42998 | F23: 53.56 | G23: 7058002 | I23: 37134 | J23: 6.2999 | K23: 6.2999 | M23: 43012 | N23: 55.4315 | O23: 55.4315
A24: 42674 | B24: 50.18 | C24: 190327931 | E24: 42997 | F24: 53.33 | G24: 14707174 | I24: 37162 | J24: 5.9131 | K24: 5.9131 | M24: 43011 | N24: 54.7823 | O24: 54.7823
... A216: 36830 | B216: 4.9922 | C216: 181374400 | E216: 42717 | F216: 52.3 | G216: 11442327 | I216: 43007 | J216: 64.6032 | K216: 64.6032 | M216: 42732 | N216: 53.7658 | O216: 53.7658
E217: 42716 | F217: 51.54 | G217: 11459541 | M217: 42731 | N217: 54.0503 | O217: 54.0503
E218: 42713 | F218: 51.72 | G218: 5869828 | M218: 42727 | N218: 54.7037 | O218: 54.7037
E219: 42712 | F219: 51.55 | G219: 9260850 | M219: 42726 | N219: 54.9461 | O219: 54.9461
E220: 42711 | F220: 52.1 | G220: 10412638 | M220: 42725 | N220: 55.1147 | O220: 55.1147
E221: 42710 | F221: 50.57 | G221: 12496332 | M221: 42724 | N221: 54.5772 | O221: 54.5772
E222: 42709 | F222: 51.85 | G222: 12031170 | M222: 42723 | N222: 53.5866 | O222: 53.5866
E223: 42706 | F223: 50.46 | G223: 6933279 | M223: 42720 | N223: 53.6604 | O223: 53.6604
E224: 42705 | F224: 50.65 | G224: 7610063 | M224: 42719 | N224: 54.0503 | O224: 54.0503
E225: 42704 | F225: 50.07 | G225: 8198418 | M225: 42718 | N225: 54.5772 | O225: 54.5772
E226: 42703 | F226: 50.63 | G226: 6065682 | M226: 42717 | N226: 55.1147 | O226: 55.1147
E227: 42702 | F227: 51.01 | G227: 8602118 | M227: 42716 | N227: 54.3138 | O227: 54.3138
E228: 42699 | F228: 51.52 | G228: 2736767 | M228: 42713 | N228: 54.5035 | O228: 54.5035
... E1283: 41169 | F1283: 24.4925 | G1283: 9378872 | M1283: 41183 | N1283: 23.8875 | O1283: 23.8875
E1284: 41166 | F1284: 24.16 | G1284: 22892364
E1285: 41165 | F1285: 24.8 | G1285: 17325628
E1286: 41164 | F1286: 25.21 | G1286: 9197820
E1287: 41163 | F1287: 24.92 | G1287: 9840004
E1288: 41162 | F1288: 25.01 | G1288: 8678360
...

Sheet APV
A2: NIKE Inc (NKE US) - Adjusted Present Value
A4: Projected Cash Flows | H4: Discounted Cash Flows
A6: Case selection for cash flow projection: | H6: Case selection for rA:
A7: Scenario 1: Base Case | H7: Scenario 1: Base Case | J7: >> rA: | K7: =INDEX(WACC!P10:P12,MATCH(APV!H7,WACC!O10:O12,0),1) -> 0.094491073
A9: In Millions of USD | B9: FY 2018E | C9: FY 2019E | D9: FY 2020E | E9: FY 2021E | F9: FY 2022E | H9: In Millions of USD | I9: FY 2018E | J9: FY 2019E | K9: FY 2020E | L9: FY 2021E | M9: FY 2022E
A11: Free Cash Flow | B11: {=INDEX('Free Cash Flows'!$D$22:$H$24,MATCH($A$7,'Free Cash Flows'!$C$22:$C$24,0),MATCH(B9,'Free Cash Flows'!$D$21:$H$21,0))} -> 4867.6183 | C11: {=INDEX('Free Cash Flows'!$D$22:$H$24,MATCH($A$7,'Free Cash Flows'!$C$22:$C$24,0),MATCH(C9,'Free Cash Flows'!$D$21:$H$21,0))} -> 5251.4318 | D11: {=INDEX('Free Cash Flows'!$D$22:$H$24,MATCH($A$7,'Free Cash Flows'!$C$22:$C$24,0),MATCH(D9,'Free Cash Flows'!$D$21:$H$21,0))} -> 5666.3935 | E11: {=INDEX('Free Cash Flows'!$D$22:$H$24,MATCH($A$7,'Free Cash Flows'!$C$22:$C$24,0),MATCH(E9,'Free Cash Flows'!$D$21:$H$21,0))} -> 6115.0279 | F11: {=INDEX('Free Cash Flows'!$D$22:$H$24,MATCH($A$7,'Free Cash Flows'!$C$22:$C$24,0),MATCH(F9,'Free Cash Flows'!$D$21:$H$21,0))} -> 6600.064 | H11: Present Value of Free Cash Flow | I11: =I14*B11 -> 4447.3806 | J11: =J14*C11 -> 4383.8257 | K11: =K14*D11 -> 4321.8536 | L11: =L14*E11 -> 4261.373 | M11: =M14*F11 -> 4202.2997
H13: Discounting Period | I13: 1 | J13: =I13+1 -> 2 | K13: =J13+1 -> 3 | L13: =K13+1 -> 4 | M13: =L13+1 -> 5
A14: Adjusted Present Value of Nike Inc. | H14: Discounting Factor | I14: =1/((1+$K$7)^I13) -> 0.91366666 | J14: =1/((1+$K$7)^J13) -> 0.83478676 | K14: =1/((1+$K$7)^K13) -> 0.76271683 | L14: =1/((1+$K$7)^L13) -> 0.69686893 | M14: =1/((1+$K$7)^M13) -> 0.63670591
A16: Total Capital terminal year | B16: ='Cost of Debt'!R33 -> 98166.089
A17: Debt Ratio terminal year | B17: ='Cost of Debt'!R27 -> 0.022742587
A19: Inflation rate (as of 09/2017) | B19: 0.022
A20: GDP growth rate (as of Q2/2017) | B20: 0.0384 | F20: Cash Flows | H20: Scenario 1: Base Case | I20: {=INDEX('Free Cash Flows'!$D$22:$H$24,MATCH($H$20,'Free Cash Flows'!$C$22:$C$24,0),MATCH(B9,'Free Cash Flows'!$D$21:$H$21,0))} -> 4867.6183 | J20: {=INDEX('Free Cash Flows'!$D$22:$H$24,MATCH($H$20,'Free Cash Flows'!$C$22:$C$24,0),MATCH(C9,'Free Cash Flows'!$D$21:$H$21,0))} -> 5251.4318 | K20: {=INDEX('Free Cash Flows'!$D$22:$H$24,MATCH($H$20,'Free Cash Flows'!$C$22:$C$24,0),MATCH(D9,'Free Cash Flows'!$D$21:$H$21,0))} -> 5666.3935 | L20: {=INDEX('Free Cash Flows'!$D$22:$H$24,MATCH($H$20,'Free Cash Flows'!$C$22:$C$24,0),MATCH(E9,'Free Cash Flows'!$D$21:$H$21,0))} -> 6115.0279 | M20: {=INDEX('Free Cash Flows'!$D$22:$H$24,MATCH($H$20,'Free Cash Flows'!$C$22:$C$24,0),MATCH(F9,'Free Cash Flows'!$D$21:$H$21,0))} -> 6600.064
A21: Perpetuity growth rate | B21: =AVERAGE(B19:B20) -> 0.0302 | F21: rA | H21: Scenario 1: Base Case | I21: {=INDEX(WACC!P10:P12,MATCH(APV!H21,WACC!O10:O12,0),1)} -> 0.094491073
A22: Discount factor | B22: =1/(1+K7)^M13 -> 0.63670591 | H22: Discounting Factor | I22: =1/((1+$I$21)^I13) -> 0.91366666 | J22: =1/((1+$I$21)^J13) -> 0.83478676 | K22: =1/((1+$I$21)^K13) -> 0.76271683 | L22: =1/((1+$I$21)^L13) -> 0.69686893 | M22: =1/((1+$I$21)^M13) -> 0.63670591
A23: Terminal year debt balance | B23: =B16*B17 -> 2232.5509 | H23: Present Value of Cash Flows | I23: =I20*I22 -> 4447.3806 | J23: =J20*J22 -> 4383.8257 | K23: =K20*K22 -> 4321.8536 | L23: =L20*L22 -> 4261.373 | M23: =M20*M22 -> 4202.2997
A24: Terminal value of tax shield | B24: ='Marginal Tax Rate'!K18*B23*'Cost of Equity'!N12*(1+APV!B21)/('Cost of Equity'!N12-APV!B21)^2 -> 14589.453
A26: Present value of tax shield | B26: =B24*B22 -> 9289.1911
A28: q | B28: =(1.26+2.01)/2 -> 1.635 | C28: q = corporate bond spread over Treasuries 1) | H28: PV of terminal value:
A29: ϕ | B29: =(0.1+0.23)/2*100 -> 16.5 | C29: ϕ = total loss in % of pre-distress firm value 2) | F29: PV of terminal value | H29: Scenario 1: Base Case | I29: =M20*(1+B36)/(I21-B36)*M22 -> 72210.685
A30: rF | B30: 2.33 | C30: rF = risk free rate 3) | F30: PV of tax shield | H30: Scenario 1: Base Case | I30: =B24*M22 -> 9289.1911
A31: Φ | B31: =(B28/(B28+B30))*B29 -> 6.8039092 | C31: Φ = NPV of FD in % of pre-distress firm value | F31: Cost of financial distress | H31: Scenario 1: Base Case | I31: =B31*(I29+SUM(I23:M23))/100 -> 6383.9323
A33: Costs of Financial Distress (CFD) 4) | B33: =B31*(B39+SUM(I11:M11))/100 -> 6383.9323 | F33: Enterprise value | I33: =I29+SUM(I23:M23)+I30-I31 -> 96732.676
A35: Free cash flow terminal year | B35: =F11 -> 6600.064
A36: Perpetuity growth rate | B36: =DCF!B19 -> 0.0343
A37: Terminal Value | B37: =B35*(1+B36)/(K7-B36) -> 113412.93
A38: Discount Factor | B38: =1/(1+K7)^M13 -> 0.63670591
A39: PV of Terminal Value | B39: =B37*B38 -> 72210.685
A41: Enterprise Value | B41: =B39+SUM(I11:M11)+B26-B33 -> 96732.676 | E41: =ROUND(((B43-'Share Prices'!F13)/'Share Prices'!F13),3) -> 0.12
A43: Share Price (in $) | B43: =B41/'Income Statement'!K45 -> 58.350028 | C43: =IF(B43>'Share Prices'!F13,CONCATENATE("undervalued by ",(E41*100),"%"),CONCATENATE("overvalued by ",((-1*E41)*100),"%")) -> undervalued by 12%
A44: Source: own calculations
A46: 1) average between Aaa and Baa Bonds, since Nike is A1 rated by Moody's and AA- rated by S&P; see FRED Economic Data, as of 04.10.2017
A47: 2) average of estimation in range of 10-23% of pre-distress firm value; see Gregor Andrade and Steven Kaplan, (1998), “How Costly is Financial (not Economic) Distress? Evidence from Highly Leveraged Transactions that Become Distressed,” Journal of Finance 53, pp. 1443-1493
A48: 3) 10 years Treasury Bill as of 04.10.2017; see US Department of the Treasury as of 04.10.2017
A49: 4) see Heitor Almeida, University of Illinois at Urbana-Champaign, and Thomas Philippon, New York University in: Journal of Applied Corporate Finance; Volume 20 Number 4

Sheet Trading Multiples
N1: EBITDA 2022E
A2: NIKE Inc (NKE US) - Trading Multiples
A4: Comparable Sportswear Companies | B4: Price per Share | C4: Market | D4: Enterprise | E4: Enterprise Value/EBITDA | H4: EBITDA LTM | I4: Bookvalue of Equity | J4: Shares Outstanding | K4: Current Shares Outstanding | L4: Diluted EPS | M4: P/E Ratio | N4: Price/Book Ratio
A5: In Millions of USD except Per Share | C5: Capitalization | D5: Value | E5: FY 2017 | F5: FY 2018 | G5: FY 2019
A6: Nike | B6: 52.69 | C6: 85964.707 | D6: 84259.707 | E6: 15.776017 | F6: 15.517644 | G6: 13.947809 | H6: 5341 | I6: =11992999936/1000000 -> 11993 | J6: 1636.9999 | K6: 1302.273 | L6: =I6/K6 -> 9.2092825 | M6: 22.421276 | N6: 7.1919893
A7: Adidas | B7: 220.492 | C7: 46130.506 | D7: 46447.939 | E7: 18.125747 | F7: 16.131951 | G7: 13.806369 | H7: 2367.9244 | I7: =6990462492.48889/1000000 -> 6990.4625 | J7: 202.65734 | K7: 209.2162 | L7: =I7/K7 -> 33.412625 | M7: 31.881571 | N7: 6.1810325
