Workbook
Name acq: [1]Assumptions!$H$8
Name acq_fye: [1]Assumptions!$H$32
Name acq_price: [1]Assumptions!$J$11
Name assume: [1]Assumptions!$T$11
Name base_year: [2]Control!$D$11
Name case: [1]Assumptions!$T$7
Name cash_rate: [1]Assumptions!$T$20
Name circ: [2]Control!$D$13
Name curr: [2]Control!$D$9
Name debt_rate: [1]Assumptions!$T$16
Name eps: [1]Assumptions!$T$41
Name fees: [1]Assumptions!$T$24
Name libor: [3]LBO!$AF$34
Name min_cash: [1]Assumptions!$T$21
Name pct_cash: [1]Assumptions!$T$8
Name project: [2]Control!$D$5
Name ScenarioSelection: '[4]Table of Contents'!$J$1:$J$3
Name sec_338: [1]Assumptions!$T$13
Name synergies: [1]Assumptions!$T$28
Name tax_rate: [1]Assumptions!$T$39
Name tgt: [1]Assumptions!$L$8
Name tgt_price: [1]Assumptions!$N$11
Name type: [1]Assumptions!$T$12
Name year: [1]Assumptions!$T$40

Sheet K structure
A1: source Annual reports SANOFI 2011, 2012, 2013, 2014, 2015
A4: (€ million) | B4: 2006 | C4: 2007 | D4: 2008 | E4: 2009 | F4: 2010 | G4: 2011 | H4: 2012 | I4: 2013 | J4: 2014 | K4: 2015
A5: Total Assets | B5: 77763 | C5: 71914 | D5: 71987 | E5: 80049 | F5: 85264 | G5: 100165 | H5: 100407 | I5: 96065 | J5: 97392 | K5: 102321
A6: Equity | B6: 45600 | C6: 44719 | D6: 44571 | E6: 48446 | F6: 53097 | G6: 56219 | H6: 57338 | I6: 56885 | J6: 56120 | K6: 58049
A7: LT Debt | B7: 4499 | C7: 3734 | D7: 4173 | E7: 5961 | F7: 6695 | G7: 12499 | H7: 10719 | I7: 10414 | J7: 13276 | K7: 13118
A9: Debt/Assets | B9: =B7/B5 -> 0.057855278 | C9: =C7/C5 -> 0.05192313 | D9: =D7/D5 -> 0.0579688 | E9: =E7/E5 -> 0.074466889 | F9: =F7/F5 -> 0.078520829 | G9: =G7/G5 -> 0.12478411 | H9: =H7/H5 -> 0.10675551 | I9: =I7/I5 -> 0.10840577 | ... K9: =K7/K5 -> 0.12820438 | L9: =AVERAGE(G9:K9) -> 0.12089297
A10: D/(D+E) | B10: =B7/(B6+B7) -> 0.089802192 | C10: =C7/(C6+C7) -> 0.077064372 | D10: =D7/(D6+D7) -> 0.085610537 | E10: =E7/(E6+E7) -> 0.10956311 | F10: =F7/(F6+F7) -> 0.1119715 | G10: =G7/(G6+G7) -> 0.1818883 | H10: =H7/(H6+H7) -> 0.15750033 | I10: =I7/(I6+I7) -> 0.15474227 | ... K10: =K7/(K6+K7) -> 0.18432701 | L10: =AVERAGE(G10:K10) -> 0.17395315
A11: D/E | B11: =B7/B6 -> 0.098662281 | C11: =C7/C6 -> 0.083499184 | D11: =D7/D6 -> 0.0936259 | E11: =E7/E6 -> 0.12304421 | F11: =F7/F6 -> 0.12608999 | G11: =G7/G6 -> 0.22232697 | H11: =H7/H6 -> 0.18694409 | I11: =I7/I6 -> 0.18307111 | ... K11: =K7/K6 -> 0.2259815 | L11: =AVERAGE(G11:K11) -> 0.21097763

Sheet Project Title
B2: Finance and Economics of M&A
B4: Acquisition of Pharmacia Corporation by Pfizer Inc.
B5: Post-Merger Valuation
B16: by
B18: Marc Schwarz
B24: EBS Universität für Wirtschaft und Recht
B25: Spring Term 2018

Sheet Overview
C3: Overview
D4: Valuation techniques | E4: mUSD | L4: Revenue Synergy | N4: 4677.8 | O4: Market Permium (Control Permium) | P4: 10355.36
D5: Stand alone Pfizer | E5: 275606.2 | F5: 343840.06 | L5: Cost of Sale Synergy | N5: 3299.3
D6: Stand alone Pharmacia | E6: 53908.5 | L6: R&D Synergy | N6: 4666.3
D7: Postmerger | E7: 343840.06 | L7: Value of Control | N7: 1599
D8: Potential synergies | E8: 14325.359
D9: Pharmacia value of control | E9: 1598.9
D10: Net potential synergies | E10: 12726.459
D11: Announced Total Purchase Value | E11: 64263.86
D12: Market Premium (Control Premium) | E12: 10355.36

Sheet 1. DATA

Sheet 1.1 Income Statement Pharmacia
B1: Income Statement Pharmacia
B2: Pharmacia LLC
B3: Income Statement | E3: Actual | H3: Projections
B4: In Millions of USD | E4: 1997 | F4: 1998 | G4: 1999 | H4: 2000 | I4: 2001 | J4: 2002 | K4: 2003 | L4: 2004 | M4: 2005 | N4: 2006
C6: Income Statement
C8: Sales | E8: 7514 | F8: 7237 | G8: 16425 | H8: 12651 | I8: 13835 | J8: 14497.697 | K8: 15192.136 | L8: 15919.839 | M8: 16682.4 | N8: 17481.487
C9: Cost of sales | E9: -3091 | F9: -2912 | G9: -5319 | H9: -2886 | I9: -2978 | J9: -2123.9125 | K9: -1365.773 | L9: -1431.1936 | M9: -1499.7477 | N9: -1571.5857
C10: Selling, general & administrative and others | E10: -1709 | F10: -1967 | G10: -4977 | H10: -4968 | I10: -5492 | J10: -4615.8171 | K10: -4836.9147 | L10: -5068.603 | M10: -5311.389 | N10: -5565.8046
C11: R&D expenses | E11: -1044 | F11: -1238 | G11: -2815 | H11: -2165 | I11: -2263 | J11: -2366.298 | K11: -2479.6436 | L11: -2598.4186 | M11: -2722.8828 | N11: -2853.3089
C12: EBITDA | E12: =SUM(E8,E9,E10,E11) -> 1670 | F12: =SUM(F8,F9,F10,F11) -> 1120 | G12: =SUM(G8,G9,G10,G11) -> 3314 | H12: =SUM(H8,H9,H10,H11) -> 2632 | I12: =SUM(I8,I9,I10,I11) -> 3102 | J12: =SUM(J8,J9,J10,J11) -> 5391.6689 | K12: =SUM(K8,K9,K10,K11) -> 6509.8048 | L12: =SUM(L8,L9,L10,L11) -> 6821.6244 | ... N12: =SUM(N8,N9,N10,N11) -> 7490.7876
C13: % margin | E13: =E12/E8 -> 0.2222518 | F13: =F12/F8 -> 0.15476026 | G13: =G12/G8 -> 0.2017656 | H13: =H12/H8 -> 0.20804679 | I13: =I12/I8 -> 0.22421395 | J13: =J12/J8 -> 0.37189832 | K13: =K12/K8 -> 0.42849832 | L13: =L12/L8 -> 0.42849832 | ... N13: =N12/N8 -> 0.42849832
C15: Depreciation & amortization* | E15: -487 | F15: -518 | G15: -1145 | H15: -633 | I15: -611 | J15: -870.72789 | K15: -912.43575 | L15: -956.14142 | M15: -1001.9406 | N15: -1049.9336
C16: EBIT | E16: =E12+E15 -> 1183 | F16: =F12+F15 -> 602 | G16: =G12+G15 -> 2169 | H16: =H12+H15 -> 1999 | I16: =I12+I15 -> 2491 | J16: =J12+J15 -> 4520.941 | K16: =K12+K15 -> 5597.369 | L16: =L12+L15 -> 5865.483 | ... N16: =N12+N15 -> 6440.8541
C17: % margin | E17: =E16/E8 -> 0.15743945 | F17: =F16/F8 -> 0.08318364 | G17: =G16/G8 -> 0.13205479 | H17: =H16/H8 -> 0.15801122 | I17: =I16/I8 -> 0.1800506 | J17: =J16/J8 -> 0.31183858 | K17: =K16/K8 -> 0.36843858 | L17: =L16/L8 -> 0.36843858 | ... N17: =N16/N8 -> 0.36843858
C20: *from Cash Flow Statement

Sheet 1.2 Balance Sheet Pharmacia
B1: Balance Sheet Pharmacia
B2: Pharmacia LLC
B3: Balance Sheet | E3: Actual | H3: Projections
B4: In Millions of USD | E4: 1997 | F4: 1998 | G4: 1999 | H4: 2000 | I4: 2001 | J4: 2002 | K4: 2003 | L4: 2004 | M4: 2005 | N4: 2006
C6: Assets
C8: Cash & cash equivalents | E8: 134 | F8: 89 | G8: 1600 | H8: 2035 | I8: 1276
C9: Short-Term Investments | E9: 0 | F9: 0 | G9: 138 | H9: 35 | I9: 119
C10: Inventory | E10: 1374 | F10: 1722 | G10: 2905 | H10: 1519 | I10: 1683
C11: Accounts receivable | E11: 1823 | F11: 2119 | G11: 4131 | H11: 2510 | I11: 2433
C12: Other current assets | E12: 935 | F12: 1265 | G12: 1908 | H12: 2139 | I12: 2152
C13: Total current assets | E13: =SUM(E8:E12) -> 4266 | F13: =SUM(F8:F12) -> 5195 | G13: =SUM(G8:G12) -> 10682 | H13: =SUM(H8:H12) -> 8238 | I13: =SUM(I8:I12) -> 7663
C15: PP&E | E15: 2400 | F15: 2865 | G15: 6825 | H15: 4512 | I15: 4856
C16: Goodwill | E16: 0 | F16: 0 | G16: 4402 | H16: 1279 | I16: 1059
C17: Other fixed assets | E17: 4108 | F17: 8325 | G17: 5285 | H17: 8748 | I17: 8799
C18: Total fixed assets | E18: =SUM(E15:E17) -> 6508 | F18: =SUM(F15:F17) -> 11190 | G18: =SUM(G15:G17) -> 16512 | H18: =SUM(H15:H17) -> 14539 | I18: =SUM(I15:I17) -> 14714
C20: Assets held for sale of exchange | E20: 0 | F20: 0 | G20: 0 | H20: 0 | I20: 0
C21: Total assets | E21: =E13+E18+E20 -> 10774 | F21: =F13+F18+F20 -> 16385 | G21: =G13+G18+G20 -> 27194 | H21: =H13+H18+H20 -> 22777 | I21: =I13+I18+I20 -> 22377
C23: Equity and Liabilities
C25: Accounts payable | E25: 480 | F25: 823 | G25: 1272 | H25: 836 | I25: 1048
C26: Short-term debt and current portion of long-term debt | E26: 1726 | F26: 1069 | G26: 1992 | H26: 675 | I26: 470
C27: Other current liabilities | E27: 1333 | F27: 1888 | G27: 3910 | H27: 3555 | I27: 3471
C28: Total current libailities | E28: =SUM(E25:E27) -> 3539 | F28: =SUM(F25:F27) -> 3780 | G28: =SUM(G25:G27) -> 7174 | H28: =SUM(H25:H27) -> 5066 | I28: =SUM(I25:I27) -> 4989
C30: Long-term debt | E30: 1979 | F30: 6259 | G30: 6236 | H30: 3624 | I30: 2612
C31: Other non-current liabilities | E31: 1152 | F31: 1360 | G31: 2873 | H31: 2166 | I31: 2386
C32: Total liabilities | E32: =E28+SUM(E30:E31) -> 6670 | F32: =F28+SUM(F30:F31) -> 11399 | G32: =G28+SUM(G30:G31) -> 16283 | H32: =H28+SUM(H30:H31) -> 10856 | I32: =I28+SUM(I30:I31) -> 9987
C34: Equity attributable to equity holders of the Company | E34: 4104 | F34: 4986 | G34: 10911 | H34: 11921 | I34: 12390
C35: Minority interests | E35: 0 | F35: 0 | G35: 0 | H35: 0 | I35: 0
C36: Total equity | E36: =SUM(E34:E35) -> 4104 | F36: =SUM(F34:F35) -> 4986 | G36: =SUM(G34:G35) -> 10911 | H36: =SUM(H34:H35) -> 11921 | I36: =SUM(I34:I35) -> 12390
C38: Liabilities related to assets held for sale or exchange | E38: 0 | F38: 0 | G38: 0 | H38: 0 | I38: 0
C39: Total equity and liabilities | E39: =E32+E36+E38 -> 10774 | F39: =F32+F36+F38 -> 16385 | G39: =G32+G36+G38 -> 27194 | H39: =H32+H36+H38 -> 22777 | I39: =I32+I36+I38 -> 22377
C40: check | E40: =IF(ROUND(E39-E21,1)=0,"ok!",E39-E21) -> ok! | F40: =IF(ROUND(F39-F21,1)=0,"ok!",F39-F21) -> ok! | G40: =IF(ROUND(G39-G21,1)=0,"ok!",G39-G21) -> ok! | H40: =IF(ROUND(H39-H21,1)=0,"ok!",H39-H21) -> ok! | I40: =IF(ROUND(I39-I21,1)=0,"ok!",I39-I21) -> ok!
C43: Operating Working Capital | D43: 1996 | E43: 1997 | F43: 1998 | G43: 1999 | H43: 2000 | I43: 2001 | J43: 2002 | K43: 2003 | L43: 2004 | M43: 2005 | N43: 2006
C44: Total current assets | D44: 4340 | E44: =E13 -> 4266 | F44: =F13 -> 5195 | G44: =G13 -> 10682 | H44: =H13 -> 8238 | I44: =I13 -> 7663
C45: - Cash and Cash equivalents | D45: 166 | E45: =E8 -> 134 | F45: =F8 -> 89 | G45: =G8 -> 1600 | H45: =H8 -> 2035 | I45: =I8 -> 1276
C46: -Total curent liabilities | D46: 3401 | E46: =E28 -> 3539 | F46: =F28 -> 3780 | G46: =G28 -> 7174 | H46: =H28 -> 5066 | I46: =I28 -> 4989
C47: + Short-term debt and current portion of long-term debt | D47: 654 | E47: =E26 -> 1726 | F47: =F26 -> 1069 | G47: =G26 -> 1992 | H47: =H26 -> 675 | I47: =I26 -> 470
C48: NET NON-CASH WORKING CAPITAL | D48: =D44-D45-D46+D47 -> 1427 | E48: =E44-E45-E46+E47 -> 2319 | F48: =F44-F45-F46+F47 -> 2395 | G48: =G44-G45-G46+G47 -> 3900 | H48: =H44-H45-H46+H47 -> 1812 | I48: =I44-I45-I46+I47 -> 1868 | J48: 3068.5492 | K48: 3215.5327 | L48: 3369.5567 | M48: 3530.9584 | N48: 3700.0914
C50: Δ NET NON-CASH WORKING CAPITAL | E50: =E48-D48 -> 892 | F50: =F48-E48 -> 76 | G50: =G48-F48 -> 1505 | H50: =H48-G48 -> -2088 | I50: =I48-H48 -> 56 | J50: =J48-I48 -> 1200.5492 | K50: =K48-J48 -> 146.9835 | L50: =L48-K48 -> 154.02401 | ... N50: =N48-M48 -> 169.13291

Sheet 1.3 Cash Flow Statement 
B1: Balance Sheet Pharmacia
B2: Pharmacia LLC
B3: Cash Flow Statement | E3: Actual | H3: Projections
B4: In Millions of USD | E4: 1997 | F4: 1998 | G4: 1999 | H4: 2000 | I4: 2001 | J4: 2002 | K4: 2003 | L4: 2004 | M4: 2005 | N4: 2006
C6: Cash Flow Statement
C7: Cash From Operating Activities
C8: Depreciation & amortization | E8: 487 | F8: 518 | G8: 1145 | H8: 633 | I8: 611 | J8: 870.72789 | K8: 912.43575 | L8: 956.14142 | M8: 1001.9406 | N8: 1049.9336
C9: Cash From Investing Activities
C10: Capital Expenditures | E10: -644 | F10: -859 | G10: -1678 | H10: -774 | I10: -1020 | J10: -1289.4393 | K10: -1351.2035 | L10: -1415.9261 | M10: -1483.749 | N10: -1554.8206

Sheet 1.4 Income Statement Pfizer
B1: Income Statement Pfizer
R3: Pfizer Inc. US
R4: Income Statement | U4: Actual | X4: Projections
R5: $m | U5: 1997 | V5: 1998 | W5: 1999 | X5: 2000 | Y5: 2001 | Z5: 2002 | AA5: 2003 | AB5: 2004 | AC5: 2005 | AD5: 2006
B7: Assumptions | E7: Actual | H7: Projections | S7: Income Statement
B8: In Millions of USD | E8: 1997 | F8: 1998 | G8: 1999 | H8: 2000 | I8: 2001 | J8: 2002 | K8: 2003 | L8: 2004 | M8: 2005 | N8: 2006
S9: Sales | U9: 12504 | V9: 13544 | W9: 27376 | X9: 29355 | Y9: 29024 | Z9: 31280.079 | AA9: 33711.526 | AB9: 36331.973 | AC9: 39156.112 | AD9: 42199.774
C10: Operating assumptions - Stable growth | S10: Cost of sales | U10: -1776 | V10: -2094 | W10: -5464 | X10: -5007 | Y10: -3823 | Z10: -4100.8183 | AA10: -4251.0234 | AB10: -4399.8019 | AC10: -4546.0245 | AD10: -4688.3949
E11: 1997 | F11: 1998 | G11: 1999 | H11: 2000 | I11: 2001 | J11: 2002 | K11: 2003 | L11: 2004 | M11: 2005 | N11: 2006 | S11: SG&A | U11: -4401 | V11: -6577 | W11: -12070 | X11: -11223 | Y11: -9646 | Z11: -11039.507 | AA11: -11897.624 | AB11: -12822.445 | AC11: -13819.152 | AD11: -14893.336
C12: Income statement | S12: R&D expenses | U12: -1805 | V12: -2279 | W12: -2776 | X12: -4435 | Y12: -4847 | Z12: -4580.0554 | AA12: -4936.0699 | AB12: -5319.758 | AC12: -5733.2707 | AD12: -6178.9264
C13: Sales growth | E13: NA | F13: 0.083173385 | G13: 1.021264 | H13: 0.072289597 | I13: -0.011275762 | J13: 0.077731491 | K13: 0.077731491 | L13: 0.077731491 | M13: 0.077731491 | N13: 0.077731491 | S13: EBITDA | U13: =SUM(U9,U10,U11,U12) -> 4522 | V13: =SUM(V9,V10,V11,V12) -> 2594 | W13: =SUM(W9,W10,W11,W12) -> 7066 | X13: =SUM(X9,X10,X11,X12) -> 8690 | Y13: =SUM(Y9,Y10,Y11,Y12) -> 10708 | Z13: =SUM(Z9,Z10,Z11,Z12) -> 11559.698 | AA13: =SUM(AA9,AA10,AA11,AA12) -> 12626.808 | AB13: =SUM(AB9,AB10,AB11,AB12) -> 13789.969 | ... AD13: =SUM(AD9,AD10,AD11,AD12) -> 16439.118
C14: COGS as % of sales | E14: =-U10/U9 -> 0.14203455 | F14: =-V10/V9 -> 0.15460721 | G14: =-W10/W9 -> 0.19959088 | H14: =-X10/X9 -> 0.17056719 | I14: =-Y10/Y9 -> 0.13171858 | J14: =6*-0.005+0.1611 -> 0.1311 | K14: =7*-0.005+0.1611 -> 0.1261 | L14: =8*-0.005+0.1611 -> 0.1211 | M14: =9*-0.005+0.1611 -> 0.1161 | N14: =10*-0.005+0.1611 -> 0.1111 | S14: % margin | U14: =U13/U9 -> 0.36164427 | V14: =V13/V9 -> 0.19152392 | W14: =W13/W9 -> 0.25810929 | X14: =X13/X9 -> 0.29603134 | Y14: =Y13/Y9 -> 0.36893605 | Z14: =Z13/Z9 -> 0.36955463 | AA14: =AA13/AA9 -> 0.37455463 | AB14: =AB13/AB9 -> 0.37955463 | ... AD14: =AD13/AD9 -> 0.38955463
C15: SG&A, Others as % of sales | E15: =-U11/U9 -> 0.35196737 | F15: =-V11/V9 -> 0.48560248 | G15: =-W11/W9 -> 0.44089714 | H15: =-X11/X9 -> 0.38231988 | I15: =-Y11/Y9 -> 0.33234564 | J15: =-Z11/Z9 -> 0.35292453 | K15: =-AA11/AA9 -> 0.35292453 | L15: =-AB11/AB9 -> 0.35292453 | ... N15: =-AD11/AD9 -> 0.35292453
C16: R&D as % of sales | E16: =-(U12/U9) -> 0.14435381 | F16: =-(V12/V9) -> 0.16826639 | G16: =-(W12/W9) -> 0.10140269 | H16: =-(X12/X9) -> 0.15108159 | I16: =-(Y12/Y9) -> 0.16699972 | J16: =AVERAGE($E$16,$F$16,$G$16,$H$16,$I$16) -> 0.14642084 | K16: =AVERAGE($E$16,$F$16,$G$16,$H$16,$I$16) -> 0.14642084 | L16: =AVERAGE($E$16,$F$16,$G$16,$H$16,$I$16) -> 0.14642084 | M16: =AVERAGE($E$16,$F$16,$G$16,$H$16,$I$16) -> 0.14642084 | N16: =AVERAGE($E$16,$F$16,$G$16,$H$16,$I$16) -> 0.14642084 | S16: Depreciation & amortization* | U16: -428 | V16: -489 | W16: -905 | X16: -968 | Y16: -1068 | Z16: -1151.0172 | AA16: -1240.4875 | AB16: -1336.9125 | AC16: -1440.8327 | AD16: -1552.8307
C17: Effective tax rate | E17: 0.1967 | F17: 0.1967 | G17: 0.3119 | H17: 0.2269 | I17: 0.1873 | J17: 0.4 | K17: 0.4 | L17: 0.4 | M17: 0.4 | N17: 0.4 | S17: EBIT | U17: =U13+U16 -> 4094 | V17: =V13+V16 -> 2105 | W17: =W13+W16 -> 6161 | X17: =X13+X16 -> 7722 | Y17: =Y13+Y16 -> 9640 | Z17: =Z13+Z16 -> 10408.681 | AA17: =AA13+AA16 -> 11386.321 | AB17: =AB13+AB16 -> 12453.056 | ... AD17: =AD13+AD16 -> 14886.287
S18: % margin | U18: =U17/U9 -> 0.32741523 | V18: =V17/V9 -> 0.15541937 | W18: =W17/W9 -> 0.22505114 | X18: =X17/X9 -> 0.2630557 | Y18: =Y17/Y9 -> 0.33213892 | Z18: =Z17/Z9 -> 0.3327575 | AA18: =AA17/AA9 -> 0.3377575 | AB18: =AB17/AB9 -> 0.3427575 | ... AD18: =AD17/AD9 -> 0.3527575
C19: Balance Sheet
C20: NC-WC as % of sales | E20: 0.3086239 | F20: 0.33093823 | G20: 0.23744292 | H20: 0.14322978 | I20: 0.13501988 | J20: =AVERAGE($F$20:$I$20) -> 0.2116577 | K20: =AVERAGE($F$20:$I$20) -> 0.2116577 | L20: =AVERAGE($F$20:$I$20) -> 0.2116577 | M20: =AVERAGE($F$20:$I$20) -> 0.2116577 | N20: =AVERAGE($F$20:$I$20) -> 0.2116577
S21: *from Cash Flow Statement
C22: Cash Flow Statement
C23: D&A as % of sales | E23: 0.06481235 | F23: 0.07157662 | G23: 0.069710807 | H23: 0.05003557 | I23: 0.044163354 | J23: =AVERAGE($E$23:$I$23) -> 0.06005974 | K23: =AVERAGE($E$23:$I$23) -> 0.06005974 | L23: =AVERAGE($E$23:$I$23) -> 0.06005974 | M23: =AVERAGE($E$23:$I$23) -> 0.06005974 | N23: =AVERAGE($E$23:$I$23) -> 0.06005974
C24: Capex as % of sales | E24: 0.085706681 | F24: 0.11869559 | G24: 0.10216134 | H24: 0.061180934 | I24: 0.073726057 | J24: =AVERAGE($F$24:$I$24) -> 0.088940981 | K24: =AVERAGE($F$24:$I$24) -> 0.088940981 | L24: =AVERAGE($F$24:$I$24) -> 0.088940981 | M24: =AVERAGE($F$24:$I$24) -> 0.088940981 | N24: =AVERAGE($F$24:$I$24) -> 0.088940981

Sheet 1.5 Income Statements PfizerRaw
B3: Pfizer Inc (PFE US) - Adjusted
B5: In Millions of USD except Per Share | C5: FY 1997 | D5: FY 1998 | E5: FY 1999 | F5: FY 2000 | G5: FY 2001 | H5: FY 2002 | I5: FY 2003 | J5: FY 2004 | K5: FY 2005 | L5: FY 2006 | M5: FY 2007 | N5: FY 2008 | O5: FY 2009 | P5: FY 2010 | Q5: FY 2011 | R5: FY 2012 | S5: FY 2013 | T5: FY 2014 | U5: FY 2015 | V5: FY 2016 | W5: FY 2017
B6: 12 Months Ending | C6: 12/31/1997 | D6: 12/31/1998 | E6: 12/31/1999 | F6: 12/31/2000 | G6: 12/31/2001 | H6: 12/31/2002 | I6: 12/31/2003 | J6: 12/31/2004 | K6: 12/31/2005 | L6: 12/31/2006 | M6: 12/31/2007 | N6: 12/31/2008 | O6: 12/31/2009 | P6: 12/31/2010 | Q6: 12/31/2011 | R6: 12/31/2012 | S6: 12/31/2013 | T6: 12/31/2014 | U6: 12/31/2015 | V6: 12/31/2016 | W6: 12/31/2017
B7: Revenue | C7: 12504 | D7: 13544 | E7: 27376 | F7: 29355 | G7: 29024 | H7: 32373 | I7: 45188 | J7: 52516 | K7: 47405 | L7: 48371 | M7: 48418 | N7: 48296 | O7: 49934 | P7: 67039 | Q7: 65259 | R7: 54657 | S7: 51452 | T7: 49605 | U7: 48851 | V7: 52824 | W7: 52546
B8: + Sales & Services Revenue | C8: — | D8: — | E8: — | F8: — | G8: — | H8: — | I8: — | J8: — | K8: — | L8: — | M8: — | N8: — | O8: 49934 | P8: 67039 | Q8: 65259 | R8: 54657 | S8: 51452 | T8: 49605 | U8: 48851 | V8: 52824 | W8: 52546
B9: - Cost of Revenue | C9: 1776 | D9: 2094 | E9: 5464 | F9: 5007 | G9: 3823 | H9: 4045 | I9: 6932 | J9: 7541 | K9: 7232 | L9: 7640 | M9: 7745 | N9: 7040 | O9: 8649 | P9: 15083 | Q9: 13264 | R9: 9493 | S9: 9250 | T9: 9139 | U9: 9433 | V9: 11630 | W9: 11154
B10: + Cost of Goods & Services | C10: — | D10: — | E10: — | F10: — | G10: — | H10: — | I10: — | J10: — | K10: — | L10: — | M10: — | N10: — | O10: 8649 | P10: 15083 | Q10: 13264 | R10: 9493 | S10: 9250 | T10: 9139 | U10: 9433 | V10: 11630 | W10: 11154
B11: Gross Profit | C11: 10728 | D11: 11450 | E11: 21912 | F11: 24348 | G11: 25201 | H11: 28328 | I11: 38256 | J11: 44975 | K11: 40173 | L11: 40731 | M11: 40673 | N11: 41256 | O11: 41285 | P11: 51956 | Q11: 51995 | R11: 45164 | S11: 42202 | T11: 40466 | U11: 39418 | V11: 41194 | W11: 41392
B12: + Other Operating Income | C12: — | D12: — | E12: — | F12: — | G12: — | H12: — | I12: — | J12: — | K12: — | L12: — | M12: — | N12: 0 | O12: 0 | P12: 0 | Q12: 0 | R12: 0 | S12: 0 | T12: 0 | U12: 0 | V12: 0 | W12: 0
B13: - Operating Expenses | C13: 6206 | D13: 8856 | E13: 14846 | F13: 15658 | G13: 14493 | H13: 16012 | I13: 22166 | J13: 27887 | K13: 25968 | L13: 26449 | M13: 25893 | N13: 24200 | O13: 25270 | P13: 34045 | Q13: 32673 | R13: 27082 | S13: 25314 | T13: 25001 | U13: 24009 | V13: 22703 | W13: 25476
B14: + Selling, General & Admin | C14: — | D14: 5568 | E14: 10810 | F14: 11223 | G14: — | H14: — | I14: — | J14: 16903 | K14: 15313 | L14: 15589 | M14: 15626 | N14: 14537 | O14: 14637 | P14: 19302 | Q14: 18733 | R14: 15018 | S14: 14164 | T14: 13720 | U14: 14325 | V14: 14745 | W14: 14768
B15: + Research & Development | C15: 1805 | D15: 2279 | E15: 2776 | F15: 4435 | G15: 4847 | H15: 5176 | I15: 7131 | J15: 7684 | K15: 7256 | L15: 7599 | M15: — | N15: — | O15: 7776 | P15: 9340 | Q15: 8396 | R15: 6955 | S15: 6551 | T15: 7150 | U15: 7646 | V15: 7841 | W15: 7596
B16: + Other Operating Expense | C16: — | D16: — | E16: — | F16: — | G16: — | H16: — | I16: — | J16: — | K16: — | L16: — | M16: — | N16: — | O16: 2857 | P16: 5403 | Q16: 5544 | R16: 5109 | S16: 4599 | T16: 4131 | U16: 2038 | V16: 117 | W16: 3112
B17: Operating Income (Loss) | C17: 3073 | D17: 2594 | E17: 7066 | F17: 8690 | G17: 10708 | H17: 12316 | I17: 16090 | J17: 17088 | K17: 14205 | L17: 14282 | M17: 14780 | N17: 17056 | O17: 16015 | P17: 17911 | Q17: 19322 | R17: 18082 | S17: 16888 | T17: 15465 | U17: 15409 | V17: 18491 | W17: 15916
B18: - Non-Operating (Income) Loss | C18: — | D18: — | E18: — | F18: — | G18: — | H18: — | I18: — | J18: — | K18: — | L18: — | M18: — | N18: — | O18: -771 | P18: 551 | Q18: 692 | R18: 855 | S18: 66 | T18: -393 | U18: 1075 | V18: 1351 | W18: 316
B19: + Interest Expense, Net | C19: — | D19: -42 | E19: -64 | F19: -126 | G19: -273 | H19: -131 | I19: -76 | J19: 1 | K19: -269 | L19: -408 | M19: -1099 | N19: -726 | O19: 487 | P19: 1395 | Q19: 1225 | R19: 1140 | S19: 1011 | T19: 935 | U19: 728 | V19: 716 | W19: 879
B20: + Interest Expense | C20: 147 | D20: 143 | E20: 363 | F20: 432 | G20: 266 | H20: 251 | I20: 270 | J20: 347 | K20: 471 | L20: 517 | M20: 397 | N20: 562 | O20: 1233 | P20: 1797 | Q20: 1681 | R20: 1522 | S20: 1414 | T20: 1360 | U20: 1199 | V20: 1186 | W20: 1270
B21: - Interest Income | C21: — | D21: 185 | E21: 427 | F21: 558 | G21: 539 | H21: 382 | I21: 346 | J21: 346 | K21: 740 | L21: 925 | M21: 1496 | N21: 1288 | O21: 746 | P21: 402 | Q21: 456 | R21: 382 | S21: 403 | T21: 425 | U21: 471 | V21: 470 | W21: 391
B22: + Foreign Exch (Gain) Loss | C22: 26 | D22: — | E22: 11 | F22: 59 | G22: 0 | H22: 40 | I22: 1 | J22: 81 | K22: 8 | L22: — | M22: 0 | N22: 0 | O22: 0 | P22: 0 | Q22: 0 | R22: 0 | S22: 0 | T22: 0 | U22: 806 | V22: 0 | W22: 0
B23: + Other Non-Op (Income) Loss | C23: — | D23: — | E23: — | F23: — | G23: — | H23: — | I23: — | J23: — | K23: — | L23: — | M23: — | N23: — | O23: -1258 | P23: -844 | Q23: -533 | R23: -285 | S23: -945 | T23: -1328 | U23: -459 | V23: 635 | W23: -563
B24: Pretax Income (Loss), Adjusted | C24: 2867 | D24: 2594 | E24: 6945 | F24: 5781 | G24: 9984 | H24: 11796 | I24: 3263 | J24: 14007 | K24: 10800 | L24: 13028 | M24: 9278 | N24: 9694 | O24: 16786 | P24: 17360 | Q24: 18630 | R24: 17227 | S24: 16822 | T24: 15858 | U24: 14334 | V24: 17140 | W24: 15600
B25: - Abnormal Losses (Gains) | C25: -10 | D25: 2156.769 | E25: 343 | F25: 3257 | G25: 853 | H25: 716 | I25: 13108 | J25: 4018 | K25: 9867 | L25: 6116 | M25: 6890 | N25: 3308 | O25: 5959 | P25: 8078 | Q25: 6326 | R25: 5985 | S25: 1106 | T25: 3618 | U25: 5369 | V25: 8789 | W25: 3295
B26: + Acquired In-Process R&D | C26: — | D26: — | E26: — | F26: — | G26: — | H26: — | I26: — | J26: — | K26: — | L26: — | M26: — | N26: — | O26: 20 | P26: 125 | Q26: — | R26: — | S26: — | T26: — | U26: — | V26: — | W26: —
B27: + Merger/Acquisition Expense | C27: — | D27: — | E27: — | F27: — | G27: — | H27: — | I27: — | J27: — | K27: — | L27: — | M27: — | N27: — | O27: 4026 | P27: 3989 | Q27: 1979 | R27: 946 | S27: 376 | T27: 183 | U27: 909 | V27: 1364 | W27: 502
B28: + Disposal of Assets | C28: — | D28: — | E28: — | F28: — | G28: — | H28: — | I28: — | J28: — | K28: — | L28: — | M28: — | N28: — | O28: — | P28: — | Q28: — | R28: — | S28: — | T28: -288 | U28: -232 | V28: -171 | W28: —
B29: + Early Extinguishment of Debt | C29: — | D29: — | E29: — | F29: — | G29: — | H29: — | I29: — | J29: — | K29: — | L29: — | M29: — | N29: — | O29: — | P29: — | Q29: — | R29: — | S29: — | T29: — | U29: — | V29: 162 | W29: 999
B30: + Asset Write-Down | C30: — | D30: 213 | E30: — | F30: — | G30: — | H30: — | I30: — | J30: — | K30: — | L30: — | M30: 2798 | N30: — | O30: — | P30: — | Q30: — | R30: — | S30: — | T30: 469 | U30: 1282 | V30: 3716 | W30: 434
B31: + Impairment of Intangibles | C31: — | D31: — | E31: — | F31: — | G31: — | H31: — | I31: — | J31: — | K31: — | L31: — | M31: — | N31: — | O31: — | P31: — | Q31: — | R31: — | S31: — | T31: — | U31: 323 | V31: 869 | W31: —
B32: + Legal Settlement | C32: — | D32: — | E32: — | F32: — | G32: — | H32: — | I32: — | J32: — | K32: — | L32: — | M32: — | N32: — | O32: — | P32: — | Q32: — | R32: — | S32: — | T32: 993 | U32: 968 | V32: 494 | W32: 237
B33: + Restructuring | C33: — | D33: — | E33: — | F33: — | G33: — | H33: — | I33: — | J33: — | K33: — | L33: — | M33: — | N33: — | O33: — | P33: — | Q33: — | R33: — | S33: — | T33: 168 | U33: 1451 | V33: 1685 | W33: 567
B34: + Other Abnormal Items | C34: — | D34: — | E34: — | F34: — | G34: — | H34: — | I34: — | J34: — | K34: — | L34: — | M34: — | N34: — | O34: 1913 | P34: 3964 | Q34: 4347 | R34: 5039 | S34: 730 | T34: 2093 | U34: 668 | V34: 670 | W34: 556
B35: Pretax Income (Loss), GAAP | C35: 2867 | D35: 2594 | E35: 6945 | F35: 5781 | G35: 9984 | H35: 11796 | I35: 3263 | J35: 14007 | K35: 10800 | L35: 13028 | M35: 9278 | N35: 9694 | O35: 10827 | P35: 9282 | Q35: 12304 | R35: 11242 | S35: 15716 | T35: 12240 | U35: 8965 | V35: 8351 | W35: 12305
B36: - Income Tax Expense (Benefit) | C36: 775 | D36: 642 | E36: 1968 | F36: 2049 | G36: 2433 | H36: 2609 | I36: 1621 | J36: 2665 | K36: 3178 | L36: 1992 | M36: 1023 | N36: 1645 | O36: 2197 | P36: 1071 | Q36: 3909 | R36: 2221 | S36: 4306 | T36: 3120 | U36: 1990 | V36: 1123 | W36: -9048
B37: + Current Income Tax | C37: — | D37: — | E37: — | F37: — | G37: — | H37: — | I37: — | J37: — | K37: — | L37: — | M37: — | N37: — | O37: 11779 | P37: -866 | Q37: 3602 | R37: 1435 | S37: 2580 | T37: 2800 | U37: 2010 | V37: 1823 | W37: 17156
B38: + Deferred Income Tax | C38: — | D38: — | E38: — | F38: — | G38: — | H38: — | I38: — | J38: — | K38: — | L38: — | M38: — | N38: — | O38: -9582 | P38: 1937 | Q38: 307 | R38: 786 | S38: 1726 | T38: 320 | U38: -20 | V38: -700 | W38: -26204
B39: Income (Loss) from Cont Ops | C39: 2092 | D39: 1952 | E39: 4977 | F39: 3732 | G39: 7551 | H39: 9187 | I39: 1642 | J39: 11342 | K39: 7622 | L39: 11036 | M39: 8255 | N39: 8049 | O39: 8630 | P39: 8211 | Q39: 8395 | R39: 9021 | S39: 11410 | T39: 9120 | U39: 6975 | V39: 7228 | W39: 21353
B40: - Net Extraordinary Losses (Gains) | C40: -131 | D40: -1401 | E40: 20 | F40: -8 | G40: -251 | H40: 55 | I40: -2271 | J40: -29 | K40: -475 | L40: -8313 | M40: 69 | N40: -78 | O40: -14 | P40: -77 | Q40: -1654 | R40: -5577 | S40: -10662 | T40: -48 | U40: -11 | V40: -18 | W40: -2
B41: + Discontinued Operations | C41: — | D41: -1401 | E41: 20 | F41: — | G41: — | H41: — | I41: — | J41: — | K41: -498 | L41: -8313 | M41: 69 | N41: — | O41: -14 | P41: -77 | Q41: -1654 | R41: -5577 | S41: -10662 | T41: -48 | U41: -11 | V41: -18 | W41: -2
B42: + XO & Accounting Changes | C42: — | D42: — | E42: — | F42: — | G42: — | H42: — | I42: — | J42: — | K42: 23 | L42: — | M42: — | N42: — | O42: 0 | P42: 0 | Q42: 0 | R42: 0 | S42: 0 | T42: 0 | U42: 0 | V42: 0 | W42: 0
B43: Income (Loss) Incl. MI | C43: 2223 | D43: 3353 | E43: 4957 | F43: 3740 | G43: 7802 | H43: 9132 | I43: 3913 | J43: 11371 | K43: 8097 | L43: 19349 | M43: 8186 | N43: 8127 | O43: 8644 | P43: 8288 | Q43: 10049 | R43: 14598 | S43: 22072 | T43: 9168 | U43: 6986 | V43: 7246 | W43: 21355
...

Sheet 1.6 DCF Analysis Pfizer
D2: DCF Analysis Pfizer
E5: In Millions of USD | I5: FY 1997 A | J5: FY 1998 A | K5: FY 1999 A | L5: FY 2000 A | M5: FY 2001 A | N5: Est. Growth Rates | O5: FY 2002 E | P5: FY 2003 E | Q5: FY 2004 E | R5: FY 2005 E | S5: FY 2006 E
E7: Revenues | I7: 12504 | J7: 13544 | K7: 27376 | L7: 29355 | M7: 29024 | N7: =MEDIAN(J10:M10) -> 0.077731491 | O7: =M7*($N$7+1) -> 31280.079 | P7: =($N$7+1)*O7 -> 33711.526 | Q7: =($N$7+1)*P7 -> 36331.973 | R7: =($N$7+1)*Q7 -> 39156.112 | S7: =($N$7+1)*R7 -> 42199.774
E8: (+) Other Operating Income | I8: — | J8: — | K8: — | L8: — | M8: — | O8: — | P8: — | Q8: — | R8: — | S8: —
E9: (-) Operating Expenses | I9: 6206 | J9: 8856 | K9: 14846 | L9: 15658 | M9: 14493 | O9: =M9*($N$7+1) -> 15619.562 | P9: =O9*($N$7+1) -> 16833.694 | Q9: =P9*($N$7+1) -> 18142.203 | R9: =Q9*($N$7+1) -> 19552.423 | S9: =R9*($N$7+1) -> 21072.262
E10: Revenue Growth (y-o-y) | J10: =(J7/I7)-1 -> 0.083173385 | K10: =(K7/J7)-1 -> 1.021264 | L10: =(L7/K7)-1 -> 0.072289597 | M10: =(M7/L7)-1 -> -0.011275762 | O10: =N7 -> 0.077731491 | P10: =N7 -> 0.077731491 | Q10: =N7 -> 0.077731491 | R10: =N7 -> 0.077731491 | S10: =N7 -> 0.077731491
E12: Depreciation & Amortization | I12: 428 | J12: 489 | K12: 905 | L12: 968 | M12: 1068 | N12: =N7 -> 0.077731491 | O12: =M12*($N$12+1) -> 1151.0172 | P12: =O12*($N$12+1) -> 1240.4875 | Q12: =P12*($N$12+1) -> 1336.9125 | R12: =Q12*($N$12+1) -> 1440.8327 | S12: =R12*($N$12+1) -> 1552.8307
E14: Operating Income | I14: 3073 | J14: 2594 | K14: 7066 | L14: 8690 | M14: 10708 | N14: =N7 -> 0.077731491 | O14: =M14*($N$14+1) -> 11540.349 | P14: =O14*($N$14+1) -> 12437.397 | Q14: =P14*($N$14+1) -> 13404.175 | R14: =Q14*($N$14+1) -> 14446.101 | S14: =R14*($N$14+1) -> 15569.018
E15: Operating Income Margin | I15: =I14/I7 -> 0.24576136 | J15: =J14/J7 -> 0.19152392 | K15: =K14/K7 -> 0.25810929 | L15: =L14/L7 -> 0.29603134 | M15: =M14/M7 -> 0.36893605 | O15: =O14/O7 -> 0.36893605 | P15: =P14/P7 -> 0.36893605 | Q15: =Q14/Q7 -> 0.36893605 | R15: =R14/R7 -> 0.36893605 | S15: =S14/S7 -> 0.36893605
E16: Operating Income Growth | J16: =(J14/I14)-1 -> -0.15587374 | K16: =(K14/J14)-1 -> 1.7239784 | L16: =(L14/K14)-1 -> 0.229833 | M16: =(M14/L14)-1 -> 0.23222094 | O16: =(O14/M14)-1 -> 0.077731491 | P16: =(P14/O14)-1 -> 0.077731491 | Q16: =(Q14/P14)-1 -> 0.077731491 | R16: =(R14/Q14)-1 -> 0.077731491 | S16: =(S14/R14)-1 -> 0.077731491
E18: Taxes | I18: 775 | J18: 642 | K18: 1968 | L18: 2049 | M18: 2433 | N18: =AVERAGE(I19:M19) -> 0.24824183 | O18: =$N$18*O14 -> 2864.7974 | P18: =$N$18*P14 -> 3087.4823 | Q18: =$N$18*Q14 -> 3327.4769 | R18: =$N$18*R14 -> 3586.1267 | S18: =$N$18*S14 -> 3864.8816
E19: Average Tax Rate | I19: =I18/I14 -> 0.25219655 | J19: =J18/J14 -> 0.24749422 | K19: =K18/K14 -> 0.27851684 | L19: =L18/L14 -> 0.23578826 | M19: =M18/M14 -> 0.2272133 | O19: =$N$18 -> 0.24824183 | P19: =$N$18 -> 0.24824183 | Q19: =$N$18 -> 0.24824183 | R19: =$N$18 -> 0.24824183 | S19: =$N$18 -> 0.24824183
E21: Net Income | I21: =I14-I18 -> 2298 | J21: =J14-J18 -> 1952 | K21: =K14-K18 -> 5098 | L21: =L14-L18 -> 6641 | M21: =M14-M18 -> 8275 | O21: =O14-O18 -> 8675.5514 | P21: =P14-P18 -> 9349.915 | Q21: =Q14-Q18 -> 10076.698 | R21: =R14-R18 -> 10859.975 | S21: =S14-S18 -> 11704.137
E22: Net Income Margin | I22: =I21/I7 -> 0.18378119 | J22: =J21/J7 -> 0.14412286 | K22: =K21/K7 -> 0.18622151 | L22: =L21/L7 -> 0.22623063 | M22: =M21/M7 -> 0.28510888 | O22: =O21/O7 -> 0.27735069 | P22: =P21/P7 -> 0.27735069 | Q22: =Q21/Q7 -> 0.27735069 | R22: =R21/R7 -> 0.27735069 | S22: =S21/S7 -> 0.27735069
E23: Net Income Growth | J23: =(J21/I21)-1 -> -0.15056571 | K23: =(K21/J21)-1 -> 1.6116803 | L23: =(L21/K21)-1 -> 0.30266771 | M23: =(M21/L21)-1 -> 0.24604728 | O23: =(O21/M21)-1 -> 0.048405009 | P23: =(P21/O21)-1 -> 0.077731491 | Q23: =(Q21/P21)-1 -> 0.077731491 | R23: =(R21/Q21)-1 -> 0.077731491 | S23: =(S21/R21)-1 -> 0.077731491
E25: (+) Depreciation & Amortization | I25: =I12 -> 428 | J25: =J12 -> 489 | K25: =K12 -> 905 | L25: =L12 -> 968 | M25: =M12 -> 1068 | N25: =AVERAGE(J26:M26) -> 0.29153954 | O25: =M25*($N$25+1) -> 1379.3642 | P25: =O25*($N$25+1) -> 1781.5034 | Q25: =P25*($N$25+1) -> 2300.8821 | R25: =Q25*($N$25+1) -> 2971.6802 | S25: =R25*($N$25+1) -> 3838.0425
E26: %-Change D&A | J26: =(J25/I25)-1 -> 0.14252336 | K26: =(K25/J25)-1 -> 0.85071575 | L26: =(L25/K25)-1 -> 0.06961326 | M26: =(M25/L25)-1 -> 0.10330579 | O26: =(O25/M25)-1 -> 0.29153954 | P26: =(P25/O25)-1 -> 0.29153954 | Q26: =(Q25/P25)-1 -> 0.29153954 | R26: =(R25/Q25)-1 -> 0.29153954 | S26: =(S25/R25)-1 -> 0.29153954
E27: Net Working Capital | I27: 410 | J27: 2671 | K27: 1628 | L27: 3593 | M27: 1362 | N27: =MEDIAN(I27:M27) -> 1628 | O27: =N27 -> 1628 | P27: =O27 -> 1628 | Q27: =P27 -> 1628 | R27: =Q27 -> 1628 | S27: =R27 -> 1628
E28: (-) Change in Net Working Capital | I28: =I27-F35 -> -251 | J28: =J27-I27 -> 2261 | K28: =K27-J27 -> -1043 | L28: =L27-K27 -> 1965 | M28: =M27-L27 -> -2231 | O28: =O27-M27 -> 266 | P28: =P27-O27 -> 0 | Q28: =Q27-P27 -> 0 | R28: =R27-Q27 -> 0 | S28: =S27-R27 -> 0
E29: %-Change in Net Working Capital | I29: =(I27/F35)-1 -> -0.37972769 | J29: =(J27/I27)-1 -> 5.5146341 | K29: =(K27/J27)-1 -> -0.39049045 | L29: =(L27/K27)-1 -> 1.2070025 | M29: =(M27/L27)-1 -> -0.62092959
E30: (-) CAPEX | I30: 371 | J30: 1466 | K30: 5175 | L30: 1708 | M30: 1426 | N30: =MEDIAN(I30:M30) -> 1466 | O30: =$N$30 -> 1466 | P30: =$N$30 -> 1466 | Q30: =$N$30 -> 1466 | R30: =$N$30 -> 1466 | S30: =$N$30 -> 1466
E33: Free Cash Flow | I33: =I21+I25-I28-I30 -> 2606 | J33: =J21+J25-J28-J30 -> -1286 | K33: =K21+K25-K28-K30 -> 1871 | L33: =L21+L25-L28-L30 -> 3936 | M33: =M21+M25-M28-M30 -> 10148 | O33: =O21+O25-O28-O30 -> 8322.9157 | P33: =P21+P25-P28-P30 -> 9665.4184 | Q33: =Q21+Q25-Q28-Q30 -> 10911.58 | R33: =R21+R25-R28-R30 -> 12365.655 | S33: =S21+S25-S28-S30 -> 14076.179
E35: NWC 1996 | F35: 661
E38: Projected Cash Flows | L38: WACC | M38: Discounted Cash Flows
E39: In Millions of USD | G39: FY 2002 E | H39: FY 2003 E | I39: FY 2004 E | J39: FY 2005 E | K39: FY 2006 E | L39: 0.078 | M39: In Millions of USD | O39: FY 2002 E | P39: FY 2003 E | Q39: FY 2004 E | R39: FY 2005 E | S39: FY 2006 E
E41: Free Cash Flow | G41: =O33 -> 8322.9157 | H41: =P33 -> 9665.4184 | I41: =Q33 -> 10911.58 | J41: =R33 -> 12365.655 | K41: =S33 -> 14076.179 | M41: Present Value of Free Cash Flow | O41: =O43*G41 -> 7720.701 | P41: =P43*H41 -> 8317.3148 | Q41: =Q43*I41 -> 8710.2648 | R41: =R43*J41 -> 9156.7651 | S41: =S43*K41 -> 9669.2097
M42: Discounting Period | O42: 1 | P42: 2 | Q42: 3 | R42: 4 | S42: 5
E43: Present Value of Pfizer Inc. | M43: Discounting Factor | O43: =1/((1+$L$39)^O42) -> 0.92764378 | P43: =1/((1+$L$39)^P42) -> 0.86052299 | Q43: =1/((1+$L$39)^Q42) -> 0.7982588 | R43: =1/((1+$L$39)^R42) -> 0.74049982 | S43: =1/((1+$L$39)^S42) -> 0.68692005
E44: Free cash flow terminal year | F44: =K41 -> 14076.179
E45: Inflation rate (as of 12/2001) | F45: 0.027
E46: GDP growth rate (as of 12/2001) | F46: 0.0375
E47: Perpetuity growth rate | F47: =0.25*F45+0.75*F46 -> 0.034875
E48: Terminal Value | F48: =F44*(1+F47)/(L39-F47) -> 337787.5
E49: Discount Factor | F49: =1/((1+L39)^S42) -> 0.68692005
E50: PV of Terminal Value | F50: =F48*F49 -> 232033.01
E52: Enterprise Value (EV) | F52: =F50+O41+P41+Q41+R41+S41 -> 275607.26
E54: Share Price (in $) | F54: 43.324938 | G54: undervalued by 8.7%
E55: Source: own calculations
G56: 0.087

Sheet 2. WACC >>>>

Sheet 2.1 Post-WACC
B1: Post-WACC
B2: In Millions of USD | C2: Acquiring Firm* | E2: Target Firm*
C4: Pfizer | E4: Pharmacia
B5: Levered Beta | C5: 0.656 | E5: 0.63
B6: Enterprise Value | C6: 275607.26 | E6: 55507.4
B7: Debt | C7: 8872 | E7: 3082
B8: Equity | C8: 250138.45 | E8: 55328.1
B9: Unlevered Beta | C9: =C5/(1+(C7/C8)*(1-C10)) -> 0.64233055 | E9: =E5/(1+(E7/E8)*(1-E10)) -> 0.60962485
B10: Marginal Tax rate | C10: 0.4 | E10: 0.4
B11: After Tax Cost of Debt | C11: 0.0286 | E11: 0.0459
B12: Cost of Equity | C12: 0.073 | E12: 0.0785
C14: Postmerger Firm
C16: Pfizer
B17: Unlevered Beta | C17: =C9*(C6/(C6+E6))+E9*(E6/(C6+E6)) -> 0.63684784
B18: Combined D/E ratio | C18: =(C7+E7)/(C8+E8) -> 0.039133581
B19: Levered Beta | C19: =C17*(1+C18*(1-C10)) -> 0.65180112
B20: After Tax Cost of Debt | C20: =(C11*C6+E11*E6)/(C6+E6) -> 0.031500137
B21: Cost of Equity | C21: =(C12*C6+E12*E6)/(C6+E6) -> 0.073922009
B22: WACC | C22: =C21*100/104+C20*4/104 -> 0.072290399
B26: *From Bloomberg 2001A

Sheet 3. FINANCIALS >>>>

Sheet 3.1 Growth Ratio
B1: Growth Ratio
B6: Assumptions | E6: Projections
B7: In Millions of USD | E7: 2002 | F7: 2003 | G7: 2004 | H7: 2005 | I7: 2006
C9: Operating assumptions - Stable growth
E10: 2002 | F10: 2003 | G10: 2004 | H10: 2005 | I10: 2006
C11: Income statement
C12: Sales growth | E12: =('3.3 Income Statement'!F8-'3.3 Income Statement'!E8)/'3.3 Income Statement'!E8 -> 0.068101806 | F12: =('3.3 Income Statement'!G8-'3.3 Income Statement'!F8)/'3.3 Income Statement'!F8 -> 0.068283939 | G12: =('3.3 Income Statement'!H8-'3.3 Income Statement'!G8)/'3.3 Income Statement'!G8 -> 0.068464208 | H12: =('3.3 Income Statement'!I8-'3.3 Income Statement'!H8)/'3.3 Income Statement'!H8 -> 0.068642571 | I12: =('3.3 Income Statement'!J8-'3.3 Income Statement'!I8)/'3.3 Income Statement'!I8 -> 0.068818988
C13: Cost of Sales as % of sales | E13: =-'3.3 Income Statement'!F9/'3.3 Income Statement'!F8 -> 0.13597714 | F13: =-'3.3 Income Statement'!G9/'3.3 Income Statement'!G8 -> 0.11485431 | G13: =-'3.3 Income Statement'!H9/'3.3 Income Statement'!H8 -> 0.11159413 | H13: =-'3.3 Income Statement'!I9/'3.3 Income Statement'!I8 -> 0.10827245 | I13: =-'3.3 Income Statement'!J9/'3.3 Income Statement'!J8 -> 0.10489022
C14: SG&A, Others as % of sales | E14: =-'3.3 Income Statement'!F10/'3.3 Income Statement'!F8 -> 0.34198526 | F14: =-'3.3 Income Statement'!G10/'3.3 Income Statement'!G8 -> 0.34219399 | G14: =-'3.3 Income Statement'!H10/'3.3 Income Statement'!H8 -> 0.34240051 | H14: =-'3.3 Income Statement'!I10/'3.3 Income Statement'!I8 -> 0.34260479 | I14: =-'3.3 Income Statement'!J10/'3.3 Income Statement'!J8 -> 0.34280677
C15: R&D as % of sales | E15: =-'3.3 Income Statement'!F11/'3.3 Income Statement'!F8 -> 0.15174074 | F15: =-'3.3 Income Statement'!G11/'3.3 Income Statement'!G8 -> 0.15163923 | G15: =-'3.3 Income Statement'!H11/'3.3 Income Statement'!H8 -> 0.15153879 | H15: =-'3.3 Income Statement'!I11/'3.3 Income Statement'!I8 -> 0.15143945 | I15: =-'3.3 Income Statement'!J11/'3.3 Income Statement'!J8 -> 0.15134123
C16: Effective tax rate | E16: 0.4 | F16: 0.4 | G16: 0.4 | H16: 0.4 | I16: 0.4
C18: Balance Sheet
C19: NC-WC as % of sales | E19: ='3.2 Balance Sheet'!D8/'3.3 Income Statement'!F8 -> 0.070558256 | F19: ='3.2 Balance Sheet'!E8/'3.3 Income Statement'!G8 -> 0.096036758 | G19: ='3.2 Balance Sheet'!F8/'3.3 Income Statement'!H8 -> 0.092695974 | H19: ='3.2 Balance Sheet'!G8/'3.3 Income Statement'!I8 -> 0.089500178 | I19: ='3.2 Balance Sheet'!H8/'3.3 Income Statement'!J8 -> 0.086441847
C21: Cash Flow Statement
C22: D&A as % of sales | E22: ='3.4 Cash Flow Statement'!E8/'3.3 Income Statement'!F8 -> 0.036677186 | F22: ='3.4 Cash Flow Statement'!F8/'3.3 Income Statement'!G8 -> 0.041341385 | G22: ='3.4 Cash Flow Statement'!G8/'3.3 Income Statement'!H8 -> 0.041202844 | H22: ='3.4 Cash Flow Statement'!H8/'3.3 Income Statement'!I8 -> 0.041065813 | I22: ='3.4 Cash Flow Statement'!I8/'3.3 Income Statement'!J8 -> 0.040930322
C23: Capex as % of sales | E23: ='3.4 Cash Flow Statement'!E11/'3.3 Income Statement'!F8 -> -0.060191639 | F23: ='3.4 Cash Flow Statement'!F11/'3.3 Income Statement'!G8 -> -0.057607209 | G23: ='3.4 Cash Flow Statement'!G11/'3.3 Income Statement'!H8 -> -0.055154568 | H23: ='3.4 Cash Flow Statement'!H11/'3.3 Income Statement'!I8 -> -0.052826426 | I23: ='3.4 Cash Flow Statement'!I11/'3.3 Income Statement'!J8 -> -0.050615897

Sheet 3.2 Balance Sheet
B1: Balance Sheet
B3: Income Statement | D3: Actual | E3: Projections
B4: In Millions of USD
C7: Operating Working Capital | D7: 2001 | E7: 2002 | F7: 2003 | G7: 2004 | H7: 2005 | I7: 2006
C8: NET NON-CASH WORKING CAPITAL | D8: ='1.2 Balance Sheet Pharmacia'!I48+'1.6 DCF Analysis Pfizer'!M27 -> 3230 | E8: ='1.2 Balance Sheet Pharmacia'!J48+'1.6 DCF Analysis Pfizer'!N27 -> 4696.5492 | F8: ='1.2 Balance Sheet Pharmacia'!K48+'1.6 DCF Analysis Pfizer'!O27 -> 4843.5327 | G8: ='1.2 Balance Sheet Pharmacia'!L48+'1.6 DCF Analysis Pfizer'!P27 -> 4997.5567 | H8: ='1.2 Balance Sheet Pharmacia'!M48+'1.6 DCF Analysis Pfizer'!Q27 -> 5158.9584 | I8: ='1.2 Balance Sheet Pharmacia'!N48+'1.6 DCF Analysis Pfizer'!R27 -> 5328.0914
C10: Δ NET NON-CASH WORKING CAPITAL | D10: NA | E10: =E8-D8 -> 1466.5492 | F10: =F8-E8 -> 146.9835 | G10: =G8-F8 -> 154.02401 | H10: =H8-G8 -> 161.40176 | I10: =I8-H8 -> 169.13291

Sheet 3.3 Income Statement
B1: Income Statement
B3: Income Statement | E3: Actual | F3: Projections
B4: In Millions of USD | E4: 2001A | F4: 2002 | G4: 2003 | H4: 2004 | I4: 2005 | J4: 2006
C6: Income Statement
C8: Sales | E8: ='1.1 Income Statement Pharmacia'!I8+'1.4 Income Statement Pfizer'!Y9 -> 42859 | F8: ='1.1 Income Statement Pharmacia'!J8+'1.4 Income Statement Pfizer'!Z9 -> 45777.775 | G8: ='1.1 Income Statement Pharmacia'!K8+'1.4 Income Statement Pfizer'!AA9 -> 48903.662 | H8: ='1.1 Income Statement Pharmacia'!L8+'1.4 Income Statement Pfizer'!AB9 -> 52251.813 | I8: ='1.1 Income Statement Pharmacia'!M8+'1.4 Income Statement Pfizer'!AC9 -> 55838.511 | J8: ='1.1 Income Statement Pharmacia'!N8+'1.4 Income Statement Pfizer'!AD9 -> 59681.261
C9: Cost of sales | E9: ='1.1 Income Statement Pharmacia'!I9+'1.4 Income Statement Pfizer'!Y10 -> -6801 | F9: ='1.1 Income Statement Pharmacia'!J9+'1.4 Income Statement Pfizer'!Z10 -> -6224.7309 | G9: ='1.1 Income Statement Pharmacia'!K9+'1.4 Income Statement Pfizer'!AA10 -> -5616.7965 | H9: ='1.1 Income Statement Pharmacia'!L9+'1.4 Income Statement Pfizer'!AB10 -> -5830.9955 | I9: ='1.1 Income Statement Pharmacia'!M9+'1.4 Income Statement Pfizer'!AC10 -> -6045.7723 | J9: ='1.1 Income Statement Pharmacia'!N9+'1.4 Income Statement Pfizer'!AD10 -> -6259.9806
C10: Selling, general & administrative | E10: ='1.1 Income Statement Pharmacia'!I10+'1.4 Income Statement Pfizer'!Y11 -> -15138 | F10: ='1.1 Income Statement Pharmacia'!J10+'1.4 Income Statement Pfizer'!Z11 -> -15655.324 | G10: ='1.1 Income Statement Pharmacia'!K10+'1.4 Income Statement Pfizer'!AA11 -> -16734.539 | H10: ='1.1 Income Statement Pharmacia'!L10+'1.4 Income Statement Pfizer'!AB11 -> -17891.047 | I10: ='1.1 Income Statement Pharmacia'!M10+'1.4 Income Statement Pfizer'!AC11 -> -19130.541 | J10: ='1.1 Income Statement Pharmacia'!N10+'1.4 Income Statement Pfizer'!AD11 -> -20459.14
C11: R&D expenses | E11: ='1.1 Income Statement Pharmacia'!I11+'1.4 Income Statement Pfizer'!Y12 -> -7110 | F11: ='1.1 Income Statement Pharmacia'!J11+'1.4 Income Statement Pfizer'!Z12 -> -6946.3534 | G11: ='1.1 Income Statement Pharmacia'!K11+'1.4 Income Statement Pfizer'!AA12 -> -7415.7136 | H11: ='1.1 Income Statement Pharmacia'!L11+'1.4 Income Statement Pfizer'!AB12 -> -7918.1766 | I11: ='1.1 Income Statement Pharmacia'!M11+'1.4 Income Statement Pfizer'!AC12 -> -8456.1535 | J11: ='1.1 Income Statement Pharmacia'!N11+'1.4 Income Statement Pfizer'!AD12 -> -9032.2353
C12: EBITDA | E12: =SUM(E8,E9,E10,E11) -> 13810 | F12: =SUM(F8,F9,F10,F11) -> 16951.367 | G12: =SUM(G8,G9,G10,G11) -> 19136.613 | H12: =SUM(H8,H9,H10,H11) -> 20611.593 | I12: =SUM(I8,I9,I10,I11) -> 22206.044 | J12: =SUM(J8,J9,J10,J11) -> 23929.905
C13: % margin | E13: =E12/E8 -> 0.32221937 | F13: =F12/F8 -> 0.37029687 | G13: =G12/G8 -> 0.39131247 | H13: =H12/H8 -> 0.39446657 | I13: =I12/I8 -> 0.39768331 | J13: =J12/J8 -> 0.40096179
C15: Depreciation & amortization* | E15: ='1.1 Income Statement Pharmacia'!I15+'1.4 Income Statement Pfizer'!Y16 -> -1679 | F15: ='1.1 Income Statement Pharmacia'!J15+'1.4 Income Statement Pfizer'!Z16 -> -2021.7451 | G15: ='1.1 Income Statement Pharmacia'!K15+'1.4 Income Statement Pfizer'!AA16 -> -2152.9233 | H15: ='1.1 Income Statement Pharmacia'!L15+'1.4 Income Statement Pfizer'!AB16 -> -2293.0539 | I15: ='1.1 Income Statement Pharmacia'!M15+'1.4 Income Statement Pfizer'!AC16 -> -2442.7733 | J15: ='1.1 Income Statement Pharmacia'!N15+'1.4 Income Statement Pfizer'!AD16 -> -2602.7643
C16: EBIT | E16: =E12+E15 -> 12131 | F16: =F12+F15 -> 14929.622 | G16: =G12+G15 -> 16983.69 | H16: =H12+H15 -> 18318.539 | I16: =I12+I15 -> 19763.271 | J16: =J12+J15 -> 21327.141
C17: % margin | E17: =E16/E8 -> 0.2830444 | F17: =F16/F8 -> 0.32613253 | G17: =G16/G8 -> 0.34728871 | H17: =H16/H8 -> 0.35058189 | I17: =I16/I8 -> 0.35393621 | J17: =J16/J8 -> 0.35735071
C19: *from Cash Flow Statement

Sheet 3.4 Cash Flow Statement
B1: Cash Flow Statement
B3: Income Statement | E3: Projections
B4: In Millions of USD | E4: 2002 | F4: 2003 | G4: 2004 | H4: 2005 | I4: 2006
C6: Cash Flow Statement
C7: Cash From Operating Activities
C8: Depreciation & amortization | E8: =-'3.3 Income Statement'!E15 -> 1679 | F8: =-'3.3 Income Statement'!F15 -> 2021.7451 | G8: =-'3.3 Income Statement'!G15 -> 2152.9233 | H8: =-'3.3 Income Statement'!H15 -> 2293.0539 | I8: =-'3.3 Income Statement'!I15 -> 2442.7733
C10: Cash From Investing Activities
C11: Capital Expenditures | E11: =-'1.6 DCF Analysis Pfizer'!O30+'1.3 Cash Flow Statement '!J10 -> -2755.4393 | F11: =-'1.6 DCF Analysis Pfizer'!P30+'1.3 Cash Flow Statement '!K10 -> -2817.2035 | G11: =-'1.6 DCF Analysis Pfizer'!Q30+'1.3 Cash Flow Statement '!L10 -> -2881.9261 | H11: =-'1.6 DCF Analysis Pfizer'!R30+'1.3 Cash Flow Statement '!M10 -> -2949.749 | I11: =-'1.6 DCF Analysis Pfizer'!S30+'1.3 Cash Flow Statement '!N10 -> -3020.8206

Sheet 4. VALUATION >>>>

Sheet 4.1 Combined Free Cash Flow
B1: Combined Free Cash Flow
B3: Income Statement
B4: In Millions of USD | E4: 2002 | F4: 2003 | G4: 2004 | H4: 2005 | I4: 2006
C6: Unlevered Free Cash Flow
C8: Year (t) | E8: 1 | F8: 2 | G8: 3 | H8: 4 | I8: 5
C10: Revenue | E10: ='3.3 Income Statement'!F8 -> 45777.775 | F10: ='3.3 Income Statement'!G8 -> 48903.662 | G10: ='3.3 Income Statement'!H8 -> 52251.813 | H10: ='3.3 Income Statement'!I8 -> 55838.511 | I10: ='3.3 Income Statement'!J8 -> 59681.261
C11: Cost of sales | E11: ='3.3 Income Statement'!F9 -> -6224.7309 | F11: ='3.3 Income Statement'!G9 -> -5616.7965 | G11: ='3.3 Income Statement'!H9 -> -5830.9955 | H11: ='3.3 Income Statement'!I9 -> -6045.7723 | I11: ='3.3 Income Statement'!J9 -> -6259.9806
C12: SG&A | E12: ='3.3 Income Statement'!F10 -> -15655.324 | F12: ='3.3 Income Statement'!G10 -> -16734.539 | G12: ='3.3 Income Statement'!H10 -> -17891.047 | H12: ='3.3 Income Statement'!I10 -> -19130.541 | I12: ='3.3 Income Statement'!J10 -> -20459.14
C13: R&D | E13: ='3.3 Income Statement'!F11 -> -6946.3534 | F13: ='3.3 Income Statement'!G11 -> -7415.7136 | G13: ='3.3 Income Statement'!H11 -> -7918.1766 | H13: ='3.3 Income Statement'!I11 -> -8456.1535 | I13: ='3.3 Income Statement'!J11 -> -9032.2353
C14: EBITDA | E14: =E10+E11+E12+E13 -> 16951.367 | F14: =F10+F11+F12+F13 -> 19136.613 | G14: =G10+G11+G12+G13 -> 20611.593 | H14: =H10+H11+H12+H13 -> 22206.044 | I14: =I10+I11+I12+I13 -> 23929.905
C16: Depreciation & amortization | E16: ='3.3 Income Statement'!F15 -> -2021.7451 | F16: ='3.3 Income Statement'!G15 -> -2152.9233 | G16: ='3.3 Income Statement'!H15 -> -2293.0539 | H16: ='3.3 Income Statement'!I15 -> -2442.7733 | I16: ='3.3 Income Statement'!J15 -> -2602.7643
C17: EBIT | E17: =E14+E16 -> 14929.622 | F17: =F14+F16 -> 16983.69 | G17: =G14+G16 -> 18318.539 | H17: =H14+H16 -> 19763.271 | I17: =I14+I16 -> 21327.141
C18: Adjust. EBIT* | E18: ='1.1 Income Statement Pharmacia'!J16+'1.6 DCF Analysis Pfizer'!O14 -> 16061.29 | F18: ='1.1 Income Statement Pharmacia'!K16+'1.6 DCF Analysis Pfizer'!P14 -> 18034.766 | G18: ='1.1 Income Statement Pharmacia'!L16+'1.6 DCF Analysis Pfizer'!Q14 -> 19269.658 | H18: ='1.1 Income Statement Pharmacia'!M16+'1.6 DCF Analysis Pfizer'!R14 -> 20592.541 | I18: ='1.1 Income Statement Pharmacia'!N16+'1.6 DCF Analysis Pfizer'!S14 -> 22009.872
C20: Effective tax rate | E20: 0.4 | F20: 0.4 | G20: 0.4 | H20: 0.4 | I20: 0.4
C21: EBIT*(1-Tax rate) | E21: =E18*(1-E20) -> 9636.7739 | F21: =F18*(1-F20) -> 10820.86 | G21: =G18*(1-G20) -> 11561.795 | H21: =H18*(1-H20) -> 12355.525 | I21: =I18*(1-I20) -> 13205.923
C23: Depreciation & amortization | E23: ='3.3 Income Statement'!F15 -> -2021.7451 | F23: ='3.3 Income Statement'!G15 -> -2152.9233 | G23: ='3.3 Income Statement'!H15 -> -2293.0539 | H23: ='3.3 Income Statement'!I15 -> -2442.7733 | I23: ='3.3 Income Statement'!J15 -> -2602.7643
C24: Δ net Working Capital | E24: ='3.2 Balance Sheet'!E10 -> 1466.5492 | F24: ='3.2 Balance Sheet'!F10 -> 146.9835 | G24: ='3.2 Balance Sheet'!G10 -> 154.02401 | H24: ='3.2 Balance Sheet'!H10 -> 161.40176 | I24: ='3.2 Balance Sheet'!I10 -> 169.13291
C25: Capex | E25: ='3.4 Cash Flow Statement'!E11 -> -2755.4393 | F25: ='3.4 Cash Flow Statement'!F11 -> -2817.2035 | G25: ='3.4 Cash Flow Statement'!G11 -> -2881.9261 | H25: ='3.4 Cash Flow Statement'!H11 -> -2949.749 | I25: ='3.4 Cash Flow Statement'!I11 -> -3020.8206
C27: FCF | E27: =E21-E23-E24+E25 -> 7436.5305 | F27: =F21-F23-F24+F25 -> 10009.596 | G27: =G21-G23-G24+G25 -> 10818.898 | H27: =H21-H23-H24+H25 -> 11687.147 | I27: =I21-I23-I24+I25 -> 12618.734
C29: Unleverd FCF | E29: =E27/(1+$D$39)^'4.1 Combined Free Cash Flow'!E8 -> 6935.1833 | F29: =F27/(1+$D$39)^'4.1 Combined Free Cash Flow'!F8 -> 8705.4599 | G29: =G27/(1+$D$39)^'4.1 Combined Free Cash Flow'!G8 -> 8774.973 | H29: =H27/(1+$D$39)^'4.1 Combined Free Cash Flow'!H8 -> 8840.1338 | I29: =I27/(1+$D$39)^'4.1 Combined Free Cash Flow'!I8 -> 8901.3055
C30: PV of UFCF | I30: =SUM(E29:I29) -> 42157.055
C31: TV | I31: =I29*(1+D40)/(D39-D40) -> 261313.9
C32: EV* | I32: =I30+I31 -> 303470.96
C33: *Because this value is much smaller than the sum of two companies stand alone, therefore this result should be discarded. Therefore we use the sum of the two companies stand alone to show the pre-merger value
C36: * Estimation using the number from the Income Statement - Adjusted of Bloomberg Terminal from 1997A to 2001A
C39: WACC | D39: ='2.1 Post-WACC'!C22 -> 0.072290399
C40: Perpetuity growth rate* | D40: =1.06*'1.6 DCF Analysis Pfizer'!F47 -> 0.0369675
C41: * It's a little higher than Pfizer standing alone, becaues we believe this case is acrrective.
F44: Sensitivity Analysis
G46: WACC
D48: =I32 -> 303470.96 | E48: =F48-0.5% -> 0.052290399 | F48: =G48-0.5% -> 0.057290399 | G48: =H48-0.5% -> 0.062290399 | H48: =I48-0.5% -> 0.067290399 | I48: =D39 -> 0.072290399 | J48: =I48+0.5% -> 0.077290399 | K48: =J48+0.5% -> 0.082290399 | L48: =K48+0.5% -> 0.087290399 | M48: =L48+0.5% -> 0.092290399
C49: Perpetuity Growth Rate | D49: =D50-0.005 -> 0.0219675 | E49: =$E$27/(1+E48)^1+$F$27/(1+E48)^2+$G$27/(1+E48)^3+$H$27/(1+E48)^4+$I$27/(1+E48)^5+$I$29*(1+$D$49)/(E48-$D$49) -> 344702.16 | F49: =$E$27/(1+F48)^1+$F$27/(1+F48)^2+$G$27/(1+F48)^3+$H$27/(1+F48)^4+$I$27/(1+F48)^5+$I$29*(1+$D$49)/(F48-$D$49) -> 301578.98 | G49: =$E$27/(1+G48)^1+$F$27/(1+G48)^2+$G$27/(1+G48)^3+$H$27/(1+G48)^4+$I$27/(1+G48)^5+$I$29*(1+$D$49)/(G48-$D$49) -> 269001.67 | H49: =$E$27/(1+H48)^1+$F$27/(1+H48)^2+$G$27/(1+H48)^3+$H$27/(1+H48)^4+$I$27/(1+H48)^5+$I$29*(1+$D$49)/(H48-$D$49) -> 243484.39 | I49: =$E$27/(1+I48)^1+$F$27/(1+I48)^2+$G$27/(1+I48)^3+$H$27/(1+I48)^4+$I$27/(1+I48)^5+$I$29*(1+$D$49)/(I48-$D$49) -> 222926.55 | J49: =$E$27/(1+J48)^1+$F$27/(1+J48)^2+$G$27/(1+J48)^3+$H$27/(1+J48)^4+$I$27/(1+J48)^5+$I$29*(1+$D$49)/(J48-$D$49) -> 205986.81 | K49: =$E$27/(1+K48)^1+$F$27/(1+K48)^2+$G$27/(1+K48)^3+$H$27/(1+K48)^4+$I$27/(1+K48)^5+$I$29*(1+$D$49)/(K48-$D$49) -> 191768.46 | L49: =$E$27/(1+L48)^1+$F$27/(1+L48)^2+$G$27/(1+L48)^3+$H$27/(1+L48)^4+$I$27/(1+L48)^5+$I$29*(1+$D$49)/(L48-$D$49) -> 179649.2 | M49: =$E$27/(1+M48)^1+$F$27/(1+M48)^2+$G$27/(1+M48)^3+$H$27/(1+M48)^4+$I$27/(1+M48)^5+$I$29*(1+$D$49)/(M48-$D$49) -> 169183.66
D50: =D51-0.005 -> 0.0269675 | E50: =$E$27/(1+E48)^1+$F$27/(1+E48)^2+$G$27/(1+E48)^3+$H$27/(1+E48)^4+$I$27/(1+E48)^5+$I$29*(1+$D$50)/(E48-$D$50) -> 405694.48 | F50: =$E$27/(1+F48)^1+$F$27/(1+F48)^2+$G$27/(1+F48)^3+$H$27/(1+F48)^4+$I$27/(1+F48)^5+$I$29*(1+$D$50)/(F48-$D$50) -> 345511.99 | G50: =$E$27/(1+G48)^1+$F$27/(1+G48)^2+$G$27/(1+G48)^3+$H$27/(1+G48)^4+$I$27/(1+G48)^5+$I$29*(1+$D$50)/(G48-$D$50) -> 302195.62 | H50: =$E$27/(1+H48)^1+$F$27/(1+H48)^2+$G$27/(1+H48)^3+$H$27/(1+H48)^4+$I$27/(1+H48)^5+$I$29*(1+$D$50)/(H48-$D$50) -> 269476.22 | I50: =$E$27/(1+I48)^1+$F$27/(1+I48)^2+$G$27/(1+I48)^3+$H$27/(1+I48)^4+$I$27/(1+I48)^5+$I$29*(1+$D$50)/(I48-$D$50) -> 243850.94 | J50: =$E$27/(1+J48)^1+$F$27/(1+J48)^2+$G$27/(1+J48)^3+$H$27/(1+J48)^4+$I$27/(1+J48)^5+$I$29*(1+$D$50)/(J48-$D$50) -> 223208.91 | K50: =$E$27/(1+K48)^1+$F$27/(1+K48)^2+$G$27/(1+K48)^3+$H$27/(1+K48)^4+$I$27/(1+K48)^5+$I$29*(1+$D$50)/(K48-$D$50) -> 206202.25 | L50: =$E$27/(1+L48)^1+$F$27/(1+L48)^2+$G$27/(1+L48)^3+$H$27/(1+L48)^4+$I$27/(1+L48)^5+$I$29*(1+$D$50)/(L48-$D$50) -> 191929.86 | M50: =$E$27/(1+M48)^1+$F$27/(1+M48)^2+$G$27/(1+M48)^3+$H$27/(1+M48)^4+$I$27/(1+M48)^5+$I$29*(1+$D$50)/(M48-$D$50) -> 179766.44
D51: =D52-0.005 -> 0.0319675 | E51: =$E$27/(1+E48)^1+$F$27/(1+E48)^2+$G$27/(1+E48)^3+$H$27/(1+E48)^4+$I$27/(1+E48)^5+$I$29*(1+$D$51)/(E48-$D$51) -> 496698.44 | F51: =$E$27/(1+F48)^1+$F$27/(1+F48)^2+$G$27/(1+F48)^3+$H$27/(1+F48)^4+$I$27/(1+F48)^5+$I$29*(1+$D$51)/(F48-$D$51) -> 406794.12 | G51: =$E$27/(1+G48)^1+$F$27/(1+G48)^2+$G$27/(1+G48)^3+$H$27/(1+G48)^4+$I$27/(1+G48)^5+$I$29*(1+$D$51)/(G48-$D$51) -> 346336.39 | H51: =$E$27/(1+H48)^1+$F$27/(1+H48)^2+$G$27/(1+H48)^3+$H$27/(1+H48)^4+$I$27/(1+H48)^5+$I$29*(1+$D$51)/(H48-$D$51) -> 302826.41 | I51: =$E$27/(1+I48)^1+$F$27/(1+I48)^2+$G$27/(1+I48)^3+$H$27/(1+I48)^4+$I$27/(1+I48)^5+$I$29*(1+$D$51)/(I48-$D$51) -> 269964.54 | J51: =$E$27/(1+J48)^1+$F$27/(1+J48)^2+$G$27/(1+J48)^3+$H$27/(1+J48)^4+$I$27/(1+J48)^5+$I$29*(1+$D$51)/(J48-$D$51) -> 244230.87 | K51: =$E$27/(1+K48)^1+$F$27/(1+K48)^2+$G$27/(1+K48)^3+$H$27/(1+K48)^4+$I$27/(1+K48)^5+$I$29*(1+$D$51)/(K48-$D$51) -> 223504.27 | L51: =$E$27/(1+L48)^1+$F$27/(1+L48)^2+$G$27/(1+L48)^3+$H$27/(1+L48)^4+$I$27/(1+L48)^5+$I$29*(1+$D$51)/(L48-$D$51) -> 206430.33 | M51: =$E$27/(1+M48)^1+$F$27/(1+M48)^2+$G$27/(1+M48)^3+$H$27/(1+M48)^4+$I$27/(1+M48)^5+$I$29*(1+$D$51)/(M48-$D$51) -> 192103.57
D52: =D40 -> 0.0369675 | E52: =$E$27/(1+E48)^1+$F$27/(1+E48)^2+$G$27/(1+E48)^3+$H$27/(1+E48)^4+$I$27/(1+E48)^5+$I$29*(1+$D$52)/(E48-$D$52) -> 647093.21 | F52: =$E$27/(1+F48)^1+$F$27/(1+F48)^2+$G$27/(1+F48)^3+$H$27/(1+F48)^4+$I$27/(1+F48)^5+$I$29*(1+$D$52)/(F48-$D$52) -> 498230.48 | G52: =$E$27/(1+G48)^1+$F$27/(1+G48)^2+$G$27/(1+G48)^3+$H$27/(1+G48)^4+$I$27/(1+G48)^5+$I$29*(1+$D$52)/(G48-$D$52) -> 407908.33 | H52: =$E$27/(1+H48)^1+$F$27/(1+H48)^2+$G$27/(1+H48)^3+$H$27/(1+H48)^4+$I$27/(1+H48)^5+$I$29*(1+$D$52)/(H48-$D$52) -> 347174.94 | I52: =$E$27/(1+I48)^1+$F$27/(1+I48)^2+$G$27/(1+I48)^3+$H$27/(1+I48)^4+$I$27/(1+I48)^5+$I$29*(1+$D$52)/(I48-$D$52) -> 303470.96 | J52: =$E$27/(1+J48)^1+$F$27/(1+J48)^2+$G$27/(1+J48)^3+$H$27/(1+J48)^4+$I$27/(1+J48)^5+$I$29*(1+$D$52)/(J48-$D$52) -> 270466.23 | K52: =$E$27/(1+K48)^1+$F$27/(1+K48)^2+$G$27/(1+K48)^3+$H$27/(1+K48)^4+$I$27/(1+K48)^5+$I$29*(1+$D$52)/(K48-$D$52) -> 244623.8 | L52: =$E$27/(1+L48)^1+$F$27/(1+L48)^2+$G$27/(1+L48)^3+$H$27/(1+L48)^4+$I$27/(1+L48)^5+$I$29*(1+$D$52)/(L48-$D$52) -> 223812.29 | M52: =$E$27/(1+M48)^1+$F$27/(1+M48)^2+$G$27/(1+M48)^3+$H$27/(1+M48)^4+$I$27/(1+M48)^5+$I$29*(1+$D$52)/(M48-$D$52) -> 206670.72
D53: =D52+0.005 -> 0.0419675 | E53: =$E$27/(1+E48)^1+$F$27/(1+E48)^2+$G$27/(1+E48)^3+$H$27/(1+E48)^4+$I$27/(1+E48)^5+$I$29*(1+$D$53)/(E48-$D$53) -> 943178.43 | F53: =$E$27/(1+F48)^1+$F$27/(1+F48)^2+$G$27/(1+F48)^3+$H$27/(1+F48)^4+$I$27/(1+F48)^5+$I$29*(1+$D$53)/(F48-$D$53) -> 649339.86 | G53: =$E$27/(1+G48)^1+$F$27/(1+G48)^2+$G$27/(1+G48)^3+$H$27/(1+G48)^4+$I$27/(1+G48)^5+$I$29*(1+$D$53)/(G48-$D$53) -> 499777.1 | H53: =$E$27/(1+H48)^1+$F$27/(1+H48)^2+$G$27/(1+H48)^3+$H$27/(1+H48)^4+$I$27/(1+H48)^5+$I$29*(1+$D$53)/(H48-$D$53) -> 409036.69 | I53: =$E$27/(1+I48)^1+$F$27/(1+I48)^2+$G$27/(1+I48)^3+$H$27/(1+I48)^4+$I$27/(1+I48)^5+$I$29*(1+$D$53)/(I48-$D$53) -> 348027.25 | J53: =$E$27/(1+J48)^1+$F$27/(1+J48)^2+$G$27/(1+J48)^3+$H$27/(1+J48)^4+$I$27/(1+J48)^5+$I$29*(1+$D$53)/(J48-$D$53) -> 304128.89 | K53: =$E$27/(1+K48)^1+$F$27/(1+K48)^2+$G$27/(1+K48)^3+$H$27/(1+K48)^4+$I$27/(1+K48)^5+$I$29*(1+$D$53)/(K48-$D$53) -> 270980.93 | L53: =$E$27/(1+L48)^1+$F$27/(1+L48)^2+$G$27/(1+L48)^3+$H$27/(1+L48)^4+$I$27/(1+L48)^5+$I$29*(1+$D$53)/(L48-$D$53) -> 245029.39 | M53: =$E$27/(1+M48)^1+$F$27/(1+M48)^2+$G$27/(1+M48)^3+$H$27/(1+M48)^4+$I$27/(1+M48)^5+$I$29*(1+$D$53)/(M48-$D$53) -> 224132.61
D54: =D53+0.005 -> 0.0469675 | E54: =$E$27/(1+E48)^1+$F$27/(1+E48)^2+$G$27/(1+E48)^3+$H$27/(1+E48)^4+$I$27/(1+E48)^5+$I$29*(1+$D$54)/(E48-$D$54) -> 1795511.8 | F54: =$E$27/(1+F48)^1+$F$27/(1+F48)^2+$G$27/(1+F48)^3+$H$27/(1+F48)^4+$I$27/(1+F48)^5+$I$29*(1+$D$54)/(F48-$D$54) -> 946831.95 | G54: =$E$27/(1+G48)^1+$F$27/(1+G48)^2+$G$27/(1+G48)^3+$H$27/(1+G48)^4+$I$27/(1+G48)^5+$I$29*(1+$D$54)/(G48-$D$54) -> 651601.08 | H54: =$E$27/(1+H48)^1+$F$27/(1+H48)^2+$G$27/(1+H48)^3+$H$27/(1+H48)^4+$I$27/(1+H48)^5+$I$29*(1+$D$54)/(H48-$D$54) -> 501337.87 | I54: =$E$27/(1+I48)^1+$F$27/(1+I48)^2+$G$27/(1+I48)^3+$H$27/(1+I48)^4+$I$27/(1+I48)^5+$I$29*(1+$D$54)/(I48-$D$54) -> 410178.81 | J54: =$E$27/(1+J48)^1+$F$27/(1+J48)^2+$G$27/(1+J48)^3+$H$27/(1+J48)^4+$I$27/(1+J48)^5+$I$29*(1+$D$54)/(J48-$D$54) -> 348892.95 | K54: =$E$27/(1+K48)^1+$F$27/(1+K48)^2+$G$27/(1+K48)^3+$H$27/(1+K48)^4+$I$27/(1+K48)^5+$I$29*(1+$D$54)/(K48-$D$54) -> 304799.83 | L54: =$E$27/(1+L48)^1+$F$27/(1+L48)^2+$G$27/(1+L48)^3+$H$27/(1+L48)^4+$I$27/(1+L48)^5+$I$29*(1+$D$54)/(L48-$D$54) -> 271508.28 | M54: =$E$27/(1+M48)^1+$F$27/(1+M48)^2+$G$27/(1+M48)^3+$H$27/(1+M48)^4+$I$27/(1+M48)^5+$I$29*(1+$D$54)/(M48-$D$54) -> 245447.28
D55: =D54+0.005 -> 0.0519675 | E55: =$E$27/(1+E48)^1+$F$27/(1+E48)^2+$G$27/(1+E48)^3+$H$27/(1+E48)^4+$I$27/(1+E48)^5+$I$29*(1+$D$55)/(E48-$D$55) -> 29044163 | F55: =$E$27/(1+F48)^1+$F$27/(1+F48)^2+$G$27/(1+F48)^3+$H$27/(1+F48)^4+$I$27/(1+F48)^5+$I$29*(1+$D$55)/(F48-$D$55) -> 1803215.2 | G55: =$E$27/(1+G48)^1+$F$27/(1+G48)^2+$G$27/(1+G48)^3+$H$27/(1+G48)^4+$I$27/(1+G48)^5+$I$29*(1+$D$55)/(G48-$D$55) -> 950500.03 | H55: =$E$27/(1+H48)^1+$F$27/(1+H48)^2+$G$27/(1+H48)^3+$H$27/(1+H48)^4+$I$27/(1+H48)^5+$I$29*(1+$D$55)/(H48-$D$55) -> 653876.46 | I55: =$E$27/(1+I48)^1+$F$27/(1+I48)^2+$G$27/(1+I48)^3+$H$27/(1+I48)^4+$I$27/(1+I48)^5+$I$29*(1+$D$55)/(I48-$D$55) -> 502912.4 | J55: =$E$27/(1+J48)^1+$F$27/(1+J48)^2+$G$27/(1+J48)^3+$H$27/(1+J48)^4+$I$27/(1+J48)^5+$I$29*(1+$D$55)/(J48-$D$55) -> 411334.31 | K55: =$E$27/(1+K48)^1+$F$27/(1+K48)^2+$G$27/(1+K48)^3+$H$27/(1+K48)^4+$I$27/(1+K48)^5+$I$29*(1+$D$55)/(K48-$D$55) -> 349771.65 | L55: =$E$27/(1+L48)^1+$F$27/(1+L48)^2+$G$27/(1+L48)^3+$H$27/(1+L48)^4+$I$27/(1+L48)^5+$I$29*(1+$D$55)/(L48-$D$55) -> 305483.41 | M55: =$E$27/(1+M48)^1+$F$27/(1+M48)^2+$G$27/(1+M48)^3+$H$27/(1+M48)^4+$I$27/(1+M48)^5+$I$29*(1+$D$55)/(M48-$D$55) -> 272047.94

Sheet 4.2 Free Cash Flow + Synergies 
B1: Free Cash Flow + Synergies
B3: Income Statement
B4: In Millions of USD | E4: 2002 | F4: 2003 | G4: 2004 | H4: 2005 | I4: 2006
C6: Unlevered Free Cash Flow
C8: Year (t) | E8: 1 | F8: 2 | G8: 3 | H8: 4 | I8: 5 | L8: Revenue Synergy | M8: ='4.4 Revenue Synergy'!G8 -> 4677.8282
L9: Cost of sales Synergy | M9: ='4.5 Cost of Sale Synergy'!G7 -> 3299.3358
C10: Revenue | E10: ='3.3 Income Statement'!F8 -> 45777.775 | F10: ='3.3 Income Statement'!G8 -> 48903.662 | G10: ='3.3 Income Statement'!H8 -> 52251.813 | H10: ='3.3 Income Statement'!I8 -> 55838.511 | I10: ='3.3 Income Statement'!J8 -> 59681.261 | L10: R&D Synergy | M10: ='4.6 R&D Synergy'!G7 -> 4666.3082
C11: Revenue Synergy | E11: ='4.4 Revenue Synergy'!C6 -> 1367.1247 | F11: ='4.4 Revenue Synergy'!D6 -> 1451.8907 | G11: ='4.4 Revenue Synergy'!E6 -> 1542.2157 | H11: ='4.4 Revenue Synergy'!F6 -> 593.44627 | I11: ='4.4 Revenue Synergy'!G6 -> 624.33104
C12: Adj. Revenue | E12: =E10+E11 -> 47144.9 | F12: =F10+F11 -> 50355.553 | G12: =G10+G11 -> 53794.028 | H12: =H10+H11 -> 56431.958 | I12: =I10+I11 -> 60305.592
C13: Cost of sales | E13: =-'3.1 Growth Ratio'!E13*'4.2 Free Cash Flow + Synergies '!E12 -> -6410.6286 | F13: =-'3.1 Growth Ratio'!F13*'4.2 Free Cash Flow + Synergies '!F12 -> -5783.5524 | G13: =-'3.1 Growth Ratio'!G13*'4.2 Free Cash Flow + Synergies '!G12 -> -6003.0977 | H13: =-'3.1 Growth Ratio'!H13*'4.2 Free Cash Flow + Synergies '!H12 -> -6110.0262 | I13: =-'3.1 Growth Ratio'!I13*'4.2 Free Cash Flow + Synergies '!I12 -> -6325.4668
C14: Cost of sales Synergy | E14: ='4.5 Cost of Sale Synergy'!C5 -> 1696.1386 | F14: ='4.5 Cost of Sale Synergy'!D5 -> 747.99709 | G14: ='4.5 Cost of Sale Synergy'!E5 -> 623.6949 | H14: ='4.5 Cost of Sale Synergy'!F5 -> 466.83041 | I14: ='4.5 Cost of Sale Synergy'!G5 -> 294.9076
C15: Adj. Cost of sales | E15: =E13+E14 -> -4714.49 | F15: =F13+F14 -> -5035.5553 | G15: =G13+G14 -> -5379.4028 | H15: =H13+H14 -> -5643.1958 | I15: =I13+I14 -> -6030.5592
C16: SG&A | E16: =-'3.1 Growth Ratio'!E14*'4.2 Free Cash Flow + Synergies '!E12 -> -16122.861 | F16: =-'3.1 Growth Ratio'!F14*'4.2 Free Cash Flow + Synergies '!F12 -> -17231.367 | G16: =-'3.1 Growth Ratio'!G14*'4.2 Free Cash Flow + Synergies '!G12 -> -18419.103 | H16: =-'3.1 Growth Ratio'!H14*'4.2 Free Cash Flow + Synergies '!H12 -> -19333.859 | I16: =-'3.1 Growth Ratio'!I14*'4.2 Free Cash Flow + Synergies '!I12 -> -20673.165
C17: SG&A Synergy* | E17: 0 | F17: 0 | G17: 0 | H17: 0 | I17: 0
